Workbook
Name _____________BSG11: [3]Busang1!$A$5:$GK$35
Name _____________BSG12: [3]Busang1!$A$41:$IO$71
Name _____________BSG13: [3]Busang1!$A$77:$GC$108
Name _____________BSG21: [3]Busang2!$A$5:$GK$35
Name _____________BSG23: [3]Busang2!$A$77:$GC$107
Name _____________BSG33: [3]Busang3!$A$77:$GC$107
Name _____________BUS1: [3]Busang1!$HQ$4:$HT$36
Name _____________BUS2: [3]Busang2!$HY$4:$IB$36
Name _____________JG1: [3]Jonggon1!$HY$6:$IB$36
Name _____________JG2: [3]Jonggon2!$IO$5:$IR$35
Name _____________JGN11: [3]Jonggon1!$A$5:$GK$35
Name _____________JGN12: [3]Jonggon1!$A$41:$IO$71
Name _____________JGN13: [3]Jonggon1!$A$77:$GC$107
Name _____________JGN21: [3]Jonggon2!$A$5:$GK$35
Name _____________JGN22: [3]Jonggon2!$A$41:$IO$71
Name _____________JGN23: [3]Jonggon2!$A$77:$GC$107
Name _____________JGN31: [3]Jonggon3!$A$5:$EW$35
Name _____________JGN32: [3]Jonggon3!$A$41:$IO$71
Name _____________JGN33: [3]Jonggon3!$A$77:$GC$107
Name ____________BSG13: [3]Busang1!$A$77:$GC$108
Name ____________BSG21: [3]Busang2!$A$5:$GK$35
Name ____________BSG22: [3]Busang2!$A$41:$IO$71
Name ____________BSG23: [3]Busang2!$A$77:$GC$107
Name ____________BSG31: [3]Busang3!$A$5:$EW$35
Name ____________BSG32: [3]Busang3!$A$41:$IO$71
Name ____________BSG33: [3]Busang3!$A$77:$GC$107
Name ____________BUS1: [3]Busang1!$HQ$4:$HT$36
Name ____________BUS2: [3]Busang2!$HY$4:$IB$36
Name ____________JG1: [3]Jonggon1!$HY$6:$IB$36
Name ____________JG2: [3]Jonggon2!$IO$5:$IR$35
Name ____________JGN11: [3]Jonggon1!$A$5:$GK$35
Name ____________JGN12: [3]Jonggon1!$A$41:$IO$71
Name ____________JGN13: [3]Jonggon1!$A$77:$GC$107
Name ____________JGN21: [3]Jonggon2!$A$5:$GK$35
Name ____________JGN22: [3]Jonggon2!$A$41:$IO$71
Name ____________JGN23: [3]Jonggon2!$A$77:$GC$107
Name ____________JGN31: [3]Jonggon3!$A$5:$EW$35
Name ____________JGN32: [3]Jonggon3!$A$41:$IO$71
Name ____________JGN33: [3]Jonggon3!$A$77:$GC$107
Name ____________new2: #REF!
Name ___________BSG13: [3]Busang1!$A$77:$GC$108
Name ___________BSG21: [3]Busang2!$A$5:$GK$35
Name ___________BSG22: [3]Busang2!$A$41:$IO$71
Name ___________BSG23: [3]Busang2!$A$77:$GC$107
Name ___________BSG31: [3]Busang3!$A$5:$EW$35
Name ___________BSG32: [3]Busang3!$A$41:$IO$71
Name ___________BSG33: [3]Busang3!$A$77:$GC$107
Name ___________BUS1: [3]Busang1!$HQ$4:$HT$36
Name ___________BUS2: [3]Busang2!$HY$4:$IB$36
Name ___________JG1: [3]Jonggon1!$HY$6:$IB$36
Name ___________JG2: [3]Jonggon2!$IO$5:$IR$35
Name ___________JGN11: [3]Jonggon1!$A$5:$GK$35
Name ___________JGN12: [3]Jonggon1!$A$41:$IO$71
Name ___________JGN13: [3]Jonggon1!$A$77:$GC$107
Name ___________JGN21: [3]Jonggon2!$A$5:$GK$35
Name ___________JGN22: [3]Jonggon2!$A$41:$IO$71
Name ___________JGN23: [3]Jonggon2!$A$77:$GC$107
Name ___________JGN31: [3]Jonggon3!$A$5:$EW$35
Name ___________JGN32: [3]Jonggon3!$A$41:$IO$71
Name ___________JGN33: [3]Jonggon3!$A$77:$GC$107

Sheet OKT 2026
B1: UNIT NO | C1: LOKASI | D1: MODEL 1 | E1: MODEL 2 | F1: SMU READING 30 SEP 2023 | G1: 1 | H1: 44653 | I1: 44654 | J1: 44655 | K1: 44656 | L1: 44657 | M1: 44658 | N1: 44659 | O1: 44660 | P1: 44661 | Q1: 44662 | R1: 44663 | S1: 44664 | T1: 44665 | U1: 44666 | V1: 44667 | W1: 44668 | X1: 44669 | Y1: 44670 | Z1: 44671 | AA1: 44672 | AB1: 44673 | AC1: 44674 | AD1: 44675 | AE1: 44676 | AF1: 44677 | AG1: 44678 | AH1: 44679 | AI1: 44680 | AJ1: 44681 | AK1: 31 | AL1: EST. TOTAL DOWN TIME (hrs) | AM1: % PA | AO1: REPAIR OPTION REQUIRED / BACKLOG | AP1: REMAKS
G3: OKT | H3: =G3 -> OKT | I3: =H3 -> OKT | J3: =I3 -> OKT | K3: =J3 -> OKT | L3: =K3 -> OKT | M3: =L3 -> OKT | N3: =M3 -> OKT | O3: =N3 -> OKT | ... AE3: =AD3 -> OKT | AF3: =AB3 -> OKT | AG3: =AF3 -> OKT | AH3: =AG3 -> OKT | AI3: =AE3 -> OKT | AJ3: =AG3 -> OKT | AK3: =AH3 -> OKT | AM3: Monthly Forecast | AN3: Target
G4: =COUNT(G7:G308) -> 134 | H4: =COUNT(H7:H308) -> 134 | I4: =COUNT(I7:I308) -> 134 | J4: =COUNT(J7:J308) -> 135 | K4: =COUNT(K7:K308) -> 136 | L4: =COUNT(L7:L308) -> 134 | M4: =COUNT(M7:M308) -> 134 | N4: =COUNT(N7:N308) -> 134 | ... AK4: =COUNT(AK7:AK308) -> 135
B5: PA UNIT A2B PRODUCTION
B6: FORECAST AC SECTION TRACK
B7: D1521 | D7: D155A-6 | E7: D155A-6 | F7: 43834 | G7: 0 | H7: 0 | I7: 0 | J7: 0 | K7: 0 | L7: 0 | M7: 0 | N7: 0 | O7: 16 | P7: 0 | Q7: 0 | R7: 0 | S7: 0 | T7: 0 | U7: 0 | V7: 0 | W7: 0 | X7: 0 | Y7: 0 | Z7: 0 | AA7: 0 | AB7: 0 | AC7: 6 | AD7: 0 | AE7: 0 | AF7: 0 | AG7: 0 | AH7: 0 | AI7: 0 | AJ7: 0 | AK7: 0 | AL7: 53 | AM7: 0.92876344 | AN7: 0.922 | AO7: PMS 4000 & PMS 250 | AP7: compresor | AQ7: 2814400
AP8: m cluth | AQ8: 1530375
AP9: motor blower | AQ9: 1028500
AP10: evaporator | AQ10: 973500
AP11: expansi valeve | AQ11: 504000
AP12: thermostat elektrik | AQ12: 203000
AP13: drayer | AQ13: 250000
AP14: v-belt b38 | AQ14: 453250
AP15: oli ND08 | AQ15: 313500
AQ16: =SUM(AQ7:AQ15) -> 8070525
B18: D1535 | D18: D155A-6 | E18: D155A-6 | F18: 29660 | G18: 0 | H18: 0 | I18: 0 | J18: 0 | K18: 6 | L18: 0 | M18: 0 | N18: 0 | O18: 0 | P18: 0 | Q18: 0 | R18: 0 | S18: 0 | T18: 0 | U18: 0 | V18: 0 | W18: 0 | X18: 0 | Y18: 16 | Z18: 0 | AA18: 0 | AB18: 0 | AC18: 0 | AD18: 0 | AE18: 0 | AF18: 0 | AG18: 0 | AH18: 0 | AI18: 0 | AJ18: 0 | AK18: 0 | AL18: 53 | AM18: 0.92876344 | AN18: 0.922 | AO18: PMS 250 & PMS 2000 | AP18: compresor | AQ18: 2814400
AP19: m cluth | AQ19: 1530375
AP20: expansi valeve | AQ20: 504000
AP21: thermostat elektrik | AQ21: 203000
AP22: drayer | AQ22: 250000
AP23: v-belt b38 | AQ23: 453250
AP24: oli ND08 | AQ24: 313500
AQ25: =SUM(AQ18:AQ24) -> 6068525
B27: D5107AMM | D27: D155A-6 | E27: D155A-6 | F27: 25987 | G27: 16 | H27: 0 | I27: 0 | J27: 0 | K27: 0 | L27: 0 | M27: 0 | N27: 0 | O27: 0 | P27: 0 | Q27: 0 | R27: 0 | S27: 0 | T27: 0 | U27: 6 | V27: 0 | W27: 0 | X27: 0 | Y27: 0 | Z27: 0 | AA27: 0 | AB27: 0 | AC27: 0 | AD27: 0 | AE27: 0 | AF27: 0 | AG27: 0 | AH27: 0 | AI27: 8 | AJ27: 0 | AK27: 0 | AL27: 61 | AM27: 0.91801075 | AN27: 0.922 | AO27: PMS 2000 & PMS 250 & PMS 500 | AP27: expansi valeve | AQ27: 504000
AP28: thermostat elektrik | AQ28: 203000
AP29: drayer | AQ29: 250000
AP30: v-belt b38 | AQ30: 453250
AP31: oli ND08 | AQ31: 313500
AQ32: =SUM(AQ27:AQ31) -> 1723750
B34: D5109AMM | D34: D155A-6 | E34: D155A-6 | F34: 27772 | G34: 0 | H34: 0 | I34: 0 | J34: 0 | K34: 0 | L34: 0 | M34: 0 | N34: 0 | O34: 0 | P34: 0 | Q34: 0 | R34: 0 | S34: 16 | T34: 0 | U34: 0 | V34: 0 | W34: 0 | X34: 0 | Y34: 0 | Z34: 0 | AA34: 0 | AB34: 0 | AC34: 0 | AD34: 0 | AE34: 0 | AF34: 0 | AG34: 6 | AH34: 0 | AI34: 0 | AJ34: 0 | AK34: 0 | AL34: 53 | AM34: 0.92876344 | AN34: 0.922 | AO34: PMS 4000 & PMS 250 | AP34: expansi valeve | AQ34: 504000
AP35: thermostat elektrik | AQ35: 203000
AP36: drayer | AQ36: 250000
AP37: v-belt b38 | AQ37: 453250
AP38: oli ND08 | AQ38: 313500
AQ39: =SUM(AQ34:AQ38) -> 1723750
B41: D1558 | D41: D155A-6 | E41: D155A-6 | F41: 19981 | G41: 16 | H41: 0 | I41: 0 | J41: 0 | K41: 0 | L41: 0 | M41: 0 | N41: 0 | O41: 0 | P41: 0 | Q41: 0 | R41: 0 | S41: 0 | T41: 0 | U41: 6 | V41: 0 | W41: 0 | X41: 0 | Y41: 0 | Z41: 0 | AA41: 0 | AB41: 0 | AC41: 0 | AD41: 0 | AE41: 0 | AF41: 0 | AG41: 0 | AH41: 0 | AI41: 8 | AJ41: 0 | AK41: 0 | AL41: 61 | AM41: 0.91801075 | AN41: 0.922 | AO41: PMS 4000 & PMS 250 & PMS 500 | AP41: expansi valeve | AQ41: 504000
AP42: thermostat elektrik | AQ42: 203000
AP43: drayer | AQ43: 250000
AP44: v-belt b38 | AQ44: 453250
AP45: oli ND08 | AQ45: 313500
...

Sheet NOV 2026
AN1: PPA-F-PLANT-1b
E2: PA Forecast & Monthly Planning PM Schedule | AM2: Distribution List :
AM3: 1. Project Manager
AM4: 2. Dept Head Plant
AM5: 3. Dept Head Enginnering
B6: PT. PUTRA PERKASA ABADI | AM6: 4. Dept Head Operational
B7: SITE GIRI MULYA COAL PROJECT | AM7: CC: Logistic, GL Plant, Admint Plant.
B8: Monthly 11 Preventive Maintenance Schedule Periode NOVEMBER 2026 | AK8: 720
AJ9: 1
B10: UNIT NO | C10: LOKASI | D10: MODEL 1 | E10: MODEL 2 | F10: SMU READING 31 OKT 2023 | G10: 44652 | H10: 44653 | I10: 44654 | J10: 44655 | K10: 44656 | L10: 44657 | M10: 44658 | N10: 44659 | O10: 44660 | P10: 44661 | Q10: 44662 | R10: 44663 | S10: 44664 | T10: 44665 | U10: 44666 | V10: 44667 | W10: 44668 | X10: 44669 | Y10: 44670 | Z10: 44671 | AA10: 44672 | AB10: 44673 | AC10: 44674 | AD10: 44675 | AE10: 44676 | AF10: 44677 | AG10: 44678 | AH10: 44679 | AI10: 44680 | AJ10: 44681 | AK10: EST. TOTAL DOWN TIME (hrs) | AL10: % PA | AN10: REPAIR OPTION REQUIRED / BACKLOG | AO10: REMAKS
G12: NOV | H12: =G12 -> NOV | I12: =H12 -> NOV | J12: =I12 -> NOV | K12: =J12 -> NOV | L12: =K12 -> NOV | M12: =L12 -> NOV | N12: =M12 -> NOV | O12: =N12 -> NOV | ... AE12: =AD12 -> NOV | AF12: =AB12 -> NOV | AG12: =AF12 -> NOV | AH12: =AG12 -> NOV | AI12: =AE12 -> NOV | AJ12: =AG12 -> NOV | AL12: Monthly Forecast | AM12: Target
G13: =COUNT('OKT 2026'!G7:G308) -> 134 | H13: =COUNT('OKT 2026'!H7:H308) -> 134 | I13: =COUNT('OKT 2026'!I7:I308) -> 134 | J13: =COUNT('OKT 2026'!J7:J308) -> 135 | K13: =COUNT('OKT 2026'!K7:K308) -> 136 | L13: =COUNT('OKT 2026'!L7:L308) -> 134 | M13: =COUNT('OKT 2026'!M7:M308) -> 134 | N13: =COUNT('OKT 2026'!N7:N308) -> 134 | ... AJ13: =COUNT('OKT 2026'!AJ7:AJ308) -> 134
B14: PA UNIT A2B PRODUCTION
B15: E3401 | D15: PC3400-11M0 | E15: PC3400-11M0 | F15: 11147.9 | G15: 0 | H15: 0 | I15: 0 | J15: 0 | K15: 0 | L15: 0 | M15: 0 | N15: 0 | O15: 0 | P15: 8 | Q15: 0 | R15: 0 | S15: 0 | T15: 0 | U15: 0 | V15: 0 | W15: 0 | X15: 0 | Y15: 0 | Z15: 0 | AA15: 0 | AB15: 0 | AC15: 0 | AD15: 0 | AE15: 10 | AF15: 0 | AG15: 0 | AH15: 0 | AI15: 0 | AJ15: 0 | AK15: 48 | AL15: 0.93333333 | AM15: 0.922 | AN15: PMS 250 & PMS 500
B16: E3402 | D16: PC3400-11M0 | E16: PC3400-11M0 | F16: 8516.7 | G16: 0 | H16: 8 | I16: 0 | J16: 0 | K16: 0 | L16: 0 | M16: 0 | N16: 0 | O16: 0 | P16: 0 | Q16: 0 | R16: 0 | S16: 0 | T16: 0 | U16: 0 | V16: 0 | W16: 16 | X16: 0 | Y16: 0 | Z16: 0 | AA16: 0 | AB16: 0 | AC16: 0 | AD16: 0 | AE16: 0 | AF16: 0 | AG16: 0 | AH16: 0 | AI16: 0 | AJ16: 0 | AK16: 54 | AL16: 0.925 | AM16: 0.922 | AN16: PMS 250 & PMS 1000
B17: E3403 | D17: PC3400-11M0 | E17: PC3400-11M0 | F17: 6933 | G17: 0 | H17: 0 | I17: 0 | J17: 0 | K17: 0 | L17: 0 | M17: 16 | N17: 0 | O17: 0 | P17: 0 | Q17: 0 | R17: 0 | S17: 0 | T17: 0 | U17: 0 | V17: 0 | W17: 0 | X17: 0 | Y17: 0 | Z17: 0 | AA17: 0 | AB17: 8 | AC17: 0 | AD17: 0 | AE17: 0 | AF17: 0 | AG17: 0 | AH17: 0 | AI17: 0 | AJ17: 0 | AK17: 54 | AL17: 0.925 | AM17: 0.922 | AN17: PMS 1000 & PMS 250
B18: E2006 | D18: PC 2000-8 | E18: PC 2000-8 | F18: 45483.6 | G18: 0 | H18: 0 | I18: 0 | J18: 0 | K18: 0 | L18: 0 | M18: 0 | N18: 0 | O18: 8 | P18: 0 | Q18: 0 | R18: 0 | S18: 0 | T18: 0 | U18: 0 | V18: 0 | W18: 0 | X18: 0 | Y18: 0 | Z18: 0 | AA18: 0 | AB18: 0 | AC18: 0 | AD18: 0 | AE18: 6 | AF18: 0 | AG18: 0 | AH18: 0 | AI18: 0 | AJ18: 0 | AK18: 50 | AL18: 0.93055556 | AM18: 0.922 | AN18: PMS 500 & PMS 250
B19: E2007 | D19: PC 2000-8 | E19: PC 2000-8 | F19: 44564.9 | G19: 0 | H19: 0 | I19: 0 | J19: 6 | K19: 0 | L19: 0 | M19: 0 | N19: 0 | O19: 0 | P19: 0 | Q19: 0 | R19: 0 | S19: 0 | T19: 0 | U19: 0 | V19: 0 | W19: 0 | X19: 0 | Y19: 0 | Z19: 14 | AA19: 0 | AB19: 0 | AC19: 0 | AD19: 0 | AE19: 0 | AF19: 0 | AG19: 0 | AH19: 0 | AI19: 0 | AJ19: 0 | AK19: 56 | AL19: 0.92222222 | AM19: 0.922 | AN19: PMS 250 & PMS 1000
B20: E2008 | D20: PC 2000-8 | E20: PC 2000-8 | F20: 44279 | G20: 0 | H20: 0 | I20: 0 | J20: 0 | K20: 0 | L20: 8 | M20: 0 | N20: 0 | O20: 0 | P20: 0 | Q20: 0 | R20: 0 | S20: 0 | T20: 0 | U20: 0 | V20: 0 | W20: 0 | X20: 0 | Y20: 0 | Z20: 0 | AA20: 0 | AB20: 6 | AC20: 0 | AD20: 0 | AE20: 0 | AF20: 0 | AG20: 0 | AH20: 0 | AI20: 0 | AJ20: 0 | AK20: 50 | AL20: 0.93055556 | AM20: 0.922 | AN20: PMS 500 & PMS 250
B21: E2009 | D21: PC 2000-8 | E21: PC 2000-8 | F21: 42428.8 | G21: 0 | H21: 0 | I21: 0 | J21: 0 | K21: 0 | L21: 0 | M21: 0 | N21: 0 | O21: 0 | P21: 0 | Q21: 0 | R21: 8 | S21: 0 | T21: 0 | U21: 0 | V21: 0 | W21: 0 | X21: 0 | Y21: 0 | Z21: 0 | AA21: 0 | AB21: 0 | AC21: 0 | AD21: 0 | AE21: 0 | AF21: 0 | AG21: 0 | AH21: 6 | AI21: 0 | AJ21: 0 | AK21: 50 | AL21: 0.93055556 | AM21: 0.922 | AN21: PMS 500 & PMS 250
B22: E2010 | D22: PC 2000-8 | E22: PC 2000-8 | F22: 41349.9 | G22: 8 | H22: 0 | I22: 0 | J22: 0 | K22: 0 | L22: 0 | M22: 0 | N22: 0 | O22: 0 | P22: 0 | Q22: 0 | R22: 0 | S22: 0 | T22: 0 | U22: 0 | V22: 0 | W22: 6 | X22: 0 | Y22: 0 | Z22: 0 | AA22: 0 | AB22: 0 | AC22: 0 | AD22: 0 | AE22: 0 | AF22: 0 | AG22: 0 | AH22: 0 | AI22: 0 | AJ22: 0 | AK22: 50 | AL22: 0.93055556 | AM22: 0.922 | AN22: PMS 500 & PMS 250
B23: E2011 | D23: PC 2000-8 | E23: PC 2000-8 | F23: 42855.2 | G23: 14 | H23: 0 | I23: 0 | J23: 0 | K23: 0 | L23: 0 | M23: 0 | N23: 0 | O23: 0 | P23: 0 | Q23: 0 | R23: 0 | S23: 0 | T23: 0 | U23: 0 | V23: 0 | W23: 6 | X23: 0 | Y23: 0 | Z23: 0 | AA23: 0 | AB23: 0 | AC23: 0 | AD23: 0 | AE23: 0 | AF23: 0 | AG23: 0 | AH23: 0 | AI23: 0 | AJ23: 0 | AK23: 56 | AL23: 0.92222222 | AM23: 0.922 | AN23: PMS 1000 & PMS 250
B24: E2012 | D24: PC 2000-8 | E24: PC 2000-8 | F24: 42930 | G24: 0 | H24: 0 | I24: 0 | J24: 0 | K24: 0 | L24: 0 | M24: 0 | N24: 0 | O24: 0 | P24: 0 | Q24: 0 | R24: 14 | S24: 0 | T24: 0 | U24: 0 | V24: 0 | W24: 0 | X24: 0 | Y24: 0 | Z24: 0 | AA24: 0 | AB24: 0 | AC24: 0 | AD24: 0 | AE24: 0 | AF24: 0 | AG24: 0 | AH24: 6 | AI24: 0 | AJ24: 0 | AK24: 56 | AL24: 0.92222222 | AM24: 0.922 | AN24: PMS 1000 & PMS 250
B25: E2013 | D25: PC 2000-8 | E25: PC 2000-8 | F25: 42963 | G25: 0 | H25: 0 | I25: 0 | J25: 0 | K25: 0 | L25: 0 | M25: 0 | N25: 0 | O25: 0 | P25: 14 | Q25: 0 | R25: 0 | S25: 0 | T25: 0 | U25: 0 | V25: 0 | W25: 0 | X25: 0 | Y25: 0 | Z25: 0 | AA25: 0 | AB25: 0 | AC25: 0 | AD25: 0 | AE25: 0 | AF25: 6 | AG25: 0 | AH25: 0 | AI25: 0 | AJ25: 0 | AK25: 56 | AL25: 0.92222222 | AM25: 0.922 | AN25: PMS 1000 & PMS 250
B26: E2014 | D26: PC 2000-8 | E26: PC 2000-8 | F26: 43221 | G26: 0 | H26: 0 | I26: 0 | J26: 0 | K26: 0 | L26: 0 | M26: 0 | N26: 0 | O26: 0 | P26: 6 | Q26: 0 | R26: 0 | S26: 0 | T26: 0 | U26: 0 | V26: 0 | W26: 0 | X26: 0 | Y26: 0 | Z26: 0 | AA26: 0 | AB26: 0 | AC26: 0 | AD26: 0 | AE26: 0 | AF26: 8 | AG26: 0 | AH26: 0 | AI26: 0 | AJ26: 0 | AK26: 50 | AL26: 0.93055556 | AM26: 0.922 | AN26: PMS 250 & PMS 500
... B108: E2180 | D108: PC210-10M0 | E108: PC210-10M0 | F108: 19110.3 | G108: 6 | H108: 0 | I108: 0 | J108: 0 | K108: 0 | L108: 0 | M108: 0 | N108: 0 | O108: 0 | P108: 0 | Q108: 0 | R108: 0 | S108: 0 | T108: 0 | U108: 0 | V108: 0 | W108: 8 | X108: 0 | Y108: 0 | Z108: 0 | AA108: 0 | AB108: 0 | AC108: 0 | AD108: 0 | AE108: 0 | AF108: 0 | AG108: 0 | AH108: 0 | AI108: 0 | AJ108: 0 | AK108: 53 | AL108: 0.92638889 | AM108: 0.922 | AN108: PMS 250 & PMS 500
B109: FORECAST AC SECTION TRACK
B110: D1509 | D110: D155A-6 | E110: D155A-6 | F110: 49631 | G110: 0 | H110: 0 | I110: 0 | J110: 6 | K110: 0 | L110: 0 | M110: 0 | N110: 0 | O110: 0 | P110: 0 | Q110: 0 | R110: 0 | S110: 0 | T110: 0 | U110: 0 | V110: 0 | W110: 0 | X110: 16 | Y110: 0 | Z110: 0 | AA110: 0 | AB110: 0 | AC110: 0 | AD110: 0 | AE110: 0 | AF110: 0 | AG110: 0 | AH110: 0 | AI110: 0 | AJ110: 0 | AK110: 52 | AL110: 0.92777778 | AM110: 0.922 | AN110: PMS 250 & PMS 2000 | AO110: compresor | AP110: 2814400
AO111: m. cluth | AP111: 1530375
AO112: kondensor | AP112: 1864500
AO113: evaporator | AP113: 973500
AO114: m'blower | AP114: 1028500
AO115: expansi valeve | AP115: 504000
AO116: thermostat elektrik | AP116: 203000
AO117: drayer | AP117: 250000
AO118: v-belt b38 | AP118: 453250
AO119: 0li nd8 | AP119: 313500
AP120: =SUM(AP110:AP119) -> 9935025
B122: D1510 | D122: D155A-6 | E122: D155A-6 | F122: 47852 | G122: 0 | H122: 0 | I122: 0 | J122: 0 | K122: 16 | L122: 0 | M122: 0 | N122: 0 | O122: 0 | P122: 0 | Q122: 0 | R122: 0 | S122: 0 | T122: 0 | U122: 0 | V122: 0 | W122: 0 | X122: 0 | Y122: 6 | Z122: 0 | AA122: 0 | AB122: 0 | AC122: 0 | AD122: 0 | AE122: 0 | AF122: 0 | AG122: 0 | AH122: 0 | AI122: 0 | AJ122: 0 | AK122: 52 | AL122: 0.92777778 | AM122: 0.922 | AN122: PMS 4000 & PMS 250 | AO122: expansi valeve | AP122: 504000
AO123: thermostat elektrik | AP123: 203000
...

Sheet DES 2026
AP1: PPA-F-PLANT-1b
F2: PA Forecast & Monthly Planning PM Schedule | AO2: Distribution List :
AO3: 1. Project Manager
AO4: 2. Dept Head Plant
AO5: 3. Dept Head Enginnering
B6: PT. PUTRA PERKASA ABADI | AO6: 4. Dept Head Operational
B7: SITE GIRI MULYA COAL PROJECT | AO7: CC: Logistic, GL Plant, Admint Plant.
B8: Monthly 11 Preventive Maintenance Schedule Periode Desember 2026 | AM8: 744
AL9: 1
B10: UNIT NO | C10: LOKASI | D10: MODEL 1 | E10: MODEL | F10: SMU READING 30 NOV 2023 | G10: 1 | H10: 44653 | I10: 44654 | J10: 44655 | K10: 44656 | L10: 44657 | M10: 44658 | N10: 44659 | O10: 44660 | P10: 44661 | Q10: 44662 | R10: 44663 | S10: 44664 | T10: 44665 | U10: 44666 | V10: 44667 | W10: 44668 | X10: 44669 | Y10: 44670 | Z10: 44671 | AA10: 44672 | AB10: 44673 | AC10: 44674 | AD10: 44675 | AE10: 44676 | AF10: 44677 | AG10: 44678 | AH10: 44679 | AI10: 44680 | AJ10: 44681 | AK10: 31 | AL10: EST. TOTAL DOWN TIME (hrs) | AM10: % PA | AO10: REPAIR OPTION REQUIRED / BACKLOG | AP10: REMAKS
G12: DES | H12: =G12 -> DES | I12: =H12 -> DES | J12: =I12 -> DES | K12: =J12 -> DES | L12: =K12 -> DES | M12: =L12 -> DES | N12: =M12 -> DES | O12: =N12 -> DES | ... AE12: =AD12 -> DES | AF12: =AB12 -> DES | AG12: =AF12 -> DES | AH12: =AG12 -> DES | AI12: =AE12 -> DES | AJ12: =AG12 -> DES | AK12: =AH12 -> DES | AM12: Monthly Forecast | AN12: Target
G13: =COUNT('OKT 2026'!G7:G308) -> 134 | H13: =COUNT('OKT 2026'!H7:H308) -> 134 | I13: =COUNT('OKT 2026'!I7:I308) -> 134 | J13: =COUNT('OKT 2026'!J7:J308) -> 135 | K13: =COUNT('OKT 2026'!K7:K308) -> 136 | L13: =COUNT('OKT 2026'!L7:L308) -> 134 | M13: =COUNT('OKT 2026'!M7:M308) -> 134 | N13: =COUNT('OKT 2026'!N7:N308) -> 134 | ... AK13: =COUNT('OKT 2026'!AK7:AK308) -> 135
B14: PA UNIT A2B PRODUCTION
B15: FORECAST AC SECTION TRACK
B16: D1511 | D16: D155A-6 | E16: D155A-6 | F16: 47671.9 | G16: 0 | H16: 0 | I16: 0 | J16: 0 | K16: 0 | L16: 0 | M16: 0 | N16: 0 | O16: 0 | P16: 0 | Q16: 0 | R16: 6 | S16: 0 | T16: 0 | U16: 0 | V16: 0 | W16: 0 | X16: 0 | Y16: 0 | Z16: 0 | AA16: 0 | AB16: 0 | AC16: 0 | AD16: 0 | AE16: 0 | AF16: 16 | AG16: 0 | AH16: 0 | AI16: 0 | AJ16: 0 | AK16: 0 | AL16: 53 | AM16: 0.92876344 | AN16: 0.922 | AO16: PMS 250 & PMS 4000 | AP16: expansi valeve | AQ16: 504000
AP17: thermostat elektrik | AQ17: 203000
AP18: drayer | AQ18: 250000
AP19: v-belt 38 | AQ19: 453250
AP20: oli ND08 | AQ20: 313500
AQ21: =SUM(AQ16:AQ20) -> 1723750
B23: D1518 | D23: D155A-6 | E23: D155A-6 | F23: 47930 | G23: 0 | H23: 0 | I23: 0 | J23: 0 | K23: 0 | L23: 0 | M23: 0 | N23: 0 | O23: 0 | P23: 0 | Q23: 0 | R23: 16 | S23: 0 | T23: 0 | U23: 0 | V23: 0 | W23: 0 | X23: 0 | Y23: 0 | Z23: 0 | AA23: 0 | AB23: 0 | AC23: 0 | AD23: 0 | AE23: 0 | AF23: 6 | AG23: 0 | AH23: 0 | AI23: 0 | AJ23: 0 | AK23: 0 | AL23: 53 | AM23: 0.92876344 | AN23: 0.922 | AO23: PMS 4000 & PMS 250 | AP23: expansi valeve | AQ23: 504000
AP24: thermostat elektrik | AQ24: 203000
AP25: drayer | AQ25: 250000
AP26: v-belt 38 | AQ26: 453250
AP27: oli ND08 | AQ27: 313500
AQ28: =SUM(AQ23:AQ27) -> 1723750
B30: D1520 | D30: D155A-6 | E30: D155A-6 | F30: 45745 | G30: 0 | H30: 0 | I30: 0 | J30: 0 | K30: 0 | L30: 0 | M30: 0 | N30: 6 | O30: 0 | P30: 0 | Q30: 0 | R30: 0 | S30: 0 | T30: 0 | U30: 0 | V30: 0 | W30: 0 | X30: 0 | Y30: 0 | Z30: 0 | AA30: 0 | AB30: 16 | AC30: 0 | AD30: 0 | AE30: 0 | AF30: 0 | AG30: 0 | AH30: 0 | AI30: 0 | AJ30: 0 | AK30: 0 | AL30: 53 | AM30: 0.92876344 | AN30: 0.922 | AO30: PMS 250 & PMS 2000 | AP30: kondensor | AQ30: 1864500
AP31: expansi valeve | AQ31: 504000
AP32: thermostat elektrik | AQ32: 203000
AP33: drayer | AQ33: 250000
AP34: v-belt 38 | AQ34: 453250
AP35: oli ND08 | AQ35: 313500
AQ36: =SUM(AQ30:AQ35) -> 3588250
B38: D1536 | D38: D155A-6 | E38: D155A-6 | F38: 29894 | G38: 0 | H38: 0 | I38: 0 | J38: 0 | K38: 0 | L38: 0 | M38: 0 | N38: 0 | O38: 0 | P38: 0 | Q38: 0 | R38: 0 | S38: 0 | T38: 16 | U38: 0 | V38: 0 | W38: 0 | X38: 0 | Y38: 0 | Z38: 0 | AA38: 0 | AB38: 0 | AC38: 0 | AD38: 0 | AE38: 0 | AF38: 0 | AG38: 0 | AH38: 6 | AI38: 0 | AJ38: 0 | AK38: 0 | AL38: 53 | AM38: 0.92876344 | AN38: 0.922 | AO38: PMS 2000 & PMS 250 | AP38: expansi valeve | AQ38: 504000
AP39: thermostat elektrik | AQ39: 203000
AP40: drayer | AQ40: 250000
AP41: v-belt 38 | AQ41: 453250
AP42: oli ND08 | AQ42: 313500
AQ43: =SUM(AQ38:AQ42) -> 1723750
B45: D5111AMM | D45: D155A-6 | E45: D155A-6 | F45: 47996 | G45: 0 | H45: 0 | I45: 0 | J45: 0 | K45: 0 | L45: 0 | M45: 0 | N45: 16 | O45: 0 | P45: 0 | Q45: 0 | R45: 0 | S45: 0 | T45: 0 | U45: 0 | V45: 0 | W45: 0 | X45: 0 | Y45: 0 | Z45: 0 | AA45: 0 | AB45: 6 | AC45: 0 | AD45: 0 | AE45: 0 | AF45: 0 | AG45: 0 | AH45: 0 | AI45: 0 | AJ45: 0 | AK45: 0 | AL45: 53 | AM45: 0.92876344 | AN45: 0.922 | AO45: PMS 4000 & PMS 250 | AP45: expansi valeve | AQ45: 504000
...
