Workbook

Sheet AMM PIK 2024-2025
A1: PIC CONTROL | C1: : HANDRE ADITYA PUTRA | F1: NOTE : ISI SESUAI YANG BERSANGKUTAN DAN ISI LANGSUNG DI SPREADSHEET JIKA EMANG AKAN DITARIK KE EXCELL PASTIKAN FORMAT DAN TABEL SESUAI. | AA1: NOTE : AUXILIARY TABLE ( AUTOMATIC FORMULA ) | AO1: NOTE : AUXILIARY TABLE ( AUTOMATIC FORMULA & CHART )
A2: LOCATION | C2: : AMM BENGALON KPC
A3: PERIODE | C3: : 2023 | F3: MONITORING CONTROL SPB-PO-DO-IT-INVOICE GMI AMM BENGALON KPC
A4: NOTE | C4: : | AO4: =NOW() -> 46301.766
AB5: DATA TABLE DASHBOARD SPB | AO5: DASHBOARD SPB GMI AMM PIK
D6: WAREHOUSE | Q6: MARKETING | U6: LOGISTICS | W6: FINANCE
A7: NO | B7: TANGGAL SPB | C7: NO SPB | D7: PART NUMBER | E7: PART NAME | F7: QTY | G7: UOM | H7: UNIT CODE | I7: TYPE UNIT | J7: BRAND | K7: PROBLEM | L7: PIC GMI | M7: PIC PPA | N7: NO WO | O7: STATUS WO | P7: WO DATE | Q7: NO PO | R7: PO DATE | S7: NO SO | T7: SO DATE | U7: NO DO | V7: DO DATE | W7: NO INVOICE | X7: TANGGAL KIRIM | Y7: STATUS PAYMENT | AA7: NO | AB7: NO SPB | AC7: TGL SPB | AD7: NO DO | AE7: TGL DO | AF7: NO WO | AG7: NO PO | AH7: NO SO | AI7: TGL so | AJ7: NO INVOICE | AK7: TANGAL INVOICE | AL7: STATUS SPB | AM7: STATUS PAYMENT | AO7: NO | AP7: DESCRIPTION | AQ7: DONE | AR7: WAITING | AS7: TOTAL
A8: 1 | B8: 45323 | C8: GMIAMMPIK/2024/01/001 | D8: 11L-3024 | E8: =VLOOKUP(D8,MP!$A$1:$C$14184,2,0) -> LED FLood Light 6 Eyes 18 Watt 10-30 VDC | F8: 5 | G8: PCS | H8: LOGISTIK | I8: =IFERROR(INDEX(POP!$I:$I,MATCH(H8,POP!$G:$G,0)),"general") -> general | J8: =IFERROR(INDEX(POP!$E:$E,MATCH(H8,POP!$G:$G,0)),"general") -> general | K8: KEBUTUHAN PIK | L8: FANDY | M8: RESTU | N8: REFF PO | O8: DONE FROM BC | P8: =B8 -> 45323 | Q8: 7000142922 | R8: 45313 | U8: DO 21865 | V8: 45293 | W8: GMI-0018033 | X8: 45328 | Y8: 45370 | AA8: 1 | AB8: GMIAMMPIK/2024/01/001 | AC8: =IFERROR(INDEX($B:$B,MATCH(AB8,$C:$C,FALSE)),"") -> 45323 | AD8: =INDEX($U:$U,MATCH(AB8,$C:$C,FALSE)) -> DO 21865 | AE8: =IFERROR(INDEX($V:$V,MATCH(AB8,$C:$C,FALSE)),"") -> 45293 | AF8: =IFERROR(INDEX($N:$N,MATCH(AB8,$C:$C,FALSE)),"") -> REFF PO | AG8: =INDEX($Q:$Q,MATCH(AB8,$C:$C,FALSE)) -> 7000142922 | AH8: =IFERROR(INDEX($S:$S,MATCH(AB8,$C:$C,FALSE)),"") | AI8: =IFERROR(INDEX($T:$T,MATCH(AB8,$C:$C,FALSE)),"") | AJ8: =INDEX($W:$W,MATCH(AB8,$C:$C,FALSE)) -> GMI-0018033 | AK8: =IFERROR(INDEX($X:$X,MATCH(AB8,$C:$C,FALSE)),"") -> 45328 | AL8: =INDEX($O:$O,MATCH(AF8,$N:$N,FALSE),"") -> DONE FROM BC | AM8: =INDEX($Y:$Y,MATCH(AB8,$C:$C,FALSE)) -> 45370 | AO8: 1 | AP8: SPB | AQ8: =COUNTIF($AL:$AL,"DONE FROM BC") -> 192 | AR8: =COUNTIF($AL:$AL,"WAITING") -> 0 | AS8: =SUM(AQ8:AR8) -> 192
A9: 2 | B9: 45336 | C9: GMIAMMPIK/2024/02/003 | D9: 11L-1290-ARW | E9: =VLOOKUP(D9,MP!$A$1:$C$14184,2,0) -> LED Combination Lamp Amber Red White | F9: 2 | G9: PCS | H9: PLTAM15 | I9: =IFERROR(INDEX(POP!$I:$I,MATCH(H9,POP!$G:$G,0)),"general") -> general | J9: =IFERROR(INDEX(POP!$E:$E,MATCH(H9,POP!$G:$G,0)),"general") -> general | K9: COMMISIONING UNIT | L9: FANDY | M9: RESTU | N9: 200000661855 | O9: DONE FROM BC | P9: =B9 -> 45336 | Q9: 9200006866 | R9: 45341 | U9: DO 22477 | V9: 29/2/2024 | W9: GMI-0018575 | X9: 45358 | Y9: 45412 | AA9: 2 | AB9: GMIAMMPIK/2024/02/003 | AC9: =IFERROR(INDEX($B:$B,MATCH(AB9,$C:$C,FALSE)),"") -> 45336 | AD9: =INDEX($U:$U,MATCH(AB9,$C:$C,FALSE)) -> DO 22477 | AE9: =IFERROR(INDEX($V:$V,MATCH(AB9,$C:$C,FALSE)),"") -> 29/2/2024 | AF9: =IFERROR(INDEX($N:$N,MATCH(AB9,$C:$C,FALSE)),"") -> 200000661855 | AG9: =INDEX($Q:$Q,MATCH(AB9,$C:$C,FALSE)) -> 9200006866 | AH9: =IFERROR(INDEX($S:$S,MATCH(AB9,$C:$C,FALSE)),"") | AI9: =IFERROR(INDEX($T:$T,MATCH(AB9,$C:$C,FALSE)),"") | AJ9: =INDEX($W:$W,MATCH(AB9,$C:$C,FALSE)) -> GMI-0018575 | AK9: =IFERROR(INDEX($X:$X,MATCH(AB9,$C:$C,FALSE)),"") -> 45358 | AL9: =INDEX($O:$O,MATCH(AF9,$N:$N,FALSE),"") -> DONE FROM BC | AM9: =INDEX($Y:$Y,MATCH(AB9,$C:$C,FALSE)) -> 45412 | AO9: 2 | AP9: DO | AQ9: =COUNTA($AD$8:$AD$277) -> 270 | AR9: =COUNTBLANK($AD$8:$AD$105) -> 1 | AS9: =SUM(AQ9:AR9) -> 271
A10: 3 | B10: 45336 | C10: GMIAMMPIK/2024/02/004 | D10: 11L-1290-ARW | E10: =VLOOKUP(D10,MP!$A$1:$C$14184,2,0) -> LED Combination Lamp Amber Red White | F10: 2 | G10: PCS | H10: PLTAM15 | I10: =IFERROR(INDEX(POP!$I:$I,MATCH(H10,POP!$G:$G,0)),"general") -> general | J10: =IFERROR(INDEX(POP!$E:$E,MATCH(H10,POP!$G:$G,0)),"general") -> general | K10: COMMISIONING UNIT | L10: FANDY | M10: RESTU | N10: 200000661851 | O10: DONE FROM BC | P10: =B10 -> 45336 | Q10: 9200006867 | U10: DO 22476 | V10: 29/2/2024 | W10: GMI-0018574 | X10: 45358 | Y10: 45412 | AA10: 3 | AB10: GMIAMMPIK/2024/02/004 | AC10: =IFERROR(INDEX($B:$B,MATCH(AB10,$C:$C,FALSE)),"") -> 45336 | AD10: =INDEX($U:$U,MATCH(AB10,$C:$C,FALSE)) -> DO 22476 | AE10: =IFERROR(INDEX($V:$V,MATCH(AB10,$C:$C,FALSE)),"") -> 29/2/2024 | AF10: =IFERROR(INDEX($N:$N,MATCH(AB10,$C:$C,FALSE)),"") -> 200000661851 | AG10: =INDEX($Q:$Q,MATCH(AB10,$C:$C,FALSE)) -> 9200006867 | AH10: =IFERROR(INDEX($S:$S,MATCH(AB10,$C:$C,FALSE)),"") | AI10: =IFERROR(INDEX($T:$T,MATCH(AB10,$C:$C,FALSE)),"") | AJ10: =INDEX($W:$W,MATCH(AB10,$C:$C,FALSE)) -> GMI-0018574 | AK10: =IFERROR(INDEX($X:$X,MATCH(AB10,$C:$C,FALSE)),"") -> 45358 | AL10: =INDEX($O:$O,MATCH(AF10,$N:$N,FALSE),"") -> DONE FROM BC | AM10: =INDEX($Y:$Y,MATCH(AB10,$C:$C,FALSE)) -> 45412 | AO10: 3 | AP10: PO | AQ10: =COUNTIF($AG:$AG,">0") -> 270 | AR10: =COUNTBLANK($AG$8:$AG$105) -> 0 | AS10: =SUM(AQ10:AR10) -> 270
A11: 4 | B11: 45336 | C11: GMIAMMPIK/2024/02/005 | D11: 11L-1290-ARW | E11: =VLOOKUP(D11,MP!$A$1:$C$14184,2,0) -> LED Combination Lamp Amber Red White | F11: 2 | G11: PCS | H11: PLTAM15 | I11: =IFERROR(INDEX(POP!$I:$I,MATCH(H11,POP!$G:$G,0)),"general") -> general | J11: =IFERROR(INDEX(POP!$E:$E,MATCH(H11,POP!$G:$G,0)),"general") -> general | K11: COMMISIONING UNIT | L11: FANDY | M11: RESTU | N11: 200000661847 | O11: DONE FROM BC | P11: =B11 -> 45336 | Q11: 9200006868 | U11: DO 22475 | V11: 29/2/2024 | W11: GMI-0018573 | X11: 45358 | Y11: 45412 | AA11: 4 | AB11: GMIAMMPIK/2024/02/005 | AC11: =IFERROR(INDEX($B:$B,MATCH(AB11,$C:$C,FALSE)),"") -> 45336 | AD11: =INDEX($U:$U,MATCH(AB11,$C:$C,FALSE)) -> DO 22475 | AE11: =IFERROR(INDEX($V:$V,MATCH(AB11,$C:$C,FALSE)),"") -> 29/2/2024 | AF11: =IFERROR(INDEX($N:$N,MATCH(AB11,$C:$C,FALSE)),"") -> 200000661847 | AG11: =INDEX($Q:$Q,MATCH(AB11,$C:$C,FALSE)) -> 9200006868 | AH11: =IFERROR(INDEX($S:$S,MATCH(AB11,$C:$C,FALSE)),"") | AI11: =IFERROR(INDEX($T:$T,MATCH(AB11,$C:$C,FALSE)),"") | AJ11: =INDEX($W:$W,MATCH(AB11,$C:$C,FALSE)) -> GMI-0018573 | AK11: =IFERROR(INDEX($X:$X,MATCH(AB11,$C:$C,FALSE)),"") -> 45358 | AL11: =INDEX($O:$O,MATCH(AF11,$N:$N,FALSE),"") -> DONE FROM BC | AM11: =INDEX($Y:$Y,MATCH(AB11,$C:$C,FALSE)) -> 45412 | AO11: 4 | AP11: INVOICE | AQ11: =COUNTA(AJ8:AJ277) -> 269 | AR11: =COUNTBLANK($AJ$8:$AJ$105) -> 1 | AS11: =SUM(AQ11:AR11) -> 270
A12: 5 | B12: 45336 | C12: GMIAMMPIK/2024/02/006 | D12: 11L-1290-ARW | E12: =VLOOKUP(D12,MP!$A$1:$C$14184,2,0) -> LED Combination Lamp Amber Red White | F12: 2 | G12: PCS | H12: PLTAM15 | I12: =IFERROR(INDEX(POP!$I:$I,MATCH(H12,POP!$G:$G,0)),"general") -> general | J12: =IFERROR(INDEX(POP!$E:$E,MATCH(H12,POP!$G:$G,0)),"general") -> general | K12: COMMISIONING UNIT | L12: FANDY | M12: RESTU | N12: 200000661838 | O12: DONE FROM BC | P12: =B12 -> 45336 | Q12: 9200006869 | U12: DO 22431 | V12: 29/2/2024 | W12: GMI-0018572 | X12: 45358 | Y12: 45412 | AA12: 5 | AB12: GMIAMMPIK/2024/02/006 | AC12: =IFERROR(INDEX($B:$B,MATCH(AB12,$C:$C,FALSE)),"") -> 45336 | AD12: =INDEX($U:$U,MATCH(AB12,$C:$C,FALSE)) -> DO 22431 | AE12: =IFERROR(INDEX($V:$V,MATCH(AB12,$C:$C,FALSE)),"") -> 29/2/2024 | AF12: =IFERROR(INDEX($N:$N,MATCH(AB12,$C:$C,FALSE)),"") -> 200000661838 | AG12: =INDEX($Q:$Q,MATCH(AB12,$C:$C,FALSE)) -> 9200006869 | AH12: =IFERROR(INDEX($S:$S,MATCH(AB12,$C:$C,FALSE)),"") | AI12: =IFERROR(INDEX($T:$T,MATCH(AB12,$C:$C,FALSE)),"") | AJ12: =INDEX($W:$W,MATCH(AB12,$C:$C,FALSE)) -> GMI-0018572 | AK12: =IFERROR(INDEX($X:$X,MATCH(AB12,$C:$C,FALSE)),"") -> 45358 | AL12: =INDEX($O:$O,MATCH(AF12,$N:$N,FALSE),"") -> DONE FROM BC | AM12: =INDEX($Y:$Y,MATCH(AB12,$C:$C,FALSE)) -> 45412
A13: 6 | B13: 45340 | C13: GMIAMMPIK/2024/02/007 | D13: 11L-3024 | E13: =VLOOKUP(D13,MP!$A$1:$C$14184,2,0) -> LED FLood Light 6 Eyes 18 Watt 10-30 VDC | F13: 2 | G13: PCS | H13: PLTAM15 | I13: =IFERROR(INDEX(POP!$I:$I,MATCH(H13,POP!$G:$G,0)),"general") -> general | J13: =IFERROR(INDEX(POP!$E:$E,MATCH(H13,POP!$G:$G,0)),"general") -> general | K13: COMMISIONING UNIT | L13: FANDY | M13: RESTU | N13: 200000661838 | O13: DONE FROM BC | P13: =B13 -> 45340 | Q13: 9200007063 | U13: DO 22394 | V13: 45325 | W13: GMI-0018571 | X13: 45358 | Y13: 45412 | AA13: 6 | AB13: GMIAMMPIK/2024/02/007 | AC13: =IFERROR(INDEX($B:$B,MATCH(AB13,$C:$C,FALSE)),"") -> 45340 | AD13: =INDEX($U:$U,MATCH(AB13,$C:$C,FALSE)) -> DO 22394 | AE13: =IFERROR(INDEX($V:$V,MATCH(AB13,$C:$C,FALSE)),"") -> 45325 | AF13: =IFERROR(INDEX($N:$N,MATCH(AB13,$C:$C,FALSE)),"") -> 200000661838 | AG13: =INDEX($Q:$Q,MATCH(AB13,$C:$C,FALSE)) -> 9200007063 | AH13: =IFERROR(INDEX($S:$S,MATCH(AB13,$C:$C,FALSE)),"") | AI13: =IFERROR(INDEX($T:$T,MATCH(AB13,$C:$C,FALSE)),"") | AJ13: =INDEX($W:$W,MATCH(AB13,$C:$C,FALSE)) -> GMI-0018571 | AK13: =IFERROR(INDEX($X:$X,MATCH(AB13,$C:$C,FALSE)),"") -> 45358 | AL13: =INDEX($O:$O,MATCH(AF13,$N:$N,FALSE),"") -> DONE FROM BC | AM13: =INDEX($Y:$Y,MATCH(AB13,$C:$C,FALSE)) -> 45412
A14: =A13+1 -> 7 | B14: 45340 | C14: GMIAMMPIK/2024/02/008 | D14: 11L-3024 | E14: =VLOOKUP(D14,MP!$A$1:$C$14184,2,0) -> LED FLood Light 6 Eyes 18 Watt 10-30 VDC | F14: 2 | G14: PCS | H14: PLTAM15 | I14: =IFERROR(INDEX(POP!$I:$I,MATCH(H14,POP!$G:$G,0)),"general") -> general | J14: =IFERROR(INDEX(POP!$E:$E,MATCH(H14,POP!$G:$G,0)),"general") -> general | K14: COMMISIONING UNIT | L14: FANDY | M14: RESTU | N14: 200000661851 | O14: DONE FROM BC | P14: =B14 -> 45340 | Q14: 9200007064 | U14: DO 22384 | V14: 45325 | W14: GMI-0018570 | X14: 45358 | Y14: 45412 | AA14: 7 | AB14: GMIAMMPIK/2024/02/008 | AC14: =IFERROR(INDEX($B:$B,MATCH(AB14,$C:$C,FALSE)),"") -> 45340 | AD14: =INDEX($U:$U,MATCH(AB14,$C:$C,FALSE)) -> DO 22384 | AE14: =IFERROR(INDEX($V:$V,MATCH(AB14,$C:$C,FALSE)),"") -> 45325 | AF14: =IFERROR(INDEX($N:$N,MATCH(AB14,$C:$C,FALSE)),"") -> 200000661851 | AG14: =INDEX($Q:$Q,MATCH(AB14,$C:$C,FALSE)) -> 9200007064 | AH14: =IFERROR(INDEX($S:$S,MATCH(AB14,$C:$C,FALSE)),"") | AI14: =IFERROR(INDEX($T:$T,MATCH(AB14,$C:$C,FALSE)),"") | AJ14: =INDEX($W:$W,MATCH(AB14,$C:$C,FALSE)) -> GMI-0018570 | AK14: =IFERROR(INDEX($X:$X,MATCH(AB14,$C:$C,FALSE)),"") -> 45358 | AL14: =INDEX($O:$O,MATCH(AF14,$N:$N,FALSE),"") -> DONE FROM BC | AM14: =INDEX($Y:$Y,MATCH(AB14,$C:$C,FALSE)) -> 45412
A15: =A14+1 -> 8 | B15: 45340 | C15: GMIAMMPIK/2024/02/009 | D15: 11L-3024 | E15: =VLOOKUP(D15,MP!$A$1:$C$14184,2,0) -> LED FLood Light 6 Eyes 18 Watt 10-30 VDC | F15: 2 | G15: PCS | H15: PLTAM15 | I15: =IFERROR(INDEX(POP!$I:$I,MATCH(H15,POP!$G:$G,0)),"general") -> general | J15: =IFERROR(INDEX(POP!$E:$E,MATCH(H15,POP!$G:$G,0)),"general") -> general | K15: COMMISIONING UNIT | L15: FANDY | M15: RESTU | N15: 200000661857 | O15: DONE FROM BC | P15: =B15 -> 45340 | Q15: 9200007065 | U15: DO 22382 | V15: 45325 | W15: GMI-0018569 | X15: 45358 | Y15: 45412 | AA15: 8 | AB15: GMIAMMPIK/2024/02/009 | AC15: =IFERROR(INDEX($B:$B,MATCH(AB15,$C:$C,FALSE)),"") -> 45340 | AD15: =INDEX($U:$U,MATCH(AB15,$C:$C,FALSE)) -> DO 22382 | AE15: =IFERROR(INDEX($V:$V,MATCH(AB15,$C:$C,FALSE)),"") -> 45325 | AF15: =IFERROR(INDEX($N:$N,MATCH(AB15,$C:$C,FALSE)),"") -> 200000661857 | AG15: =INDEX($Q:$Q,MATCH(AB15,$C:$C,FALSE)) -> 9200007065 | AH15: =IFERROR(INDEX($S:$S,MATCH(AB15,$C:$C,FALSE)),"") | AI15: =IFERROR(INDEX($T:$T,MATCH(AB15,$C:$C,FALSE)),"") | AJ15: =INDEX($W:$W,MATCH(AB15,$C:$C,FALSE)) -> GMI-0018569 | AK15: =IFERROR(INDEX($X:$X,MATCH(AB15,$C:$C,FALSE)),"") -> 45358 | AL15: =INDEX($O:$O,MATCH(AF15,$N:$N,FALSE),"") -> DONE FROM BC | AM15: =INDEX($Y:$Y,MATCH(AB15,$C:$C,FALSE)) -> 45412
A16: =A15+1 -> 9 | B16: 45345 | C16: GMIAMMPIK/2024/02/010 | D16: 14L-0160 | E16: =VLOOKUP(D16,MP!$A$1:$C$14184,2,0) -> Compressor Assy CAT 24V | F16: 1 | G16: PCS | H16: PLTAM15 | I16: =IFERROR(INDEX(POP!$I:$I,MATCH(H16,POP!$G:$G,0)),"general") -> general | J16: =IFERROR(INDEX(POP!$E:$E,MATCH(H16,POP!$G:$G,0)),"general") -> general | K16: CONSUMABLE PIK | L16: FANDY | M16: RESTU | N16: 200000665434 | O16: DONE FROM BC | P16: =B16 -> 45345 | Q16: 9200007301 | U16: DO 22381 | V16: 45325 | W16: GMI-0018568 | X16: 45358 | Y16: 45412 | AA16: 9 | AB16: GMIAMMPIK/2024/02/010 | AC16: =IFERROR(INDEX($B:$B,MATCH(AB16,$C:$C,FALSE)),"") -> 45345 | AD16: =INDEX($U:$U,MATCH(AB16,$C:$C,FALSE)) -> DO 22381 | AE16: =IFERROR(INDEX($V:$V,MATCH(AB16,$C:$C,FALSE)),"") -> 45325 | AF16: =IFERROR(INDEX($N:$N,MATCH(AB16,$C:$C,FALSE)),"") -> 200000665434 | AG16: =INDEX($Q:$Q,MATCH(AB16,$C:$C,FALSE)) -> 9200007301 | AH16: =IFERROR(INDEX($S:$S,MATCH(AB16,$C:$C,FALSE)),"") | AI16: =IFERROR(INDEX($T:$T,MATCH(AB16,$C:$C,FALSE)),"") | AJ16: =INDEX($W:$W,MATCH(AB16,$C:$C,FALSE)) -> GMI-0018568 | AK16: =IFERROR(INDEX($X:$X,MATCH(AB16,$C:$C,FALSE)),"") -> 45358 | AL16: =INDEX($O:$O,MATCH(AF16,$N:$N,FALSE),"") -> DONE FROM BC | AM16: =INDEX($Y:$Y,MATCH(AB16,$C:$C,FALSE)) -> 45412
A17: =A16+1 -> 10 | B17: 01 Maret 2024 | C17: GMIAMMPIK/2024/03/011 | D17: 11L-3024 | E17: =VLOOKUP(D17,MP!$A$1:$C$14184,2,0) -> LED FLood Light 6 Eyes 18 Watt 10-30 VDC | F17: 2 | G17: PCS | H17: PLTAM15 | I17: =IFERROR(INDEX(POP!$I:$I,MATCH(H17,POP!$G:$G,0)),"general") -> general | J17: =IFERROR(INDEX(POP!$E:$E,MATCH(H17,POP!$G:$G,0)),"general") -> general | K17: CONSUMABLE PIK | L17: FANDY | M17: RESTU | N17: 260000019088 | O17: DONE FROM BC | P17: =B17 -> 01 Maret 2024 | Q17: 9200007625 | R17: 44992 | U17: DO 22814 | V17: 16/3/2024 | W17: GMI-0018838 | X17: 45370 | Y17: 45412 | AA17: 10 | AB17: GMIAMMPIK/2024/03/011 | AC17: =IFERROR(INDEX($B:$B,MATCH(AB17,$C:$C,FALSE)),"") -> 01 Maret 2024 | AD17: =INDEX($U:$U,MATCH(AB17,$C:$C,FALSE)) -> DO 22814 | AE17: =IFERROR(INDEX($V:$V,MATCH(AB17,$C:$C,FALSE)),"") -> 16/3/2024 | AF17: =IFERROR(INDEX($N:$N,MATCH(AB17,$C:$C,FALSE)),"") -> 260000019088 | AG17: =INDEX($Q:$Q,MATCH(AB17,$C:$C,FALSE)) -> 9200007625 | AH17: =IFERROR(INDEX($S:$S,MATCH(AB17,$C:$C,FALSE)),"") | AI17: =IFERROR(INDEX($T:$T,MATCH(AB17,$C:$C,FALSE)),"") | AJ17: =INDEX($W:$W,MATCH(AB17,$C:$C,FALSE)) -> GMI-0018838 | AK17: =IFERROR(INDEX($X:$X,MATCH(AB17,$C:$C,FALSE)),"") -> 45370 | AL17: =INDEX($O:$O,MATCH(AF17,$N:$N,FALSE),"") -> DONE FROM BC | AM17: =INDEX($Y:$Y,MATCH(AB17,$C:$C,FALSE)) -> 45412
A18: =A17+1 -> 11 | B18: 01 Maret 2024 | C18: GMIAMMPIK/2024/03/012 | D18: 11L-3024 | E18: =VLOOKUP(D18,MP!$A$1:$C$14184,2,0) -> LED FLood Light 6 Eyes 18 Watt 10-30 VDC | F18: 6 | G18: PCS | H18: PLTAM15 | I18: =IFERROR(INDEX(POP!$I:$I,MATCH(H18,POP!$G:$G,0)),"general") -> general | J18: =IFERROR(INDEX(POP!$E:$E,MATCH(H18,POP!$G:$G,0)),"general") -> general | K18: CONSUMABLE PIK | L18: FANDY | M18: RESTU | N18: 200000667740 | O18: DONE FROM BC | P18: =B18 -> 01 Maret 2024 | Q18: 9200007626 | R18: 44992 | U18: DO 22815 | V18: 16/3/2024 | W18: GMI-0018837 | X18: 45370 | Y18: 45412 | AA18: 11 | AB18: GMIAMMPIK/2024/03/012 | AC18: =IFERROR(INDEX($B:$B,MATCH(AB18,$C:$C,FALSE)),"") -> 01 Maret 2024 | AD18: =INDEX($U:$U,MATCH(AB18,$C:$C,FALSE)) -> DO 22815 | AE18: =IFERROR(INDEX($V:$V,MATCH(AB18,$C:$C,FALSE)),"") -> 16/3/2024 | AF18: =IFERROR(INDEX($N:$N,MATCH(AB18,$C:$C,FALSE)),"") -> 200000667740 | AG18: =INDEX($Q:$Q,MATCH(AB18,$C:$C,FALSE)) -> 9200007626 | AH18: =IFERROR(INDEX($S:$S,MATCH(AB18,$C:$C,FALSE)),"") | AI18: =IFERROR(INDEX($T:$T,MATCH(AB18,$C:$C,FALSE)),"") | AJ18: =INDEX($W:$W,MATCH(AB18,$C:$C,FALSE)) -> GMI-0018837 | AK18: =IFERROR(INDEX($X:$X,MATCH(AB18,$C:$C,FALSE)),"") -> 45370 | AL18: =INDEX($O:$O,MATCH(AF18,$N:$N,FALSE),"") -> DONE FROM BC | AM18: =INDEX($Y:$Y,MATCH(AB18,$C:$C,FALSE)) -> 45412
A19: =A18+1 -> 12 | B19: 03 Maret 2024 | C19: GMIAMMPIK/2024/03/013 | D19: 11L-3024 | E19: =VLOOKUP(D19,MP!$A$1:$C$14184,2,0) -> LED FLood Light 6 Eyes 18 Watt 10-30 VDC | F19: 2 | G19: PCS | H19: PLTAM15 | I19: =IFERROR(INDEX(POP!$I:$I,MATCH(H19,POP!$G:$G,0)),"general") -> general | J19: =IFERROR(INDEX(POP!$E:$E,MATCH(H19,POP!$G:$G,0)),"general") -> general | K19: CONSUMABLE PIK | L19: FANDY | M19: RESTU | N19: 200000668254 | O19: DONE FROM BC | P19: =B19 -> 03 Maret 2024 | Q19: 7000146638 | R19: 44992 | U19: DO 22816 | V19: 16/3/2024 | W19: GMI-0018836 | X19: 45370 | Y19: 45412 | AA19: 12 | AB19: GMIAMMPIK/2024/03/013 | AC19: =IFERROR(INDEX($B:$B,MATCH(AB19,$C:$C,FALSE)),"") -> 03 Maret 2024 | AD19: =INDEX($U:$U,MATCH(AB19,$C:$C,FALSE)) -> DO 22816 | AE19: =IFERROR(INDEX($V:$V,MATCH(AB19,$C:$C,FALSE)),"") -> 16/3/2024 | AF19: =IFERROR(INDEX($N:$N,MATCH(AB19,$C:$C,FALSE)),"") -> 200000668254 | AG19: =INDEX($Q:$Q,MATCH(AB19,$C:$C,FALSE)) -> 7000146638 | AH19: =IFERROR(INDEX($S:$S,MATCH(AB19,$C:$C,FALSE)),"") | AI19: =IFERROR(INDEX($T:$T,MATCH(AB19,$C:$C,FALSE)),"") | AJ19: =INDEX($W:$W,MATCH(AB19,$C:$C,FALSE)) -> GMI-0018836 | AK19: =IFERROR(INDEX($X:$X,MATCH(AB19,$C:$C,FALSE)),"") -> 45370 | AL19: =INDEX($O:$O,MATCH(AF19,$N:$N,FALSE),"") -> DONE FROM BC | AM19: =INDEX($Y:$Y,MATCH(AB19,$C:$C,FALSE)) -> 45412
A20: =A19+1 -> 13 | B20: 4 Maret 2024 | C20: GMIAMMPIK/2024/03/014 | D20: 11L-3024 | E20: =VLOOKUP(D20,MP!$A$1:$C$14184,2,0) -> LED FLood Light 6 Eyes 18 Watt 10-30 VDC | F20: 4 | G20: PCS | H20: PLTAM15 | I20: =IFERROR(INDEX(POP!$I:$I,MATCH(H20,POP!$G:$G,0)),"general") -> general | J20: =IFERROR(INDEX(POP!$E:$E,MATCH(H20,POP!$G:$G,0)),"general") -> general | K20: CONSUMABLE PIK | L20: FANDY | M20: RESTU | N20: 200000668717 | O20: DONE FROM BC | P20: =B20 -> 4 Maret 2024 | Q20: 7000146657 | R20: 44992 | U20: DO 22817 | V20: 16/3/2024 | W20: GMI-0018835 | X20: 45370 | Y20: 45412 | AA20: 13 | AB20: GMIAMMPIK/2024/03/014 | AC20: =IFERROR(INDEX($B:$B,MATCH(AB20,$C:$C,FALSE)),"") -> 4 Maret 2024 | AD20: =INDEX($U:$U,MATCH(AB20,$C:$C,FALSE)) -> DO 22817 | AE20: =IFERROR(INDEX($V:$V,MATCH(AB20,$C:$C,FALSE)),"") -> 16/3/2024 | AF20: =IFERROR(INDEX($N:$N,MATCH(AB20,$C:$C,FALSE)),"") -> 200000668717 | AG20: =INDEX($Q:$Q,MATCH(AB20,$C:$C,FALSE)) -> 7000146657 | AH20: =IFERROR(INDEX($S:$S,MATCH(AB20,$C:$C,FALSE)),"") | AI20: =IFERROR(INDEX($T:$T,MATCH(AB20,$C:$C,FALSE)),"") | AJ20: =INDEX($W:$W,MATCH(AB20,$C:$C,FALSE)) -> GMI-0018835 | AK20: =IFERROR(INDEX($X:$X,MATCH(AB20,$C:$C,FALSE)),"") -> 45370 | AL20: =INDEX($O:$O,MATCH(AF20,$N:$N,FALSE),"") -> DONE FROM BC | AM20: =INDEX($Y:$Y,MATCH(AB20,$C:$C,FALSE)) -> 45412
A21: =A20+1 -> 14 | B21: 07 Maret 2024 | C21: GMIAMMPIK/2024/03/015 | D21: 11L-3024 | E21: =VLOOKUP(D21,MP!$A$1:$C$14184,2,0) -> LED FLood Light 6 Eyes 18 Watt 10-30 VDC | F21: 2 | G21: PCS | H21: PLTAM15 | I21: =IFERROR(INDEX(POP!$I:$I,MATCH(#REF!,POP!$G:$G,0)),"general") -> general | J21: =IFERROR(INDEX(POP!$E:$E,MATCH(#REF!,POP!$G:$G,0)),"general") -> general | K21: CONSUMABLE PIK | L21: FANDY | M21: NUGROHO | N21: 200000669795 | O21: DONE FROM BC | P21: =B21 -> 07 Maret 2024 | Q21: 9200007868 | R21: 45370 | U21: DO 23013 | V21: 25/3/2024 | W21: GMI-0019168 | X21: 45381 | Y21: 45429 | AA21: 14 | AB21: GMIAMMPIK/2024/03/015 | AC21: =IFERROR(INDEX($B:$B,MATCH(AB21,$C:$C,FALSE)),"") -> 07 Maret 2024 | AD21: =INDEX($U:$U,MATCH(AB21,$C:$C,FALSE)) -> DO 23013 | AE21: =IFERROR(INDEX($V:$V,MATCH(AB21,$C:$C,FALSE)),"") -> 25/3/2024 | AF21: =IFERROR(INDEX($N:$N,MATCH(AB21,$C:$C,FALSE)),"") -> 200000669795 | AG21: =INDEX($Q:$Q,MATCH(AB21,$C:$C,FALSE)) -> 9200007868 | AH21: =IFERROR(INDEX($S:$S,MATCH(AB21,$C:$C,FALSE)),"") | AI21: =IFERROR(INDEX($T:$T,MATCH(AB21,$C:$C,FALSE)),"") | AJ21: =INDEX($W:$W,MATCH(AB21,$C:$C,FALSE)) -> GMI-0019168 | AK21: =IFERROR(INDEX($X:$X,MATCH(AB21,$C:$C,FALSE)),"") -> 45381 | AL21: =INDEX($O:$O,MATCH(AF21,$N:$N,FALSE),"") -> DONE FROM BC | AM21: =INDEX($Y:$Y,MATCH(AB21,$C:$C,FALSE)) -> 45429
A22: =A21+1 -> 15 | B22: 07 Maret 2024 | C22: GMIAMMPIK/2024/03/016 | D22: 11L-3024 | E22: =VLOOKUP(D22,MP!$A$1:$C$14184,2,0) -> LED FLood Light 6 Eyes 18 Watt 10-30 VDC | F22: 1 | G22: PCS | H22: PLTAM15 | I22: =IFERROR(INDEX(POP!$I:$I,MATCH(#REF!,POP!$G:$G,0)),"general") -> general | J22: =IFERROR(INDEX(POP!$E:$E,MATCH(#REF!,POP!$G:$G,0)),"general") -> general | K22: CONSUMABLE PIK | L22: FANDY | M22: NUGROHO | N22: 200000669870 | O22: DONE FROM BC | P22: =B22 -> 07 Maret 2024 | Q22: 9200007887 | R22: 45370 | U22: DO 23010 | V22: 25/3/2024 | W22: GMI-0019165 | X22: 45381 | Y22: 45429 | AA22: 15 | AB22: GMIAMMPIK/2024/03/016 | AC22: =IFERROR(INDEX($B:$B,MATCH(AB22,$C:$C,FALSE)),"") -> 07 Maret 2024 | AD22: =INDEX($U:$U,MATCH(AB22,$C:$C,FALSE)) -> DO 23010 | AE22: =IFERROR(INDEX($V:$V,MATCH(AB22,$C:$C,FALSE)),"") -> 25/3/2024 | AF22: =IFERROR(INDEX($N:$N,MATCH(AB22,$C:$C,FALSE)),"") -> 200000669870 | AG22: =INDEX($Q:$Q,MATCH(AB22,$C:$C,FALSE)) -> 9200007887 | AH22: =IFERROR(INDEX($S:$S,MATCH(AB22,$C:$C,FALSE)),"") | AI22: =IFERROR(INDEX($T:$T,MATCH(AB22,$C:$C,FALSE)),"") | AJ22: =INDEX($W:$W,MATCH(AB22,$C:$C,FALSE)) -> GMI-0019165 | AK22: =IFERROR(INDEX($X:$X,MATCH(AB22,$C:$C,FALSE)),"") -> 45381 | AL22: =INDEX($O:$O,MATCH(AF22,$N:$N,FALSE),"") -> DONE FROM BC | AM22: =INDEX($Y:$Y,MATCH(AB22,$C:$C,FALSE)) -> 45429
A23: =A22+1 -> 16 | B23: 16 Maret 2024 | C23: GMIAMMPIK/2024/03/017 | D23: 11L-3024 | E23: =VLOOKUP(D23,MP!$A$1:$C$14184,2,0) -> LED FLood Light 6 Eyes 18 Watt 10-30 VDC | F23: 1 | G23: PCS | H23: WP509 | I23: =IFERROR(INDEX(POP!$I:$I,MATCH(#REF!,POP!$G:$G,0)),"general") -> general | J23: =IFERROR(INDEX(POP!$E:$E,MATCH(#REF!,POP!$G:$G,0)),"general") -> general | K23: CONSUMABLE PIK | L23: FANDY | M23: NUGROHO | N23: 200000672951 | O23: DONE FROM BC | P23: =B23 -> 16 Maret 2024 | Q23: 7000147720 | R23: 45370 | U23: DO 23011 | V23: 25/3/2024 | W23: GMI-0019166 | X23: 45381 | Y23: 45429 | AA23: =AA22+1 -> 16 | AB23: GMIAMMPIK/2024/03/017 | AC23: =IFERROR(INDEX($B:$B,MATCH(AB23,$C:$C,FALSE)),"") -> 16 Maret 2024 | AD23: =INDEX($U:$U,MATCH(AB23,$C:$C,FALSE)) -> DO 23011 | AE23: =IFERROR(INDEX($V:$V,MATCH(AB23,$C:$C,FALSE)),"") -> 25/3/2024 | AF23: =IFERROR(INDEX($N:$N,MATCH(AB23,$C:$C,FALSE)),"") -> 200000672951 | AG23: =INDEX($Q:$Q,MATCH(AB23,$C:$C,FALSE)) -> 7000147720 | AH23: =IFERROR(INDEX($S:$S,MATCH(AB23,$C:$C,FALSE)),"") | AI23: =IFERROR(INDEX($T:$T,MATCH(AB23,$C:$C,FALSE)),"") | AJ23: =INDEX($W:$W,MATCH(AB23,$C:$C,FALSE)) -> GMI-0019166 | AK23: =IFERROR(INDEX($X:$X,MATCH(AB23,$C:$C,FALSE)),"") -> 45381 | AL23: =INDEX($O:$O,MATCH(AF23,$N:$N,FALSE),"") -> DONE FROM BC | AM23: =INDEX($Y:$Y,MATCH(AB23,$C:$C,FALSE)) -> 45429
A24: =A23+1 -> 17 | B24: 18 Maret 2024 | C24: GMIAMMPIK/2024/03/018 | D24: 11L-3024 | E24: =VLOOKUP(D24,MP!$A$1:$C$14184,2,0) -> LED FLood Light 6 Eyes 18 Watt 10-30 VDC | F24: 2 | G24: PCS | H24: PLTAM15 | I24: =IFERROR(INDEX(POP!$I:$I,MATCH(#REF!,POP!$G:$G,0)),"general") -> general | J24: =IFERROR(INDEX(POP!$E:$E,MATCH(#REF!,POP!$G:$G,0)),"general") -> general | K24: REPLACE WORKLAMP | L24: FANDY | M24: RESTU | N24: 200000673701 | O24: DONE FROM BC | P24: =B24 -> 18 Maret 2024 | Q24: 9200008333 | R24: 45370 | U24: DO 23012 | V24: 25/3/2024 | W24: GMI-0019167 | X24: 45381 | Y24: 45429 | AA24: =AA23+1 -> 17 | AB24: GMIAMMPIK/2024/03/018 | AC24: =IFERROR(INDEX($B:$B,MATCH(AB24,$C:$C,FALSE)),"") -> 18 Maret 2024 | AD24: =INDEX($U:$U,MATCH(AB24,$C:$C,FALSE)) -> DO 23012 | AE24: =IFERROR(INDEX($V:$V,MATCH(AB24,$C:$C,FALSE)),"") -> 25/3/2024 | AF24: =IFERROR(INDEX($N:$N,MATCH(AB24,$C:$C,FALSE)),"") -> 200000673701 | AG24: =INDEX($Q:$Q,MATCH(AB24,$C:$C,FALSE)) -> 9200008333 | AH24: =IFERROR(INDEX($S:$S,MATCH(AB24,$C:$C,FALSE)),"") | AI24: =IFERROR(INDEX($T:$T,MATCH(AB24,$C:$C,FALSE)),"") | AJ24: =INDEX($W:$W,MATCH(AB24,$C:$C,FALSE)) -> GMI-0019167 | AK24: =IFERROR(INDEX($X:$X,MATCH(AB24,$C:$C,FALSE)),"") -> 45381 | AL24: =INDEX($O:$O,MATCH(AF24,$N:$N,FALSE),"") -> DONE FROM BC | AM24: =INDEX($Y:$Y,MATCH(AB24,$C:$C,FALSE)) -> 45429
A25: =A24+1 -> 18 | B25: 19 Maret 2024 | C25: GMIAMMPIK/2024/03/019 | D25: 11L-3024 | E25: =VLOOKUP(D25,MP!$A$1:$C$14184,2,0) -> LED FLood Light 6 Eyes 18 Watt 10-30 VDC | F25: 1 | G25: PCS | H25: PLTAM15 | I25: =IFERROR(INDEX(POP!$I:$I,MATCH(H25,POP!$G:$G,0)),"general") -> general | J25: =IFERROR(INDEX(POP!$E:$E,MATCH(H25,POP!$G:$G,0)),"general") -> general | K25: CONSUMABLE PIK | L25: FANDY | M25: RESTU | N25: 200000671011 | O25: DONE FROM BC | P25: =B25 -> 19 Maret 2024 | Q25: 7000147258 | R25: 45370 | U25: DO 23014 | V25: 25/3/2024 | W25: GMI-0019169 | X25: 45381 | Y25: 45429 | AA25: =AA24+1 -> 18 | AB25: GMIAMMPIK/2024/03/019 | AC25: =IFERROR(INDEX($B:$B,MATCH(AB25,$C:$C,FALSE)),"") -> 19 Maret 2024 | AD25: =INDEX($U:$U,MATCH(AB25,$C:$C,FALSE)) -> DO 23014 | AE25: =IFERROR(INDEX($V:$V,MATCH(AB25,$C:$C,FALSE)),"") -> 25/3/2024 | AF25: =IFERROR(INDEX($N:$N,MATCH(AB25,$C:$C,FALSE)),"") -> 200000671011 | AG25: =INDEX($Q:$Q,MATCH(AB25,$C:$C,FALSE)) -> 7000147258 | AH25: =IFERROR(INDEX($S:$S,MATCH(AB25,$C:$C,FALSE)),"") | AI25: =IFERROR(INDEX($T:$T,MATCH(AB25,$C:$C,FALSE)),"") | AJ25: =INDEX($W:$W,MATCH(AB25,$C:$C,FALSE)) -> GMI-0019169 | AK25: =IFERROR(INDEX($X:$X,MATCH(AB25,$C:$C,FALSE)),"") -> 45381 | AL25: =INDEX($O:$O,MATCH(AF25,$N:$N,FALSE),"") -> DONE FROM BC | AM25: =INDEX($Y:$Y,MATCH(AB25,$C:$C,FALSE)) -> 45429
A26: =A25+1 -> 19 | B26: 19 Maret 2024 | C26: GMIAMMPIK/2024/03/020 | D26: 11L-3024 | E26: =VLOOKUP(D26,MP!$A$1:$C$14184,2,0) -> LED FLood Light 6 Eyes 18 Watt 10-30 VDC | F26: 2 | G26: PCS | H26: D5834 | I26: =IFERROR(INDEX(POP!$I:$I,MATCH(H26,POP!$G:$G,0)),"general") -> general | J26: =IFERROR(INDEX(POP!$E:$E,MATCH(H26,POP!$G:$G,0)),"general") -> general | K26: REPLACE WORKLAMP | L26: FANDY | M26: FAUZI | N26: 200000673952 | O26: DONE FROM BC | P26: =B26 -> 19 Maret 2024 | Q26: 9200008360 | R26: 45378 | U26: DO 23085 | V26: 28/3/2024 | W26: GMI-0019268 | X26: 45386 | Y26: 45429 | AA26: =AA25+1 -> 19 | AB26: GMIAMMPIK/2024/03/020 | AC26: =IFERROR(INDEX($B:$B,MATCH(AB26,$C:$C,FALSE)),"") -> 19 Maret 2024 | AD26: =INDEX($U:$U,MATCH(AB26,$C:$C,FALSE)) -> DO 23085 | AE26: =IFERROR(INDEX($V:$V,MATCH(AB26,$C:$C,FALSE)),"") -> 28/3/2024 | AF26: =IFERROR(INDEX($N:$N,MATCH(AB26,$C:$C,FALSE)),"") -> 200000673952 | AG26: =INDEX($Q:$Q,MATCH(AB26,$C:$C,FALSE)) -> 9200008360 | AH26: =IFERROR(INDEX($S:$S,MATCH(AB26,$C:$C,FALSE)),"") | AI26: =IFERROR(INDEX($T:$T,MATCH(AB26,$C:$C,FALSE)),"") | AJ26: =INDEX($W:$W,MATCH(AB26,$C:$C,FALSE)) -> GMI-0019268 | AK26: =IFERROR(INDEX($X:$X,MATCH(AB26,$C:$C,FALSE)),"") -> 45386 | AL26: =INDEX($O:$O,MATCH(AF26,$N:$N,FALSE),"") -> DONE FROM BC | AM26: =INDEX($Y:$Y,MATCH(AB26,$C:$C,FALSE)) -> 45429
A27: =A26+1 -> 20 | B27: 21 Maret 2024 | C27: GMIAMMPIK/2024/03/021 | D27: 11L-3024 | E27: =VLOOKUP(D27,MP!$A$1:$C$14184,2,0) -> LED FLood Light 6 Eyes 18 Watt 10-30 VDC | F27: 1 | G27: PCS | H27: PLTAM15 | I27: =IFERROR(INDEX(POP!$I:$I,MATCH(H27,POP!$G:$G,0)),"general") -> general | J27: =IFERROR(INDEX(POP!$E:$E,MATCH(H27,POP!$G:$G,0)),"general") -> general | K27: REPLACE WORKLAMP | L27: FANDY | M27: FAUZI | N27: 200000674807 | O27: DONE FROM BC | P27: =B27 -> 21 Maret 2024 | Q27: 9200008514 | R27: 45378 | U27: DO 23079 | V27: 28/3/2024 | W27: GMI-0019266 | X27: 45386 | Y27: 45429 | AA27: =AA26+1 -> 20 | AB27: GMIAMMPIK/2024/03/021 | AC27: =IFERROR(INDEX($B:$B,MATCH(AB27,$C:$C,FALSE)),"") -> 21 Maret 2024 | AD27: =INDEX($U:$U,MATCH(AB27,$C:$C,FALSE)) -> DO 23079 | AE27: =IFERROR(INDEX($V:$V,MATCH(AB27,$C:$C,FALSE)),"") -> 28/3/2024 | AF27: =IFERROR(INDEX($N:$N,MATCH(AB27,$C:$C,FALSE)),"") -> 200000674807 | AG27: =INDEX($Q:$Q,MATCH(AB27,$C:$C,FALSE)) -> 9200008514 | AH27: =IFERROR(INDEX($S:$S,MATCH(AB27,$C:$C,FALSE)),"") | AI27: =IFERROR(INDEX($T:$T,MATCH(AB27,$C:$C,FALSE)),"") | AJ27: =INDEX($W:$W,MATCH(AB27,$C:$C,FALSE)) -> GMI-0019266 | AK27: =IFERROR(INDEX($X:$X,MATCH(AB27,$C:$C,FALSE)),"") -> 45386 | AL27: =INDEX($O:$O,MATCH(AF27,$N:$N,FALSE),"") -> DONE FROM BC | AM27: =INDEX($Y:$Y,MATCH(AB27,$C:$C,FALSE)) -> 45429
A28: =A27+1 -> 21 | B28: 25 Maret 2024 | C28: GMIAMMPIK/2024/03/022 | D28: 11L-3024 | E28: =VLOOKUP(D28,MP!$A$1:$C$14184,2,0) -> LED FLood Light 6 Eyes 18 Watt 10-30 VDC | F28: 1 | G28: PCS | H28: G5816 | I28: =IFERROR(INDEX(POP!$I:$I,MATCH(H28,POP!$G:$G,0)),"general") -> general | J28: =IFERROR(INDEX(POP!$E:$E,MATCH(H28,POP!$G:$G,0)),"general") -> general | K28: REPLACE WORKLAMP | L28: FANDY | M28: FAUZI | N28: 200000676203 | O28: DONE FROM BC | P28: =B28 -> 25 Maret 2024 | Q28: 9200008672 | R28: 45378 | U28: DO 23083 | V28: 28/3/2024 | W28: GMI-0019267 | X28: 45386 | Y28: 45429 | AA28: =AA27+1 -> 21 | AB28: GMIAMMPIK/2024/03/022 | AC28: =IFERROR(INDEX($B:$B,MATCH(AB28,$C:$C,FALSE)),"") -> 25 Maret 2024 | AD28: =INDEX($U:$U,MATCH(AB28,$C:$C,FALSE)) -> DO 23083 | AE28: =IFERROR(INDEX($V:$V,MATCH(AB28,$C:$C,FALSE)),"") -> 28/3/2024 | AF28: =IFERROR(INDEX($N:$N,MATCH(AB28,$C:$C,FALSE)),"") -> 200000676203 | AG28: =INDEX($Q:$Q,MATCH(AB28,$C:$C,FALSE)) -> 9200008672 | AH28: =IFERROR(INDEX($S:$S,MATCH(AB28,$C:$C,FALSE)),"") | AI28: =IFERROR(INDEX($T:$T,MATCH(AB28,$C:$C,FALSE)),"") | AJ28: =INDEX($W:$W,MATCH(AB28,$C:$C,FALSE)) -> GMI-0019267 | AK28: =IFERROR(INDEX($X:$X,MATCH(AB28,$C:$C,FALSE)),"") -> 45386 | AL28: =INDEX($O:$O,MATCH(AF28,$N:$N,FALSE),"") -> DONE FROM BC | AM28: =INDEX($Y:$Y,MATCH(AB28,$C:$C,FALSE)) -> 45429
A29: =A28+1 -> 22 | B29: 45385 | C29: GMIAMMPIK/2024/04/023 | D29: 11L-3024 | E29: =VLOOKUP(D29,MP!$A$1:$C$14184,2,0) -> LED FLood Light 6 Eyes 18 Watt 10-30 VDC | F29: 1 | G29: PCS | H29: W52606 | I29: =IFERROR(INDEX(POP!$I:$I,MATCH(H29,POP!$G:$G,0)),"general") -> general | J29: =IFERROR(INDEX(POP!$E:$E,MATCH(H29,POP!$G:$G,0)),"general") -> general | K29: REPLACE WORKLAMP | L29: FANDY | M29: FAUZI | N29: 200000679595 | O29: DONE FROM BC | P29: =B29 -> 45385 | Q29: 9200009206 | R29: 45400 | U29: DO 23492 | V29: 26/4/2024 | W29: GMI-0019594 | X29: 45408 | Y29: 45457 | AA29: =AA28+1 -> 22 | AB29: GMIAMMPIK/2024/04/023 | AC29: =IFERROR(INDEX($B:$B,MATCH(AB29,$C:$C,FALSE)),"") -> 45385 | AD29: =INDEX($U:$U,MATCH(AB29,$C:$C,FALSE)) -> DO 23492 | AE29: =IFERROR(INDEX($V:$V,MATCH(AB29,$C:$C,FALSE)),"") -> 26/4/2024 | AF29: =IFERROR(INDEX($N:$N,MATCH(AB29,$C:$C,FALSE)),"") -> 200000679595 | AG29: =INDEX($Q:$Q,MATCH(AB29,$C:$C,FALSE)) -> 9200009206 | AH29: =IFERROR(INDEX($S:$S,MATCH(AB29,$C:$C,FALSE)),"") | AI29: =IFERROR(INDEX($T:$T,MATCH(AB29,$C:$C,FALSE)),"") | AJ29: =INDEX($W:$W,MATCH(AB29,$C:$C,FALSE)) -> GMI-0019594 | AK29: =IFERROR(INDEX($X:$X,MATCH(AB29,$C:$C,FALSE)),"") -> 45408 | AL29: =INDEX($O:$O,MATCH(AF29,$N:$N,FALSE),"") -> DONE FROM BC | AM29: =INDEX($Y:$Y,MATCH(AB29,$C:$C,FALSE)) -> 45457
A30: =A29+1 -> 23 | B30: 45386 | C30: GMIAMMPIK/2024/04/024 | D30: 11L-3024 | E30: =VLOOKUP(D30,MP!$A$1:$C$14184,2,0) -> LED FLood Light 6 Eyes 18 Watt 10-30 VDC | F30: 1 | G30: PCS | H30: H57106 | I30: =IFERROR(INDEX(POP!$I:$I,MATCH(H30,POP!$G:$G,0)),"general") -> general | J30: =IFERROR(INDEX(POP!$E:$E,MATCH(H30,POP!$G:$G,0)),"general") -> general | K30: REPLACE WORKLAMP | L30: FANDY | M30: FAUZI | N30: 200000680006 | O30: DONE FROM BC | P30: =B30 -> 45386 | Q30: 7000149477 | R30: 45400 | U30: DO 23493 | V30: 26/4/2024 | W30: GMI-0019595 | X30: 45408 | Y30: 45457 | AA30: =AA29+1 -> 23 | AB30: GMIAMMPIK/2024/04/024 | AC30: =IFERROR(INDEX($B:$B,MATCH(AB30,$C:$C,FALSE)),"") -> 45386 | AD30: =INDEX($U:$U,MATCH(AB30,$C:$C,FALSE)) -> DO 23493 | AE30: =IFERROR(INDEX($V:$V,MATCH(AB30,$C:$C,FALSE)),"") -> 26/4/2024 | AF30: =IFERROR(INDEX($N:$N,MATCH(AB30,$C:$C,FALSE)),"") -> 200000680006 | AG30: =INDEX($Q:$Q,MATCH(AB30,$C:$C,FALSE)) -> 7000149477 | AH30: =IFERROR(INDEX($S:$S,MATCH(AB30,$C:$C,FALSE)),"") | AI30: =IFERROR(INDEX($T:$T,MATCH(AB30,$C:$C,FALSE)),"") | AJ30: =INDEX($W:$W,MATCH(AB30,$C:$C,FALSE)) -> GMI-0019595 | AK30: =IFERROR(INDEX($X:$X,MATCH(AB30,$C:$C,FALSE)),"") -> 45408 | AL30: =INDEX($O:$O,MATCH(AF30,$N:$N,FALSE),"") -> DONE FROM BC | AM30: =INDEX($Y:$Y,MATCH(AB30,$C:$C,FALSE)) -> 45457
A31: =A30+1 -> 24 | B31: 45386 | C31: GMIAMMPIK/2024/04/025 | D31: 11L-3024 | E31: =VLOOKUP(D31,MP!$A$1:$C$14184,2,0) -> LED FLood Light 6 Eyes 18 Watt 10-30 VDC | F31: 1 | G31: PCS | H31: DA4826PPA | I31: =IFERROR(INDEX(POP!$I:$I,MATCH(H31,POP!$G:$G,0)),"general") -> general | J31: =IFERROR(INDEX(POP!$E:$E,MATCH(H31,POP!$G:$G,0)),"general") -> general | K31: REPLACE WORKLAMP | L31: FANDY | M31: FAUZI | N31: 200000680007 | O31: DONE FROM BC | P31: =B31 -> 45386 | Q31: 7000149478 | R31: 45400 | U31: DO 23495 | V31: 26/4/2024 | W31: GMI-0019597 | X31: 45408 | Y31: 45457 | AA31: =AA30+1 -> 24 | AB31: GMIAMMPIK/2024/04/025 | AC31: =IFERROR(INDEX($B:$B,MATCH(AB31,$C:$C,FALSE)),"") -> 45386 | AD31: =INDEX($U:$U,MATCH(AB31,$C:$C,FALSE)) -> DO 23495 | AE31: =IFERROR(INDEX($V:$V,MATCH(AB31,$C:$C,FALSE)),"") -> 26/4/2024 | AF31: =IFERROR(INDEX($N:$N,MATCH(AB31,$C:$C,FALSE)),"") -> 200000680007 | AG31: =INDEX($Q:$Q,MATCH(AB31,$C:$C,FALSE)) -> 7000149478 | AH31: =IFERROR(INDEX($S:$S,MATCH(AB31,$C:$C,FALSE)),"") | AI31: =IFERROR(INDEX($T:$T,MATCH(AB31,$C:$C,FALSE)),"") | AJ31: =INDEX($W:$W,MATCH(AB31,$C:$C,FALSE)) -> GMI-0019597 | AK31: =IFERROR(INDEX($X:$X,MATCH(AB31,$C:$C,FALSE)),"") -> 45408 | AL31: =INDEX($O:$O,MATCH(AF31,$N:$N,FALSE),"") -> DONE FROM BC | AM31: =INDEX($Y:$Y,MATCH(AB31,$C:$C,FALSE)) -> 45457
A32: =A31+1 -> 25 | B32: 45395 | C32: GMIAMMPIK/2024/04/026 | D32: 11L-3024 | E32: =VLOOKUP(D32,MP!$A$1:$C$14184,2,0) -> LED FLood Light 6 Eyes 18 Watt 10-30 VDC | F32: 1 | G32: PCS | H32: G5816 | I32: =IFERROR(INDEX(POP!$I:$I,MATCH(H32,POP!$G:$G,0)),"general") -> general | J32: =IFERROR(INDEX(POP!$E:$E,MATCH(H32,POP!$G:$G,0)),"general") -> general | K32: REPLACE WORKLAMP | L32: FANDY | M32: FAUZI | N32: 200000682189 | O32: DONE FROM BC | P32: =B32 -> 45395 | Q32: 9200009515 | R32: 45400 | U32: DO 23494 | V32: 26/4/2024 | W32: GMI-0019596 | X32: 45408 | Y32: 45457 | AA32: =AA31+1 -> 25 | AB32: GMIAMMPIK/2024/04/026 | AC32: =IFERROR(INDEX($B:$B,MATCH(AB32,$C:$C,FALSE)),"") -> 45395 | AD32: =INDEX($U:$U,MATCH(AB32,$C:$C,FALSE)) -> DO 23494 | AE32: =IFERROR(INDEX($V:$V,MATCH(AB32,$C:$C,FALSE)),"") -> 26/4/2024 | AF32: =IFERROR(INDEX($N:$N,MATCH(AB32,$C:$C,FALSE)),"") -> 200000682189 | AG32: =INDEX($Q:$Q,MATCH(AB32,$C:$C,FALSE)) -> 9200009515 | AH32: =IFERROR(INDEX($S:$S,MATCH(AB32,$C:$C,FALSE)),"") | AI32: =IFERROR(INDEX($T:$T,MATCH(AB32,$C:$C,FALSE)),"") | AJ32: =INDEX($W:$W,MATCH(AB32,$C:$C,FALSE)) -> GMI-0019596 | AK32: =IFERROR(INDEX($X:$X,MATCH(AB32,$C:$C,FALSE)),"") -> 45408 | AL32: =INDEX($O:$O,MATCH(AF32,$N:$N,FALSE),"") -> DONE FROM BC | AM32: =INDEX($Y:$Y,MATCH(AB32,$C:$C,FALSE)) -> 45457
A33: =A32+1 -> 26 | B33: 45398 | C33: GMIAMMPIK/2024/04/027 | D33: 11L-3024 | E33: =VLOOKUP(D33,MP!$A$1:$C$14184,2,0) -> LED FLood Light 6 Eyes 18 Watt 10-30 VDC | F33: 1 | G33: PCS | H33: FT52610 | I33: =IFERROR(INDEX(POP!$I:$I,MATCH(H33,POP!$G:$G,0)),"general") -> general | J33: =IFERROR(INDEX(POP!$E:$E,MATCH(H33,POP!$G:$G,0)),"general") -> general | K33: REPLACE WORKLAMP | L33: FANDY | M33: RESTU | N33: 200000683408 | O33: DONE FROM BC | P33: =B33 -> 45398 | Q33: 7000150439 | R33: 45401 | U33: DO 23536 | V33: 29/4/2024 | W33: GMI-0019636 | X33: 45414 | Y33: 45457 | AA33: =AA32+1 -> 26 | AB33: GMIAMMPIK/2024/04/027 | AC33: =IFERROR(INDEX($B:$B,MATCH(AB33,$C:$C,FALSE)),"") -> 45398 | AD33: =INDEX($U:$U,MATCH(AB33,$C:$C,FALSE)) -> DO 23536 | AE33: =IFERROR(INDEX($V:$V,MATCH(AB33,$C:$C,FALSE)),"") -> 29/4/2024 | AF33: =IFERROR(INDEX($N:$N,MATCH(AB33,$C:$C,FALSE)),"") -> 200000683408 | AG33: =INDEX($Q:$Q,MATCH(AB33,$C:$C,FALSE)) -> 7000150439 | AH33: =IFERROR(INDEX($S:$S,MATCH(AB33,$C:$C,FALSE)),"") | AI33: =IFERROR(INDEX($T:$T,MATCH(AB33,$C:$C,FALSE)),"") | AJ33: =INDEX($W:$W,MATCH(AB33,$C:$C,FALSE)) -> GMI-0019636 | AK33: =IFERROR(INDEX($X:$X,MATCH(AB33,$C:$C,FALSE)),"") -> 45414 | AL33: =INDEX($O:$O,MATCH(AF33,$N:$N,FALSE),"") -> DONE FROM BC | AM33: =INDEX($Y:$Y,MATCH(AB33,$C:$C,FALSE)) -> 45457
A34: =A33+1 -> 27 | B34: 45400 | C34: GMIAMMPIK/2024/04/028 | D34: 11L-3024 | E34: =VLOOKUP(D34,MP!$A$1:$C$14184,2,0) -> LED FLood Light 6 Eyes 18 Watt 10-30 VDC | F34: 1 | G34: PCS | H34: VS25PPA | I34: =IFERROR(INDEX(POP!$I:$I,MATCH(H34,POP!$G:$G,0)),"general") -> general | J34: =IFERROR(INDEX(POP!$E:$E,MATCH(H34,POP!$G:$G,0)),"general") -> general | K34: REPLACE WORKLAMP | L34: FANDY | M34: FAUZI | N34: 200000684138 | O34: DONE FROM BC | P34: =B34 -> 45400 | Q34: 7000150576 | R34: 45401 | U34: DO 23538 | V34: 29/4/2024 | W34: GMI-0019637 | X34: 45414 | Y34: 45457 | AA34: =AA33+1 -> 27 | AB34: GMIAMMPIK/2024/04/028 | AC34: =IFERROR(INDEX($B:$B,MATCH(AB34,$C:$C,FALSE)),"") -> 45400 | AD34: =INDEX($U:$U,MATCH(AB34,$C:$C,FALSE)) -> DO 23538 | AE34: =IFERROR(INDEX($V:$V,MATCH(AB34,$C:$C,FALSE)),"") -> 29/4/2024 | AF34: =IFERROR(INDEX($N:$N,MATCH(AB34,$C:$C,FALSE)),"") -> 200000684138 | AG34: =INDEX($Q:$Q,MATCH(AB34,$C:$C,FALSE)) -> 7000150576 | AH34: =IFERROR(INDEX($S:$S,MATCH(AB34,$C:$C,FALSE)),"") | AI34: =IFERROR(INDEX($T:$T,MATCH(AB34,$C:$C,FALSE)),"") | AJ34: =INDEX($W:$W,MATCH(AB34,$C:$C,FALSE)) -> GMI-0019637 | AK34: =IFERROR(INDEX($X:$X,MATCH(AB34,$C:$C,FALSE)),"") -> 45414 | AL34: =INDEX($O:$O,MATCH(AF34,$N:$N,FALSE),"") -> DONE FROM BC | AM34: =INDEX($Y:$Y,MATCH(AB34,$C:$C,FALSE)) -> 45457
A35: =A34+1 -> 28 | B35: 45406 | C35: GMIAMMPIK/2024/04/029 | D35: 11L-3024 | E35: =VLOOKUP(D35,MP!$A$1:$C$14184,2,0) -> LED FLood Light 6 Eyes 18 Watt 10-30 VDC | F35: 2 | G35: PCS | H35: M53803 | I35: =IFERROR(INDEX(POP!$I:$I,MATCH(H35,POP!$G:$G,0)),"general") -> general | J35: =IFERROR(INDEX(POP!$E:$E,MATCH(H35,POP!$G:$G,0)),"general") -> general | K35: REPLACE WORKLAMP | L35: FANDY | M35: FAUZI | N35: 200000686439 | O35: DONE FROM BC | P35: =B35 -> 45406 | Q35: 7000151244 | R35: 45406 | U35: DO 23891 | V35: 16/5/2024 | W35: GMI-0020008 | X35: 45432 | Y35: 45457 | AA35: =AA34+1 -> 28 | AB35: GMIAMMPIK/2024/04/029 | AC35: =IFERROR(INDEX($B:$B,MATCH(AB35,$C:$C,FALSE)),"") -> 45406 | AD35: =INDEX($U:$U,MATCH(AB35,$C:$C,FALSE)) -> DO 23891 | AE35: =IFERROR(INDEX($V:$V,MATCH(AB35,$C:$C,FALSE)),"") -> 16/5/2024 | AF35: =IFERROR(INDEX($N:$N,MATCH(AB35,$C:$C,FALSE)),"") -> 200000686439 | AG35: =INDEX($Q:$Q,MATCH(AB35,$C:$C,FALSE)) -> 7000151244 | AH35: =IFERROR(INDEX($S:$S,MATCH(AB35,$C:$C,FALSE)),"") | AI35: =IFERROR(INDEX($T:$T,MATCH(AB35,$C:$C,FALSE)),"") | AJ35: =INDEX($W:$W,MATCH(AB35,$C:$C,FALSE)) -> GMI-0020008 | AK35: =IFERROR(INDEX($X:$X,MATCH(AB35,$C:$C,FALSE)),"") -> 45432 | AL35: =INDEX($O:$O,MATCH(AF35,$N:$N,FALSE),"") -> DONE FROM BC | AM35: =INDEX($Y:$Y,MATCH(AB35,$C:$C,FALSE)) -> 45457
A36: =A35+1 -> 29 | B36: 45406 | C36: GMIAMMPIK/2024/04/030 | D36: 11L-3024 | E36: =VLOOKUP(D36,MP!$A$1:$C$14184,2,0) -> LED FLood Light 6 Eyes 18 Watt 10-30 VDC | F36: 10 | G36: PCS | H36: PLTAM15 | I36: =IFERROR(INDEX(POP!$I:$I,MATCH(H36,POP!$G:$G,0)),"general") -> general | J36: =IFERROR(INDEX(POP!$E:$E,MATCH(H36,POP!$G:$G,0)),"general") -> general | K36: REPLACE WORKLAMP | L36: FANDY | M36: HARLY | N36: 260000019924 | O36: DONE FROM BC | P36: =B36 -> 45406 | Q36: 9200009909 | U36: DO 24032 | V36: 24/5/2024 | W36: GMI-0020134 | X36: 45436 | Y36: 45457 | AA36: =AA35+1 -> 29 | AB36: GMIAMMPIK/2024/04/030 | AC36: =IFERROR(INDEX($B:$B,MATCH(AB36,$C:$C,FALSE)),"") -> 45406 | AD36: =INDEX($U:$U,MATCH(AB36,$C:$C,FALSE)) -> DO 24032 | AE36: =IFERROR(INDEX($V:$V,MATCH(AB36,$C:$C,FALSE)),"") -> 24/5/2024 | AF36: =IFERROR(INDEX($N:$N,MATCH(AB36,$C:$C,FALSE)),"") -> 260000019924 | AG36: =INDEX($Q:$Q,MATCH(AB36,$C:$C,FALSE)) -> 9200009909 | AH36: =IFERROR(INDEX($S:$S,MATCH(AB36,$C:$C,FALSE)),"") | AI36: =IFERROR(INDEX($T:$T,MATCH(AB36,$C:$C,FALSE)),"") | AJ36: =INDEX($W:$W,MATCH(AB36,$C:$C,FALSE)) -> GMI-0020134 | AK36: =IFERROR(INDEX($X:$X,MATCH(AB36,$C:$C,FALSE)),"") -> 45436 | AL36: =INDEX($O:$O,MATCH(AF36,$N:$N,FALSE),"") -> DONE FROM BC | AM36: =INDEX($Y:$Y,MATCH(AB36,$C:$C,FALSE)) -> 45457
A37: =A36+1 -> 30 | B37: 12 Mei 2024 | C37: GMIAMMPIK/2024/05/031 | D37: 11L-3024 | E37: =VLOOKUP(D37,MP!$A$1:$C$14184,2,0) -> LED FLood Light 6 Eyes 18 Watt 10-30 VDC | F37: 2 | G37: PCS | H37: H57072 | I37: =IFERROR(INDEX(POP!$I:$I,MATCH(H37,POP!$G:$G,0)),"general") -> general | J37: =IFERROR(INDEX(POP!$E:$E,MATCH(H37,POP!$G:$G,0)),"general") -> general | K37: REPLACE WORKLAMP | L37: FANDY | M37: WIWIK | N37: 200000693114 | O37: DONE FROM BC | P37: =B37 -> 12 Mei 2024 | Q37: 9200010641 | U37: DO 24047 | V37: 25/5/2024 | W37: GMI-0020158 | X37: 45441 | Y37: 45502 | AA37: =AA36+1 -> 30 | AB37: GMIAMMPIK/2024/05/031 | AC37: =IFERROR(INDEX($B:$B,MATCH(AB37,$C:$C,FALSE)),"") -> 12 Mei 2024 | AD37: =INDEX($U:$U,MATCH(AB37,$C:$C,FALSE)) -> DO 24047 | AE37: =IFERROR(INDEX($V:$V,MATCH(AB37,$C:$C,FALSE)),"") -> 25/5/2024 | AF37: =IFERROR(INDEX($N:$N,MATCH(AB37,$C:$C,FALSE)),"") -> 200000693114 | AG37: =INDEX($Q:$Q,MATCH(AB37,$C:$C,FALSE)) -> 9200010641 | AH37: =IFERROR(INDEX($S:$S,MATCH(AB37,$C:$C,FALSE)),"") | AI37: =IFERROR(INDEX($T:$T,MATCH(AB37,$C:$C,FALSE)),"") | AJ37: =INDEX($W:$W,MATCH(AB37,$C:$C,FALSE)) -> GMI-0020158 | AK37: =IFERROR(INDEX($X:$X,MATCH(AB37,$C:$C,FALSE)),"") -> 45441 | AL37: =INDEX($O:$O,MATCH(AF37,$N:$N,FALSE),"") -> DONE FROM BC | AM37: =INDEX($Y:$Y,MATCH(AB37,$C:$C,FALSE)) -> 45502
A38: =A37+1 -> 31 | B38: 14 Mei 2024 | C38: GMIAMMPIK/2024/05/032 | D38: 11L-3024 | E38: =VLOOKUP(D38,MP!$A$1:$C$14184,2,0) -> LED FLood Light 6 Eyes 18 Watt 10-30 VDC | F38: 1 | G38: PCS | H38: WT2532PPA | I38: =IFERROR(INDEX(POP!$I:$I,MATCH(H38,POP!$G:$G,0)),"general") -> general | J38: =IFERROR(INDEX(POP!$E:$E,MATCH(H38,POP!$G:$G,0)),"general") -> general | K38: REPLACE WORKLAMP | L38: FANDY | M38: WIWIK | N38: 200000693458 | O38: DONE FROM BC | P38: =B38 -> 14 Mei 2024 | Q38: 9200010735 | R38: 45427 | T38: 45443 | U38: DO 24311 | V38: 45297 | W38: GMI-0020419 | X38: 45451 | Y38: 45502 | AA38: =AA37+1 -> 31 | AB38: GMIAMMPIK/2024/05/032 | AC38: =IFERROR(INDEX($B:$B,MATCH(AB38,$C:$C,FALSE)),"") -> 14 Mei 2024 | AD38: =INDEX($U:$U,MATCH(AB38,$C:$C,FALSE)) -> DO 24311 | AE38: =IFERROR(INDEX($V:$V,MATCH(AB38,$C:$C,FALSE)),"") -> 45297 | AF38: =IFERROR(INDEX($N:$N,MATCH(AB38,$C:$C,FALSE)),"") -> 200000693458 | AG38: =INDEX($Q:$Q,MATCH(AB38,$C:$C,FALSE)) -> 9200010735 | AH38: =IFERROR(INDEX($S:$S,MATCH(AB38,$C:$C,FALSE)),"") | AI38: =IFERROR(INDEX($T:$T,MATCH(AB38,$C:$C,FALSE)),"") -> 45443 | AJ38: =INDEX($W:$W,MATCH(AB38,$C:$C,FALSE)) -> GMI-0020419 | AK38: =IFERROR(INDEX($X:$X,MATCH(AB38,$C:$C,FALSE)),"") -> 45451 | AL38: =INDEX($O:$O,MATCH(AF38,$N:$N,FALSE),"") -> DONE FROM BC | AM38: =INDEX($Y:$Y,MATCH(AB38,$C:$C,FALSE)) -> 45502
A39: =A38+1 -> 32 | B39: 17 Mei 2024 | C39: GMIAMMPIK/2024/05/033 | D39: 11L-3024 | E39: =VLOOKUP(D39,MP!$A$1:$C$14184,2,0) -> LED FLood Light 6 Eyes 18 Watt 10-30 VDC | F39: 3 | G39: PCS | H39: F54404 | I39: =IFERROR(INDEX(POP!$I:$I,MATCH(H39,POP!$G:$G,0)),"general") -> general | J39: =IFERROR(INDEX(POP!$E:$E,MATCH(H39,POP!$G:$G,0)),"general") -> general | K39: REPLACE WORKLAMP | L39: FANDY | M39: WIWIK | N39: 200000694785 | O39: DONE FROM BC | P39: =B39 -> 17 Mei 2024 | Q39: 9200010805 | R39: 45428 | T39: 45443 | U39: DO 24313 | V39: 45297 | W39: GMI-0020420 | X39: 45451 | Y39: 45502 | AA39: =AA38+1 -> 32 | AB39: GMIAMMPIK/2024/05/033 | AC39: =IFERROR(INDEX($B:$B,MATCH(AB39,$C:$C,FALSE)),"") -> 17 Mei 2024 | AD39: =INDEX($U:$U,MATCH(AB39,$C:$C,FALSE)) -> DO 24313 | AE39: =IFERROR(INDEX($V:$V,MATCH(AB39,$C:$C,FALSE)),"") -> 45297 | AF39: =IFERROR(INDEX($N:$N,MATCH(AB39,$C:$C,FALSE)),"") -> 200000694785 | AG39: =INDEX($Q:$Q,MATCH(AB39,$C:$C,FALSE)) -> 9200010805 | AH39: =IFERROR(INDEX($S:$S,MATCH(AB39,$C:$C,FALSE)),"") | AI39: =IFERROR(INDEX($T:$T,MATCH(AB39,$C:$C,FALSE)),"") -> 45443 | AJ39: =INDEX($W:$W,MATCH(AB39,$C:$C,FALSE)) -> GMI-0020420 | AK39: =IFERROR(INDEX($X:$X,MATCH(AB39,$C:$C,FALSE)),"") -> 45451 | AL39: =INDEX($O:$O,MATCH(AF39,$N:$N,FALSE),"") -> DONE FROM BC | AM39: =INDEX($Y:$Y,MATCH(AB39,$C:$C,FALSE)) -> 45502
A40: =A39+1 -> 33 | B40: 18 Mei 2024 | C40: GMIAMMPIK/2024/05/034 | D40: 11L-3024 | E40: =VLOOKUP(D40,MP!$A$1:$C$14184,2,0) -> LED FLood Light 6 Eyes 18 Watt 10-30 VDC | F40: 1 | G40: PCS | H40: E53905 | I40: =IFERROR(INDEX(POP!$I:$I,MATCH(H40,POP!$G:$G,0)),"general") -> general | J40: =IFERROR(INDEX(POP!$E:$E,MATCH(H40,POP!$G:$G,0)),"general") -> general | K40: REPLACE WORKLAMP | L40: FANDY | M40: WIWIK | N40: 200000695618 | O40: DONE FROM BC | P40: =B40 -> 18 Mei 2024 | Q40: 9200010914 | R40: 20/5/2024 | T40: 22/5/2024 | U40: DO 24079 | V40: 25/5/2024 | W40: GMI-0020195 | X40: 45442 | Y40: 45502 | AA40: =AA39+1 -> 33 | AB40: GMIAMMPIK/2024/05/034 | AC40: =IFERROR(INDEX($B:$B,MATCH(AB40,$C:$C,FALSE)),"") -> 18 Mei 2024 | AD40: =INDEX($U:$U,MATCH(AB40,$C:$C,FALSE)) -> DO 24079 | AE40: =IFERROR(INDEX($V:$V,MATCH(AB40,$C:$C,FALSE)),"") -> 25/5/2024 | AF40: =IFERROR(INDEX($N:$N,MATCH(AB40,$C:$C,FALSE)),"") -> 200000695618 | AG40: =INDEX($Q:$Q,MATCH(AB40,$C:$C,FALSE)) -> 9200010914 | AH40: =IFERROR(INDEX($S:$S,MATCH(AB40,$C:$C,FALSE)),"") | AI40: =IFERROR(INDEX($T:$T,MATCH(AB40,$C:$C,FALSE)),"") -> 22/5/2024 | AJ40: =INDEX($W:$W,MATCH(AB40,$C:$C,FALSE)) -> GMI-0020195 | AK40: =IFERROR(INDEX($X:$X,MATCH(AB40,$C:$C,FALSE)),"") -> 45442 | AL40: =INDEX($O:$O,MATCH(AF40,$N:$N,FALSE),"") -> DONE FROM BC | AM40: =INDEX($Y:$Y,MATCH(AB40,$C:$C,FALSE)) -> 45502
...

Sheet AMM PIK 2026
D1: WAREHOUSE | Q1: MARKETING | U1: LOGISTICS | W1: FINANCE | AB1: DATA TABLE DASHBOARD SPB | AO1: DASHBOARD SPB GMI AMM PIK
A2: NO | B2: TANGGAL SPB | C2: NO SPB | D2: PART NUMBER | E2: PART NAME | F2: QTY | G2: UOM | H2: UNIT CODE | I2: TYPE UNIT | J2: BRAND | K2: PROBLEM | L2: PIC GMI | M2: PIC PPA | N2: NO WO | O2: STATUS WO | P2: WO DATE | Q2: NO PO | R2: PO DATE | S2: NO SO | T2: SO DATE | U2: NO DO | V2: DO DATE | W2: NO INVOICE | X2: TANGGAL KIRIM | Y2: STATUS PAYMENT | AA2: NO | AB2: NO SPB | AC2: TGL SPB | AD2: NO DO | AE2: TGL DO | AF2: NO WO | AG2: NO PO | AH2: NO SO | AI2: TGL so | AJ2: NO INVOICE | AK2: TANGAL INVOICE | AL2: STATUS SPB | AM2: STATUS PAYMENT | AO2: NO | AP2: DESCRIPTION | AQ2: DONE | AR2: WAITING | AS2: TOTAL
A3: 1 | B3: 5 Januari 2026 | C3: GMIAMMPIK/2026/1/0308 | D3: 11L-3024 | E3: =VLOOKUP(D3,MP!$A$1:$C$14184,2,0) -> LED FLood Light 6 Eyes 18 Watt 10-30 VDC | F3: 1 | G3: PCS | H3: FT52513 | I3: general | J3: general | K3: REPLACE WORKLAMP | L3: DIMAS | M3: WIWIK | N3: 200000982891 | O3: DONE FROM BC | P3: 46027 | Q3: 9200065726 | R3: 46025 | S3: 41663 | T3: 46028 | U3: DO 45471 | V3: 46030 | W3: GMI26-0044453 | X3: 46030
A4: 2 | B4: 5 Januari 2026 | C4: GMIAMMPIK/2026/1/0308 | D4: 11L-3024 | E4: =VLOOKUP(D4,MP!$A$1:$C$14184,2,0) -> LED FLood Light 6 Eyes 18 Watt 10-30 VDC | F4: 1 | G4: PCS | H4: FL08PPA | I4: general | J4: general | K4: REPLACE WORKLAMP | L4: DIMAS | M4: WIWIK | N4: 200000982984 | O4: DONE FROM BC | P4: 46027 | Q4: 9200065726 | R4: 46025 | S4: 41663 | T4: 46028 | U4: DO 45471 | V4: 46030 | W4: GMI26-0044453 | X4: 46030
A5: 3 | B5: 5 Januari 2026 | C5: GMIAMMPIK/2026/1/0309 | D5: 11L-1290-ARW | E5: =VLOOKUP(D5,MP!$A$1:$C$14184,2,0) -> LED Combination Lamp Amber Red White | F5: 1 | G5: PCS | H5: F54441 | I5: general | J5: general | K5: REPLACE WORKLAMP | L5: DIMAS | M5: WIWIK | N5: 200000984490 | O5: DONE FROM BC | P5: 46027 | Q5: 9200065877 | R5: 46026 | S5: 41664 | T5: 46028 | U5: DO 45644 | V5: 46035 | W5: GMI26-0044734 | X5: 46037
A6: 4 | B6: 5 Januari 2026 | C6: GMIAMMPIK/2026/1/0309 | D6: 11L-3024 | E6: =VLOOKUP(D6,MP!$A$1:$C$14184,2,0) -> LED FLood Light 6 Eyes 18 Watt 10-30 VDC | F6: 3 | G6: PCS | H6: F54441 | I6: general | J6: general | K6: REPLACE WORKLAMP | L6: DIMAS | M6: WIWIK | N6: 200000984490 | O6: DONE FROM BC | P6: 46027 | Q6: 9200065877 | R6: 46026 | S6: 41664 | T6: 46028 | U6: DO 45644 | V6: 46035 | W6: GMI26-0044734 | X6: 46037
A7: 5 | B7: 5 Januari 2026 | C7: GMIAMMPIK/2026/1/0309 | D7: 3L4-7ASB | E7: =VLOOKUP(D7,MP!$A$1:$C$14184,2,0) -> LED (SMD Led) Strobe Beacon Blue : 12-24VDC with Alumunium screw base | F7: 2 | G7: PCS | H7: F54441 | I7: general | J7: general | K7: REPLACE WORKLAMP | L7: DIMAS | M7: WIWIK | N7: 200000984490 | O7: DONE FROM BC | P7: 46027 | Q7: 9200065877 | R7: 46026 | S7: 41664 | T7: 46028 | U7: DO 45644 | V7: 46035 | W7: GMI26-0044734 | X7: 46037
A8: 6 | B8: 5 Januari 2026 | C8: GMIAMMPIK/2026/1/0310 | D8: 11L-1290-ARW | E8: =VLOOKUP(D8,MP!$A$1:$C$14184,2,0) -> LED Combination Lamp Amber Red White | F8: 1 | G8: PCS | H8: DA48127PPA | I8: general | J8: general | K8: REPLACE WORKLAMP | L8: DIMAS | M8: WIWIK | N8: 200000985605 | O8: DONE FROM BC | P8: 46027 | Q8: 9200065980 | R8: 46027 | S8: 41665 | T8: 46028 | U8: DO 45472 | V8: 46030 | W8: GMI26-0044452 | X8: 46030
A9: 7 | B9: 9 Januari 2026 | C9: GMIAMMPIK/2026/1/0311 | D9: 3L4-7ASA | E9: =VLOOKUP(D9,MP!$A$1:$C$14184,2,0) -> LED (SMD Led) Strobe Beacon Amber : 12-24VDC with Alumunium screw base | F9: 1 | G9: PCS | H9: D5859 | I9: general | J9: general | K9: REPLACE WORKLAMP | L9: DIMAS | M9: WIWIK | N9: 200000987466 | O9: DONE FROM BC | P9: 46031 | Q9: 9200066710 | R9: 46031 | S9: 41886 | T9: 46034 | U9: DO 45724 | V9: 46036 | W9: GMI26-0044733 | X9: 46037
A10: 8 | B10: 12 Januari 2026 | C10: GMIAMMPIK/2026/1/0312 | D10: 11L-3024 | E10: =VLOOKUP(D10,MP!$A$1:$C$14184,2,0) -> LED FLood Light 6 Eyes 18 Watt 10-30 VDC | F10: 6 | G10: PCS | H10: PLTAM15 | I10: general | J10: general | K10: REPLACE WORKLAMP | L10: DIMAS | M10: WIWIK | N10: 200000986910 | O10: DONE FROM BC | P10: 46034 | Q10: 9200067070 | R10: 46034 | S10: 41887 | T10: 46034 | U10: DO 45725 | V10: 46036 | W10: GMI26-0044732 | X10: 46037
A11: 9 | B11: 12 Januari 2026 | C11: GMIAMMPIK/2026/1/0312 | D11: 3L3-8AB | E11: =VLOOKUP(D11,MP!$A$1:$C$14184,2,0) -> Blue Xenon Beacon Light 12-24VDC with alumunium screw base | F11: 1 | G11: PCS | H11: PLTAM15 | I11: general | J11: general | K11: REPLACE WORKLAMP | L11: DIMAS | M11: WIWIK | N11: 200000986910 | O11: DONE FROM BC | P11: 46034 | Q11: 9200067070 | R11: 46034 | S11: 41887 | T11: 46034 | U11: DO 45725 | V11: 46036 | W11: GMI26-0044732 | X11: 46037
A12: 10 | B12: 20 Januari 2026 | C12: GMIAMMPIK/2026/1/0313 | D12: 11L-3024 | E12: =VLOOKUP(D12,MP!$A$1:$C$14184,2,0) -> LED FLood Light 6 Eyes 18 Watt 10-30 VDC | F12: 16 | G12: PCS | H12: FT52527 | I12: general | J12: general | K12: REPLACE WORKLAMP | L12: DIMAS | M12: WIWIK | N12: 200000989610 | O12: DONE FROM BC | P12: 46042 | Q12: 9200068303 | R12: 46042 | S12: 42118 | T12: 46043 | U12: DO 45955 | V12: 46043 | W12: GMI26-0044919 | X12: 46043
A13: 11 | B13: 20 Januari 2026 | C13: GMIAMMPIK/2026/1/0313 | D13: 3L3-8AA | E13: =VLOOKUP(D13,MP!$A$1:$C$14184,2,0) -> Amber Xenon Beacon Light 12-24VDC with alumunium screw base | F13: 3 | G13: PCS | H13: FT52527 | I13: general | J13: general | K13: REPLACE WORKLAMP | L13: DIMAS | M13: WIWIK | N13: 200000989610 | O13: DONE FROM BC | P13: 46042 | Q13: 9200068303 | R13: 46042 | S13: 42118 | T13: 46043 | U13: DO 45955 | V13: 46043 | W13: GMI26-0044919 | X13: 46043
A14: 12 | B14: 20 Januari 2026 | C14: GMIAMMPIK/2026/1/0313 | D14: 3L4-7ASA | E14: =VLOOKUP(D14,MP!$A$1:$C$14184,2,0) -> LED (SMD Led) Strobe Beacon Amber : 12-24VDC with Alumunium screw base | F14: 4 | G14: PCS | H14: FT52527 | I14: general | J14: general | K14: REPLACE WORKLAMP | L14: DIMAS | M14: WIWIK | N14: 200000989610 | O14: DONE FROM BC | P14: 46042 | Q14: 9200068303 | R14: 46042 | S14: 42118 | T14: 46043 | U14: DO 45955 | V14: 46043 | W14: GMI26-0044919 | X14: 46043
... A23: 21 | B23: 9 Februari 2026 | C23: GMIAMMPIK/2026/2/0319 | D23: 11L-1290-ARW | E23: =VLOOKUP(D23,MP!$A$1:$C$14184,2,0) -> LED Combination Lamp Amber Red White | F23: 3 | G23: PCS | H23: DA48122PPA | I23: general | J23: general | K23: REPLACE WORKLAMP | L23: DIMAS | M23: WIWIK | N23: 200001003486 | O23: DONE FROM BC | P23: 46062 | Q23: 9200071172 | R23: 46062 | S23: 42653 | T23: 46061 | U23: DO 46551 | V23: 46063 | W23: GMI26-0045461 | X23: 46063
A24: 22 | B24: 18 Februari 2026 | C24: GMIAMMPIK/2026/2/0320 | D24: 3L3-8AB | E24: =VLOOKUP(D24,MP!$A$1:$C$14184,2,0) -> Blue Xenon Beacon Light 12-24VDC with alumunium screw base | F24: 1 | G24: PCS | H24: D5863 | I24: general | J24: general | K24: REPLACE WORKLAMP | L24: DIMAS | M24: WIWIK | N24: 200001009857 | O24: DONE FROM BC | P24: 46071 | Q24: 9200072643 | R24: 46070 | S24: 43028 | T24: 46072 | U24: DO 46968 | V24: 46072
A25: 23 | B25: 18 Februari 2026 | C25: GMIAMMPIK/2026/2/0320 | D25: 3L4-7ASA | E25: =VLOOKUP(D25,MP!$A$1:$C$14184,2,0) -> LED (SMD Led) Strobe Beacon Amber : 12-24VDC with Alumunium screw base | F25: 1 | G25: PCS | H25: D5863 | I25: general | J25: general | K25: REPLACE WORKLAMP | L25: DIMAS | M25: WIWIK | N25: 200001009857 | O25: DONE FROM BC | P25: 46071 | Q25: 9200072643 | R25: 46070 | S25: 43028 | T25: 46072 | U25: DO 46968 | V25: 46072
A26: 24 | B26: 18 Februari 2026 | C26: GMIAMMPIK/2026/2/0320 | D26: 3L4-7ASB | E26: =VLOOKUP(D26,MP!$A$1:$C$14184,2,0) -> LED (SMD Led) Strobe Beacon Blue : 12-24VDC with Alumunium screw base | F26: 1 | G26: PCS | H26: D5863 | I26: general | J26: general | K26: REPLACE WORKLAMP | L26: DIMAS | M26: WIWIK | N26: 200001009857 | O26: DONE FROM BC | P26: 46071 | Q26: 9200072643 | R26: 46070 | S26: 43028 | T26: 46072 | U26: DO 46968 | V26: 46072
A27: 25 | B27: 25 Februari 2026 | C27: GMIAMMPIK/2026/2/0321 | D27: 11L-3024 | E27: =VLOOKUP(D27,MP!$A$1:$C$14184,2,0) -> LED FLood Light 6 Eyes 18 Watt 10-30 VDC | F27: 2 | G27: PCS | H27: DA54242 | I27: general | J27: general | K27: REPLACE WORKLAMP | L27: DIMAS | M27: WIWIK | N27: 200001012068 | O27: DONE FROM BC | P27: 46078 | Q27: 9200074085 | R27: 46078 | S27: 43370 | T27: 46080 | U27: DO 47328 | V27: 46080
A28: 26 | B28: 25 Februari 2026 | C28: GMIAMMPIK/2026/2/0321 | D28: 11L-1290-ARW | E28: =VLOOKUP(D28,MP!$A$1:$C$14184,2,0) -> LED Combination Lamp Amber Red White | F28: 1 | G28: PCS | H28: DA54242 | I28: general | J28: general | K28: REPLACE WORKLAMP | L28: DIMAS | M28: WIWIK | N28: 200001012068 | O28: DONE FROM BC | P28: 46078 | Q28: 9200074085 | R28: 46078 | S28: 43370 | T28: 46080 | U28: DO 47328 | V28: 46080
A29: 27 | B29: 2 Maret 2026 | C29: GMIAMMPIK/2026/3/0322 | D29: 11L-3024 | E29: =VLOOKUP(D29,MP!$A$1:$C$14184,2,0) -> LED FLood Light 6 Eyes 18 Watt 10-30 VDC | F29: 4 | G29: PCS | H29: D5871 | I29: general | J29: general | K29: REPLACE WORKLAMP | L29: DIMAS | M29: WIWIK | N29: 200001016403 | O29: DONE FROM BC | P29: 46083 | Q29: 9200074794 | R29: 46082 | S29: 43497 | T29: 46084 | U29: DO 47362 | V29: 46086
A30: 28 | B30: 2 Maret 2026 | C30: GMIAMMPIK/2026/3/0322 | D30: 3L4-7ASA | E30: =VLOOKUP(D30,MP!$A$1:$C$14184,2,0) -> LED (SMD Led) Strobe Beacon Amber : 12-24VDC with Alumunium screw base | F30: 4 | G30: PCS | H30: D5871 | I30: general | J30: general | K30: REPLACE WORKLAMP | L30: DIMAS | M30: WIWIK | N30: 200001016403 | O30: DONE FROM BC | P30: 46083 | Q30: 9200074794 | R30: 46082 | S30: 43497 | T30: 46084 | U30: DO 47362 | V30: 46086
A31: 29 | B31: 2 Maret 2026 | C31: GMIAMMPIK/2026/3/0322 | D31: 3L4-7ASB | E31: =VLOOKUP(D31,MP!$A$1:$C$14184,2,0) -> LED (SMD Led) Strobe Beacon Blue : 12-24VDC with Alumunium screw base | F31: 1 | G31: PCS | H31: D5871 | I31: general | J31: general | K31: REPLACE WORKLAMP | L31: DIMAS | M31: WIWIK | N31: 200001016403 | O31: DONE FROM BC | P31: 46083 | Q31: 9200074794 | R31: 46082 | S31: 43497 | T31: 46084 | U31: DO 47362 | V31: 46086
A32: 30 | B32: 2 Maret 2026 | C32: GMIAMMPIK/2026/3/0323 | D32: 1L35-ADB-I | E32: =VLOOKUP(D32,MP!$A$1:$C$14184,2,0) -> ADBLUE EMULATOR BOX V2 CONSUMABLE | F32: 1 | G32: SET | H32: FT52513 | I32: general | J32: general | K32: ATTCH TOOL NON ACTIVE ADBLUE | L32: DIMAS | M32: WIWIK | N32: 200001002201 | O32: DONE FROM BC | P32: 46083 | Q32: 9200073067 | R32: 46072 | S32: 43407 | T32: 46083 | U32: DO 47374 | V32: 46084
A33: 31 | B33: 2 Maret 2026 | C33: GMIAMMPIK/2026/3/0324 | D33: 1L35-ADB-I | E33: =VLOOKUP(D33,MP!$A$1:$C$14184,2,0) -> ADBLUE EMULATOR BOX V2 CONSUMABLE | F33: 1 | G33: SET | H33: LT52501 | I33: general | J33: general | K33: ATTCH TOOL NON ACTIVE ADBLUE | L33: DIMAS | M33: WIWIK | N33: 200001002205 | O33: DONE FROM BC | P33: 46083 | Q33: 9200073068 | R33: 46072 | S33: 43406 | T33: 46083 | U33: DO 47373 | V33: 46084
A34: 32 | B34: 2 Maret 2026 | C34: GMIAMMPIK/2026/3/0325 | D34: 1L35-ADB-I | E34: =VLOOKUP(D34,MP!$A$1:$C$14184,2,0) -> ADBLUE EMULATOR BOX V2 CONSUMABLE | F34: 1 | G34: SET | H34: FT52527 | I34: general | J34: general | K34: ATTCH TOOL NON ACTIVE ADBLUE | L34: DIMAS | M34: WIWIK | N34: 200001002204 | O34: DONE FROM BC | P34: 46083 | Q34: 9200073069 | R34: 46072 | S34: 43408 | T34: 46083 | U34: DO 47375 | V34: 46084
A35: 33 | B35: 2 Maret 2026 | C35: GMIAMMPIK/2026/3/0326 | D35: 1L35-ADB-I | E35: =VLOOKUP(D35,MP!$A$1:$C$14184,2,0) -> ADBLUE EMULATOR BOX V2 CONSUMABLE | F35: 1 | G35: SET | H35: FT52526 | I35: general | J35: general | K35: ATTCH TOOL NON ACTIVE ADBLUE | L35: DIMAS | M35: WIWIK | N35: 200001002203 | O35: DONE FROM BC | P35: 46083 | Q35: 9200073070 | R35: 46072 | S35: 43410 | T35: 46083 | U35: DO 47377 | V35: 46084
... A53: 51 | B53: 31 Maret 2026 | C53: GMIAMMPIK/2026/3/0333 | D53: 11L-1290-ARW | E53: =VLOOKUP(D53,MP!$A$1:$C$14184,2,0) -> LED Combination Lamp Amber Red White | F53: 1 | G53: PCS | H53: FT52527 | I53: general | J53: general | K53: REPLACE WORKLAMP | L53: DIMAS | M53: WIWIK | N53: 200001029782 | O53: DONE FROM BC | P53: 46112 | Q53: 9200079303 | R53: 46112 | S53: 44379 | T53: 46112 | U53: DO 48299 | V53: 46112
A54: 52 | B54: 46122 | C54: GMIAMMPIK/2026/4/0334 | D54: 3L3-8AA | E54: =VLOOKUP(D54,MP!$A$1:$C$14184,2,0) -> Amber Xenon Beacon Light 12-24VDC with alumunium screw base | F54: 1 | G54: PCS | H54: FT52521 | I54: general | J54: general | K54: REPLACE WORKLAMP | L54: DIMAS | M54: WIWIK | N54: 200001034903 | O54: DONE FROM BC | P54: 46122 | Q54: 9200080412 | R54: 46117 | S54: 44575 | T54: 46122 | U54: DO 48599 | V54: 46127
A55: 53 | B55: 46122 | C55: GMIAMMPIK/2026/4/0334 | D55: 3L3-8AB | E55: =VLOOKUP(D55,MP!$A$1:$C$14184,2,0) -> Blue Xenon Beacon Light 12-24VDC with alumunium screw base | F55: 3 | G55: PCS | H55: FT52521 | I55: general | J55: general | K55: REPLACE WORKLAMP | L55: DIMAS | M55: WIWIK | N55: 200001034903 | O55: DONE FROM BC | P55: 46122 | Q55: 9200080412 | R55: 46117 | S55: 44575 | T55: 46122 | U55: DO 48599 | V55: 46127
A56: 54 | B56: 46122 | C56: GMIAMMPIK/2026/4/0334 | D56: 11L-3024 | E56: =VLOOKUP(D56,MP!$A$1:$C$14184,2,0) -> LED FLood Light 6 Eyes 18 Watt 10-30 VDC | F56: 5 | G56: PCS | H56: FT52521 | I56: general | J56: general | K56: REPLACE WORKLAMP | L56: DIMAS | M56: WIWIK | N56: 200001034903 | O56: DONE FROM BC | P56: 46122 | Q56: 9200080412 | R56: 46117 | S56: 44575 | T56: 46122 | U56: DO 48599 | V56: 46127
A57: 55 | B57: 46122 | C57: GMIAMMPIK/2026/4/0334 | D57: 11L-1290-ARW | E57: =VLOOKUP(D57,MP!$A$1:$C$14184,2,0) -> LED Combination Lamp Amber Red White | F57: 2 | G57: PCS | H57: FT52521 | I57: general | J57: general | K57: REPLACE WORKLAMP | L57: DIMAS | M57: WIWIK | N57: 200001034903 | O57: DONE FROM BC | P57: 46122 | Q57: 9200080412 | R57: 46117 | S57: 44575 | T57: 46122 | U57: DO 48599 | V57: 46127
A58: 56 | B58: 46125 | C58: GMIAMMPIK/2026/4/0335 | D58: 3L3-8AA | E58: =VLOOKUP(D58,MP!$A$1:$C$14184,2,0) -> Amber Xenon Beacon Light 12-24VDC with alumunium screw base | F58: 1 | G58: PCS | H58: FT52529 | I58: general | J58: general | K58: REPLACE WORKLAMP | L58: DIMAS | M58: WIWIK | N58: 200001040624 | O58: DONE FROM BC | P58: 46125 | Q58: 9200081330 | R58: 46124 | S58: 44716 | T58: 46129 | U58: 48722 | V58: 46129
A59: 57 | B59: 46129 | C59: GMIAMMPIK/2026/4/0336 | D59: 11L-3024 | E59: =VLOOKUP(D59,MP!$A$1:$C$14184,2,0) -> LED FLood Light 6 Eyes 18 Watt 10-30 VDC | F59: 3 | G59: PCS | H59: MF1203PPA | I59: general | J59: general | K59: REPLACE WORKLAMP | L59: DIMAS | M59: WIWIK | N59: 200001040911 | O59: DONE FROM BC | P59: 46129 | Q59: 9200081758 | R59: 46126 | S59: 44798 | T59: 46129 | U59: DO 48769 | V59: 46129
