Workbook

Sheet AMM-IPT JAN
D1: WAREHOUSE | V1: MARKETING | Z1: LOGISTICS | AD1: FINANCE | AL1: LEAD TIME | AT1: DATA TABLE DASHBOARD SPB | BI1: DASHBOARD SPB GMI AMM IPT
A2: NO | B2: TANGGAL SPB | C2: NO SPB | D2: PART NUMBER | E2: PART NAME | F2: QTY | G2: UOM | H2: STATUS SPB | I2: KODE UNIT | J2: MODEL UNIT | K2: BRAND | L2: HM | M2: PS | N2: PROBLEM/REMARK | O2: SECTION | P2: PIC GMI | Q2: PIC PPA | R2: NO WO | S2: DATE INPUT | T2: STATUS WO | U2: TGL SUBMIT SPB TO PO | V2: NO PO | W2: NO SO | X2: DATE INPUT | Y2: STATUS PO | Z2: NO DO | AA2: DATE INPUT | AB2: STATUS DO | AC2: STATUS PART | AD2: NO INVOICE | AE2: TANGGAL INVOICE | AF2: STATUS INVOICE | AG2: TANGGAL KIRIM EMAIL KE SITE | AH2: TANGGAL PAYMENT | AI2: STATUS PAYMENT | AJ2: PRICE | AK2: GRAND PRICE | AL2: LT SPB TO WO | AM2: LT WO TO SUBMIT PO | AN2: LT WO TO PO | AO2: LT PO TO DO | AP2: LT DO TO INV | AQ2: TOTAL | AS2: NO | AT2: NO SPB | AU2: TGL SPB | AV2: TGL SUBMIT SPB TO PO | AW2: NO DO | AX2: TGL DO | AY2: NO WO | AZ2: NO PO | BA2: NO SO | BB2: TGL SO | BC2: {=INDEX($AD:$AD,MATCH(AT2,$C:$C,FALSE))} -> NO INVOICE | BD2: TGL INV | BE2: TANGGAL KIRIM EMAIL KE SITE | BF2: STATUS SPB | BG2: STATUS PAYMENT | BI2: NO | BJ2: DESCRIPTION | BK2: DONE | BL2: WAITING | BM2: TOTAL
A3: =IF(C3=0,"",ROW()-ROW($A$2)) -> 1 | B3: 46025 | C3: GMIAMMIPT/2026/01/0001 | D3: 14L-0591 | E3: Expantion Valve HD785 | F3: 1 | G3: EA | H3: =IF(C3=0,"",IF(R3>0,"DONE","WAITING")) -> DONE | I3: D5140 | J3: D155A-6 | K3: Komatsu | L3: 8092 | M3: PS 4000 | N3: PS 4000 | O3: TRACK | P3: HANDRIAN | Q3: COBRA | R3: 200000986794 | S3: 46028 | T3: =IF(C3=0,"",IF(ISBLANK(S3),"WAITING","DONE")) -> DONE | U3: 46031 | V3: 9200066845 | W3: 41875 | X3: 46034 | Y3: =IF(C3=0,"",IF(V3>0,"DONE","WAITING")) -> DONE | Z3: DO 45711 | AA3: 46036 | AB3: =IF(C3=0,"",IF(Z3>0,"DONE","WAITING")) -> DONE | AD3: GMI26-0044682 | AE3: 46037 | AF3: =IF(C3=0,"",IF(ISBLANK(AD3),"WAITING","DONE")) -> DONE | AG3: 46038 | AH3: 46098 | AI3: =IF(AD3=0,"",IF(ISBLANK(AH3),"UNPAID","PAID")) -> PAID | AJ3: {=IFERROR(INDEX('[1]Master Price'!$E:$E,MATCH(D3,'[1]Master Price'!$B:$B,0)),"0")} -> 0 | AK3: =AJ3*F3 -> 0 | AL3: =IFERROR(DATEDIF(S3,T3,"d"),"0")&"-day" -> 0-day | AM3: =IFERROR(DATEDIF(S3,U3,"d"),"0")&"-day" -> 3-day | AN3: =IFERROR(DATEDIF(S3,X3,"d"),"0")&"-day" -> 6-day | AO3: =IFERROR(DATEDIF(X3,AA3,"d"),"0")&"-day" -> 2-day | AP3: =IFERROR(DATEDIF(AA3,AE3,"d"),"0")&"-day" -> 1-day | AQ3: =SUM(AL3:AP3)&"-day" -> 0-day | AS3: =IF(AT3=0,"",ROW()-ROW($AS$2)) -> 1 | AT3: GMIAMMIPT/2026/01/0001 | AU3: =_xludf.ifna(INDEX($B:$B,MATCH(AT3,$C:$C,FALSE)),"") -> #NAME? | AV3: =_xludf.ifna(INDEX($U:$U,MATCH(AT3,$C:$C,FALSE)),"") -> #NAME? | AW3: =_xludf.ifna(INDEX($Z:$Z,MATCH(AT3,$C:$C,FALSE)),"") -> #NAME? | AX3: =_xludf.ifna(INDEX($AA:$AA,MATCH(AT3,$C:$C,FALSE)),"") -> #NAME? | AY3: =IFERROR(INDEX($R:$R,MATCH(AT3,$C:$C,FALSE)),"") -> 200000986794 | AZ3: =_xludf.ifna(INDEX($V:$V,MATCH(AT3,$C:$C,FALSE)),"") -> #NAME? | BA3: =_xludf.ifna(INDEX($W:$W,MATCH(AT3,$C:$C,FALSE)),"") -> #NAME? | BB3: =_xludf.ifna(INDEX($X:$X,MATCH(AT3,$C:$C,FALSE)),"") -> #NAME? | BC3: =_xludf.ifna(INDEX($AD:$AD,MATCH(AT3,$C:$C,FALSE)),"") -> #NAME? | BD3: =_xludf.ifna(INDEX($AE:$AE,MATCH(AT3,$C:$C,FALSE)),"") -> #NAME? | BE3: =_xludf.ifna(INDEX($AG:$AG,MATCH(AT3,$C:$C,FALSE)),"") -> #NAME? | BF3: =_xludf.ifna(INDEX($T:$T,MATCH(AT3,$C:$C,FALSE),""),"") -> #NAME? | BG3: =_xludf.ifna(INDEX($AI:$AI,MATCH(AT3,$C:$C,FALSE)),"") -> #NAME? | BI3: 1 | BJ3: SPB | BK3: =IFERROR(__xludf.DUMMYFUNCTION("COUNTUNIQUEIFS(C3:C514,H3:H514,$BK$2)"),129) -> 129 | BL3: =IFERROR(__xludf.DUMMYFUNCTION("COUNTUNIQUEIFS(C3:C514,H3:H514,$BL$2)"),0) -> 0 | BM3: =SUM(BK3:BL3) -> 129
A4: =IF(C4=0,"",ROW()-ROW($A$2)) -> 2 | B4: 46025 | C4: GMIAMMIPT/2026/01/0001 | D4: 14L-0093 | E4: Receiver Drier | F4: 1 | G4: EA | H4: =IF(C4=0,"",IF(R4>0,"DONE","WAITING")) -> DONE | I4: D5140 | J4: D155A-6 | K4: Komatsu | L4: 8092 | M4: PS 4000 | N4: PS 4000 | O4: TRACK | P4: HANDRIAN | Q4: COBRA | R4: 200000986794 | S4: 46028 | T4: =IF(C4=0,"",IF(ISBLANK(S4),"WAITING","DONE")) -> DONE | U4: 46031 | V4: 9200066845 | W4: 41875 | X4: 46034 | Y4: =IF(C4=0,"",IF(V4>0,"DONE","WAITING")) -> DONE | Z4: DO 45711 | AA4: 46036 | AB4: =IF(C4=0,"",IF(Z4>0,"DONE","WAITING")) -> DONE | AD4: GMI26-0044682 | AE4: 46037 | AF4: =IF(C4=0,"",IF(ISBLANK(AD4),"WAITING","DONE")) -> DONE | AG4: 46038 | AH4: 46098 | AI4: =IF(AD4=0,"",IF(ISBLANK(AH4),"UNPAID","PAID")) -> PAID | AJ4: {=IFERROR(INDEX('[1]Master Price'!$E:$E,MATCH(D4,'[1]Master Price'!$B:$B,0)),"0")} -> 0 | AK4: =AJ4*F4 -> 0 | AL4: =IFERROR(DATEDIF(S4,T4,"d"),"0")&"-day" -> 0-day | AM4: =IFERROR(DATEDIF(S4,U4,"d"),"0")&"-day" -> 3-day | AN4: =IFERROR(DATEDIF(S4,X4,"d"),"0")&"-day" -> 6-day | AO4: =IFERROR(DATEDIF(X4,AA4,"d"),"0")&"-day" -> 2-day | AP4: =IFERROR(DATEDIF(AA4,AE4,"d"),"0")&"-day" -> 1-day | AQ4: =SUM(AL4:AP4)&"-day" -> 0-day | AS4: =IF(AT4=0,"",ROW()-ROW($AS$2)) -> 2 | AT4: GMIAMMIPT/2026/01/0002 | AU4: =_xludf.ifna(INDEX($B:$B,MATCH(AT4,$C:$C,FALSE)),"") -> #NAME? | AV4: =_xludf.ifna(INDEX($U:$U,MATCH(AT4,$C:$C,FALSE)),"") -> #NAME? | AW4: =_xludf.ifna(INDEX($Z:$Z,MATCH(AT4,$C:$C,FALSE)),"") -> #NAME? | AX4: =_xludf.ifna(INDEX($AA:$AA,MATCH(AT4,$C:$C,FALSE)),"") -> #NAME? | AY4: =IFERROR(INDEX($R:$R,MATCH(AT4,$C:$C,FALSE)),"") -> 200000986789 | AZ4: =_xludf.ifna(INDEX($V:$V,MATCH(AT4,$C:$C,FALSE)),"") -> #NAME? | BA4: =_xludf.ifna(INDEX($W:$W,MATCH(AT4,$C:$C,FALSE)),"") -> #NAME? | BB4: =_xludf.ifna(INDEX($X:$X,MATCH(AT4,$C:$C,FALSE)),"") -> #NAME? | BC4: =_xludf.ifna(INDEX($AD:$AD,MATCH(AT4,$C:$C,FALSE)),"") -> #NAME? | BD4: =_xludf.ifna(INDEX($AE:$AE,MATCH(AT4,$C:$C,FALSE)),"") -> #NAME? | BE4: =_xludf.ifna(INDEX($AG:$AG,MATCH(AT4,$C:$C,FALSE)),"") -> #NAME? | BF4: =_xludf.ifna(INDEX($T:$T,MATCH(AT4,$C:$C,FALSE),""),"") -> #NAME? | BG4: =_xludf.ifna(INDEX($AI:$AI,MATCH(AT4,$C:$C,FALSE)),"") -> #NAME? | BI4: 2 | BJ4: DO | BK4: =IFERROR(__xludf.DUMMYFUNCTION("COUNTUNIQUEIFS(C3:C514,AB3:AB514,$BK$2)"),129) -> 129 | BL4: =IFERROR(__xludf.DUMMYFUNCTION("COUNTUNIQUEIFS(C3:C514,AB3:AB514,$BL$2)"),0) -> 0 | BM4: =SUM(BK4:BL4) -> 129
A5: =IF(C5=0,"",ROW()-ROW($A$2)) -> 3 | B5: 46025 | C5: GMIAMMIPT/2026/01/0001 | D5: 14L-0143-1 | E5: Core Valve R134 | F5: 2 | G5: EA | H5: =IF(C5=0,"",IF(R5>0,"DONE","WAITING")) -> DONE | I5: D5140 | J5: D155A-6 | K5: Komatsu | L5: 8092 | M5: PS 4000 | N5: PS 4000 | O5: TRACK | P5: HANDRIAN | Q5: COBRA | R5: 200000986794 | S5: 46028 | T5: =IF(C5=0,"",IF(ISBLANK(S5),"WAITING","DONE")) -> DONE | U5: 46031 | V5: 9200066845 | W5: 41875 | X5: 46034 | Y5: =IF(C5=0,"",IF(V5>0,"DONE","WAITING")) -> DONE | Z5: DO 45711 | AA5: 46036 | AB5: =IF(C5=0,"",IF(Z5>0,"DONE","WAITING")) -> DONE | AD5: GMI26-0044682 | AE5: 46037 | AF5: =IF(C5=0,"",IF(ISBLANK(AD5),"WAITING","DONE")) -> DONE | AG5: 46038 | AH5: 46098 | AI5: =IF(AD5=0,"",IF(ISBLANK(AH5),"UNPAID","PAID")) -> PAID | AJ5: {=IFERROR(INDEX('[1]Master Price'!$E:$E,MATCH(D5,'[1]Master Price'!$B:$B,0)),"0")} -> 0 | AK5: =AJ5*F5 -> 0 | AL5: =IFERROR(DATEDIF(S5,T5,"d"),"0")&"-day" -> 0-day | AM5: =IFERROR(DATEDIF(S5,U5,"d"),"0")&"-day" -> 3-day | AN5: =IFERROR(DATEDIF(S5,X5,"d"),"0")&"-day" -> 6-day | AO5: =IFERROR(DATEDIF(X5,AA5,"d"),"0")&"-day" -> 2-day | AP5: =IFERROR(DATEDIF(AA5,AE5,"d"),"0")&"-day" -> 1-day | AQ5: =SUM(AL5:AP5)&"-day" -> 0-day | AS5: =IF(AT5=0,"",ROW()-ROW($AS$2)) -> 3 | AT5: GMIAMMIPT/2026/01/0003 | AU5: =_xludf.ifna(INDEX($B:$B,MATCH(AT5,$C:$C,FALSE)),"") -> #NAME? | AV5: =_xludf.ifna(INDEX($U:$U,MATCH(AT5,$C:$C,FALSE)),"") -> #NAME? | AW5: =_xludf.ifna(INDEX($Z:$Z,MATCH(AT5,$C:$C,FALSE)),"") -> #NAME? | AX5: =_xludf.ifna(INDEX($AA:$AA,MATCH(AT5,$C:$C,FALSE)),"") -> #NAME? | AY5: =IFERROR(INDEX($R:$R,MATCH(AT5,$C:$C,FALSE)),"") -> 200000986786 | AZ5: =_xludf.ifna(INDEX($V:$V,MATCH(AT5,$C:$C,FALSE)),"") -> #NAME? | BA5: =_xludf.ifna(INDEX($W:$W,MATCH(AT5,$C:$C,FALSE)),"") -> #NAME? | BB5: =_xludf.ifna(INDEX($X:$X,MATCH(AT5,$C:$C,FALSE)),"") -> #NAME? | BC5: =_xludf.ifna(INDEX($AD:$AD,MATCH(AT5,$C:$C,FALSE)),"") -> #NAME? | BD5: =_xludf.ifna(INDEX($AE:$AE,MATCH(AT5,$C:$C,FALSE)),"") -> #NAME? | BE5: =_xludf.ifna(INDEX($AG:$AG,MATCH(AT5,$C:$C,FALSE)),"") -> #NAME? | BF5: =_xludf.ifna(INDEX($T:$T,MATCH(AT5,$C:$C,FALSE),""),"") -> #NAME? | BG5: =_xludf.ifna(INDEX($AI:$AI,MATCH(AT5,$C:$C,FALSE)),"") -> #NAME? | BI5: 3 | BJ5: PO | BK5: =IFERROR(__xludf.DUMMYFUNCTION("COUNTUNIQUEIFS(C3:C514,Y3:Y514,$BK$2)"),129) -> 129 | BL5: =IFERROR(__xludf.DUMMYFUNCTION("COUNTUNIQUEIFS(C3:C514,Y3:Y514,$BL$2)"),0) -> 0 | BM5: =SUM(BK5:BL5) -> 129
A6: =IF(C6=0,"",ROW()-ROW($A$2)) -> 4 | B6: 46025 | C6: GMIAMMIPT/2026/01/0001 | D6: 14L-0107-2 | E6: Oil ND8 HFC134A 250 ml | F6: 1 | G6: EA | H6: =IF(C6=0,"",IF(R6>0,"DONE","WAITING")) -> DONE | I6: D5140 | J6: D155A-6 | K6: Komatsu | L6: 8092 | M6: PS 4000 | N6: PS 4000 | O6: TRACK | P6: HANDRIAN | Q6: COBRA | R6: 200000986794 | S6: 46028 | T6: =IF(C6=0,"",IF(ISBLANK(S6),"WAITING","DONE")) -> DONE | U6: 46031 | V6: 9200066845 | W6: 41875 | X6: 46034 | Y6: =IF(C6=0,"",IF(V6>0,"DONE","WAITING")) -> DONE | Z6: DO 45711 | AA6: 46036 | AB6: =IF(C6=0,"",IF(Z6>0,"DONE","WAITING")) -> DONE | AD6: GMI26-0044682 | AE6: 46037 | AF6: =IF(C6=0,"",IF(ISBLANK(AD6),"WAITING","DONE")) -> DONE | AG6: 46038 | AH6: 46098 | AI6: =IF(AD6=0,"",IF(ISBLANK(AH6),"UNPAID","PAID")) -> PAID | AJ6: {=IFERROR(INDEX('[1]Master Price'!$E:$E,MATCH(D6,'[1]Master Price'!$B:$B,0)),"0")} -> 0 | AK6: =AJ6*F6 -> 0 | AL6: =IFERROR(DATEDIF(S6,T6,"d"),"0")&"-day" -> 0-day | AM6: =IFERROR(DATEDIF(S6,U6,"d"),"0")&"-day" -> 3-day | AN6: =IFERROR(DATEDIF(S6,X6,"d"),"0")&"-day" -> 6-day | AO6: =IFERROR(DATEDIF(X6,AA6,"d"),"0")&"-day" -> 2-day | AP6: =IFERROR(DATEDIF(AA6,AE6,"d"),"0")&"-day" -> 1-day | AQ6: =SUM(AL6:AP6)&"-day" -> 0-day | AS6: =IF(AT6=0,"",ROW()-ROW($AS$2)) -> 4 | AT6: GMIAMMIPT/2026/01/0004 | AU6: =_xludf.ifna(INDEX($B:$B,MATCH(AT6,$C:$C,FALSE)),"") -> #NAME? | AV6: =_xludf.ifna(INDEX($U:$U,MATCH(AT6,$C:$C,FALSE)),"") -> #NAME? | AW6: =_xludf.ifna(INDEX($Z:$Z,MATCH(AT6,$C:$C,FALSE)),"") -> #NAME? | AX6: =_xludf.ifna(INDEX($AA:$AA,MATCH(AT6,$C:$C,FALSE)),"") -> #NAME? | AY6: =IFERROR(INDEX($R:$R,MATCH(AT6,$C:$C,FALSE)),"") -> PO BOSTON | AZ6: =_xludf.ifna(INDEX($V:$V,MATCH(AT6,$C:$C,FALSE)),"") -> #NAME? | BA6: =_xludf.ifna(INDEX($W:$W,MATCH(AT6,$C:$C,FALSE)),"") -> #NAME? | BB6: =_xludf.ifna(INDEX($X:$X,MATCH(AT6,$C:$C,FALSE)),"") -> #NAME? | BC6: =_xludf.ifna(INDEX($AD:$AD,MATCH(AT6,$C:$C,FALSE)),"") -> #NAME? | BD6: =_xludf.ifna(INDEX($AE:$AE,MATCH(AT6,$C:$C,FALSE)),"") -> #NAME? | BE6: =_xludf.ifna(INDEX($AG:$AG,MATCH(AT6,$C:$C,FALSE)),"") -> #NAME? | BF6: =_xludf.ifna(INDEX($T:$T,MATCH(AT6,$C:$C,FALSE),""),"") -> #NAME? | BG6: =_xludf.ifna(INDEX($AI:$AI,MATCH(AT6,$C:$C,FALSE)),"") -> #NAME? | BI6: 4 | BJ6: INVOICE | BK6: =IFERROR(__xludf.DUMMYFUNCTION("COUNTUNIQUEIFS(C3:C514,AF3:AF514,$BK$2)"),129) -> 129 | BL6: =IFERROR(__xludf.DUMMYFUNCTION("COUNTUNIQUEIFS(C3:C514,AF3:AF514,$BL$2)"),0) -> 0 | BM6: =SUM(BK6:BL6) -> 129
A7: =IF(C7=0,"",ROW()-ROW($A$2)) -> 5 | B7: 46025 | C7: GMIAMMIPT/2026/01/0001 | D7: 7L23-28-RD-1 | E7: Weather Proof In-Line Fuse Holder Red | F7: 1 | G7: EA | H7: =IF(C7=0,"",IF(R7>0,"DONE","WAITING")) -> DONE | I7: D5140 | J7: D155A-6 | K7: Komatsu | L7: 8092 | M7: PS 4000 | N7: PS 4000 | O7: TRACK | P7: HANDRIAN | Q7: COBRA | R7: 200000986794 | S7: 46028 | T7: =IF(C7=0,"",IF(ISBLANK(S7),"WAITING","DONE")) -> DONE | U7: 46031 | V7: 9200066845 | W7: 41875 | X7: 46034 | Y7: =IF(C7=0,"",IF(V7>0,"DONE","WAITING")) -> DONE | Z7: DO 45711 | AA7: 46036 | AB7: =IF(C7=0,"",IF(Z7>0,"DONE","WAITING")) -> DONE | AD7: GMI26-0044682 | AE7: 46037 | AF7: =IF(C7=0,"",IF(ISBLANK(AD7),"WAITING","DONE")) -> DONE | AG7: 46038 | AH7: 46098 | AI7: =IF(AD7=0,"",IF(ISBLANK(AH7),"UNPAID","PAID")) -> PAID | AJ7: {=IFERROR(INDEX('[1]Master Price'!$E:$E,MATCH(D7,'[1]Master Price'!$B:$B,0)),"0")} -> 0 | AK7: =AJ7*F7 -> 0 | AL7: =IFERROR(DATEDIF(S7,T7,"d"),"0")&"-day" -> 0-day | AM7: =IFERROR(DATEDIF(S7,U7,"d"),"0")&"-day" -> 3-day | AN7: =IFERROR(DATEDIF(S7,X7,"d"),"0")&"-day" -> 6-day | AO7: =IFERROR(DATEDIF(X7,AA7,"d"),"0")&"-day" -> 2-day | AP7: =IFERROR(DATEDIF(AA7,AE7,"d"),"0")&"-day" -> 1-day | AQ7: =SUM(AL7:AP7)&"-day" -> 0-day | AS7: =IF(AT7=0,"",ROW()-ROW($AS$2)) -> 5 | AT7: GMIAMMIPT/2026/01/0005 | AU7: =_xludf.ifna(INDEX($B:$B,MATCH(AT7,$C:$C,FALSE)),"") -> #NAME? | AV7: =_xludf.ifna(INDEX($U:$U,MATCH(AT7,$C:$C,FALSE)),"") -> #NAME? | AW7: =_xludf.ifna(INDEX($Z:$Z,MATCH(AT7,$C:$C,FALSE)),"") -> #NAME? | AX7: =_xludf.ifna(INDEX($AA:$AA,MATCH(AT7,$C:$C,FALSE)),"") -> #NAME? | AY7: =IFERROR(INDEX($R:$R,MATCH(AT7,$C:$C,FALSE)),"") -> 200000986781 | AZ7: =_xludf.ifna(INDEX($V:$V,MATCH(AT7,$C:$C,FALSE)),"") -> #NAME? | BA7: =_xludf.ifna(INDEX($W:$W,MATCH(AT7,$C:$C,FALSE)),"") -> #NAME? | BB7: =_xludf.ifna(INDEX($X:$X,MATCH(AT7,$C:$C,FALSE)),"") -> #NAME? | BC7: =_xludf.ifna(INDEX($AD:$AD,MATCH(AT7,$C:$C,FALSE)),"") -> #NAME? | BD7: =_xludf.ifna(INDEX($AE:$AE,MATCH(AT7,$C:$C,FALSE)),"") -> #NAME? | BE7: =_xludf.ifna(INDEX($AG:$AG,MATCH(AT7,$C:$C,FALSE)),"") -> #NAME? | BF7: =_xludf.ifna(INDEX($T:$T,MATCH(AT7,$C:$C,FALSE),""),"") -> #NAME? | BG7: =_xludf.ifna(INDEX($AI:$AI,MATCH(AT7,$C:$C,FALSE)),"") -> #NAME?
A8: =IF(C8=0,"",ROW()-ROW($A$2)) -> 6 | B8: 46025 | C8: GMIAMMIPT/2026/01/0001 | D8: 13L-10AFH | E8: Fuse 10A & Fuse Holder Set | F8: 1 | G8: EA | H8: =IF(C8=0,"",IF(R8>0,"DONE","WAITING")) -> DONE | I8: D5140 | J8: D155A-6 | K8: Komatsu | L8: 8092 | M8: PS 4000 | N8: PS 4000 | O8: TRACK | P8: HANDRIAN | Q8: COBRA | R8: 200000986794 | S8: 46028 | T8: =IF(C8=0,"",IF(ISBLANK(S8),"WAITING","DONE")) -> DONE | U8: 46031 | V8: 9200066845 | W8: 41875 | X8: 46034 | Y8: =IF(C8=0,"",IF(V8>0,"DONE","WAITING")) -> DONE | Z8: DO 45711 | AA8: 46036 | AB8: =IF(C8=0,"",IF(Z8>0,"DONE","WAITING")) -> DONE | AD8: GMI26-0044682 | AE8: 46037 | AF8: =IF(C8=0,"",IF(ISBLANK(AD8),"WAITING","DONE")) -> DONE | AG8: 46038 | AH8: 46098 | AI8: =IF(AD8=0,"",IF(ISBLANK(AH8),"UNPAID","PAID")) -> PAID | AJ8: {=IFERROR(INDEX('[1]Master Price'!$E:$E,MATCH(D8,'[1]Master Price'!$B:$B,0)),"0")} -> 0 | AK8: =AJ8*F8 -> 0 | AL8: =IFERROR(DATEDIF(S8,T8,"d"),"0")&"-day" -> 0-day | AM8: =IFERROR(DATEDIF(S8,U8,"d"),"0")&"-day" -> 3-day | AN8: =IFERROR(DATEDIF(S8,X8,"d"),"0")&"-day" -> 6-day | AO8: =IFERROR(DATEDIF(X8,AA8,"d"),"0")&"-day" -> 2-day | AP8: =IFERROR(DATEDIF(AA8,AE8,"d"),"0")&"-day" -> 1-day | AQ8: =SUM(AL8:AP8)&"-day" -> 0-day | AS8: =IF(AT8=0,"",ROW()-ROW($AS$2)) -> 6 | AT8: GMIAMMIPT/2026/01/0006 | AU8: =_xludf.ifna(INDEX($B:$B,MATCH(AT8,$C:$C,FALSE)),"") -> #NAME? | AV8: =_xludf.ifna(INDEX($U:$U,MATCH(AT8,$C:$C,FALSE)),"") -> #NAME? | AW8: =_xludf.ifna(INDEX($Z:$Z,MATCH(AT8,$C:$C,FALSE)),"") -> #NAME? | AX8: =_xludf.ifna(INDEX($AA:$AA,MATCH(AT8,$C:$C,FALSE)),"") -> #NAME? | AY8: =IFERROR(INDEX($R:$R,MATCH(AT8,$C:$C,FALSE)),"") -> 200000986778 | AZ8: =_xludf.ifna(INDEX($V:$V,MATCH(AT8,$C:$C,FALSE)),"") -> #NAME? | BA8: =_xludf.ifna(INDEX($W:$W,MATCH(AT8,$C:$C,FALSE)),"") -> #NAME? | BB8: =_xludf.ifna(INDEX($X:$X,MATCH(AT8,$C:$C,FALSE)),"") -> #NAME? | BC8: =_xludf.ifna(INDEX($AD:$AD,MATCH(AT8,$C:$C,FALSE)),"") -> #NAME? | BD8: =_xludf.ifna(INDEX($AE:$AE,MATCH(AT8,$C:$C,FALSE)),"") -> #NAME? | BE8: =_xludf.ifna(INDEX($AG:$AG,MATCH(AT8,$C:$C,FALSE)),"") -> #NAME? | BF8: =_xludf.ifna(INDEX($T:$T,MATCH(AT8,$C:$C,FALSE),""),"") -> #NAME? | BG8: =_xludf.ifna(INDEX($AI:$AI,MATCH(AT8,$C:$C,FALSE)),"") -> #NAME?
A9: =IF(C9=0,"",ROW()-ROW($A$2)) -> 7 | B9: 46025 | C9: GMIAMMIPT/2026/01/0001 | D9: 5L17-314-BK | E9: NITTO 21E PVC TAPE 19MM X 20M BLACK | F9: 1 | G9: EA | H9: =IF(C9=0,"",IF(R9>0,"DONE","WAITING")) -> DONE | I9: D5140 | J9: D155A-6 | K9: Komatsu | L9: 8092 | M9: PS 4000 | N9: PS 4000 | O9: TRACK | P9: HANDRIAN | Q9: COBRA | R9: 200000986794 | S9: 46028 | T9: =IF(C9=0,"",IF(ISBLANK(S9),"WAITING","DONE")) -> DONE | U9: 46031 | V9: 9200066845 | W9: 41875 | X9: 46034 | Y9: =IF(C9=0,"",IF(V9>0,"DONE","WAITING")) -> DONE | Z9: DO 45711 | AA9: 46036 | AB9: =IF(C9=0,"",IF(Z9>0,"DONE","WAITING")) -> DONE | AD9: GMI26-0044682 | AE9: 46037 | AF9: =IF(C9=0,"",IF(ISBLANK(AD9),"WAITING","DONE")) -> DONE | AG9: 46038 | AH9: 46098 | AI9: =IF(AD9=0,"",IF(ISBLANK(AH9),"UNPAID","PAID")) -> PAID | AJ9: {=IFERROR(INDEX('[1]Master Price'!$E:$E,MATCH(D9,'[1]Master Price'!$B:$B,0)),"0")} -> 0 | AK9: =AJ9*F9 -> 0 | AL9: =IFERROR(DATEDIF(S9,T9,"d"),"0")&"-day" -> 0-day | AM9: =IFERROR(DATEDIF(S9,U9,"d"),"0")&"-day" -> 3-day | AN9: =IFERROR(DATEDIF(S9,X9,"d"),"0")&"-day" -> 6-day | AO9: =IFERROR(DATEDIF(X9,AA9,"d"),"0")&"-day" -> 2-day | AP9: =IFERROR(DATEDIF(AA9,AE9,"d"),"0")&"-day" -> 1-day | AQ9: =SUM(AL9:AP9)&"-day" -> 0-day | AS9: =IF(AT9=0,"",ROW()-ROW($AS$2)) -> 7 | AT9: GMIAMMIPT/2026/01/0007 | AU9: =_xludf.ifna(INDEX($B:$B,MATCH(AT9,$C:$C,FALSE)),"") -> #NAME? | AV9: =_xludf.ifna(INDEX($U:$U,MATCH(AT9,$C:$C,FALSE)),"") -> #NAME? | AW9: =_xludf.ifna(INDEX($Z:$Z,MATCH(AT9,$C:$C,FALSE)),"") -> #NAME? | AX9: =_xludf.ifna(INDEX($AA:$AA,MATCH(AT9,$C:$C,FALSE)),"") -> #NAME? | AY9: =IFERROR(INDEX($R:$R,MATCH(AT9,$C:$C,FALSE)),"") -> 200000986774 | AZ9: =_xludf.ifna(INDEX($V:$V,MATCH(AT9,$C:$C,FALSE)),"") -> #NAME? | BA9: =_xludf.ifna(INDEX($W:$W,MATCH(AT9,$C:$C,FALSE)),"") -> #NAME? | BB9: =_xludf.ifna(INDEX($X:$X,MATCH(AT9,$C:$C,FALSE)),"") -> #NAME? | BC9: =_xludf.ifna(INDEX($AD:$AD,MATCH(AT9,$C:$C,FALSE)),"") -> #NAME? | BD9: =_xludf.ifna(INDEX($AE:$AE,MATCH(AT9,$C:$C,FALSE)),"") -> #NAME? | BE9: =_xludf.ifna(INDEX($AG:$AG,MATCH(AT9,$C:$C,FALSE)),"") -> #NAME? | BF9: =_xludf.ifna(INDEX($T:$T,MATCH(AT9,$C:$C,FALSE),""),"") -> #NAME? | BG9: =_xludf.ifna(INDEX($AI:$AI,MATCH(AT9,$C:$C,FALSE)),"") -> #NAME?
A10: =IF(C10=0,"",ROW()-ROW($A$2)) -> 8 | B10: 46025 | C10: GMIAMMIPT/2026/01/0001 | D10: 14L-0094-F | E10: THERMOSTAT FUJIN | F10: 1 | G10: EA | H10: =IF(C10=0,"",IF(R10>0,"DONE","WAITING")) -> DONE | I10: D5140 | J10: D155A-6 | K10: Komatsu | L10: 8092 | M10: PS 4000 | N10: PS 4000 | O10: TRACK | P10: HANDRIAN | Q10: COBRA | R10: 200000986794 | S10: 46028 | T10: =IF(C10=0,"",IF(ISBLANK(S10),"WAITING","DONE")) -> DONE | U10: 46031 | V10: 9200066845 | W10: 41875 | X10: 46034 | Y10: =IF(C10=0,"",IF(V10>0,"DONE","WAITING")) -> DONE | Z10: DO 45711 | AA10: 46036 | AB10: =IF(C10=0,"",IF(Z10>0,"DONE","WAITING")) -> DONE | AD10: GMI26-0044682 | AE10: 46037 | AF10: =IF(C10=0,"",IF(ISBLANK(AD10),"WAITING","DONE")) -> DONE | AG10: 46038 | AH10: 46098 | AI10: =IF(AD10=0,"",IF(ISBLANK(AH10),"UNPAID","PAID")) -> PAID | AJ10: {=IFERROR(INDEX('[1]Master Price'!$E:$E,MATCH(D10,'[1]Master Price'!$B:$B,0)),"0")} -> 0 | AK10: =AJ10*F10 -> 0 | AL10: =IFERROR(DATEDIF(S10,T10,"d"),"0")&"-day" -> 0-day | AM10: =IFERROR(DATEDIF(S10,U10,"d"),"0")&"-day" -> 3-day | AN10: =IFERROR(DATEDIF(S10,X10,"d"),"0")&"-day" -> 6-day | AO10: =IFERROR(DATEDIF(X10,AA10,"d"),"0")&"-day" -> 2-day | AP10: =IFERROR(DATEDIF(AA10,AE10,"d"),"0")&"-day" -> 1-day | AQ10: =SUM(AL10:AP10)&"-day" -> 0-day | AS10: =IF(AT10=0,"",ROW()-ROW($AS$2)) -> 8 | AT10: GMIAMMIPT/2026/01/0008 | AU10: =_xludf.ifna(INDEX($B:$B,MATCH(AT10,$C:$C,FALSE)),"") -> #NAME? | AV10: =_xludf.ifna(INDEX($U:$U,MATCH(AT10,$C:$C,FALSE)),"") -> #NAME? | AW10: =_xludf.ifna(INDEX($Z:$Z,MATCH(AT10,$C:$C,FALSE)),"") -> #NAME? | AX10: =_xludf.ifna(INDEX($AA:$AA,MATCH(AT10,$C:$C,FALSE)),"") -> #NAME? | AY10: =IFERROR(INDEX($R:$R,MATCH(AT10,$C:$C,FALSE)),"") -> 200000986769 | AZ10: =_xludf.ifna(INDEX($V:$V,MATCH(AT10,$C:$C,FALSE)),"") -> #NAME? | BA10: =_xludf.ifna(INDEX($W:$W,MATCH(AT10,$C:$C,FALSE)),"") -> #NAME? | BB10: =_xludf.ifna(INDEX($X:$X,MATCH(AT10,$C:$C,FALSE)),"") -> #NAME? | BC10: =_xludf.ifna(INDEX($AD:$AD,MATCH(AT10,$C:$C,FALSE)),"") -> #NAME? | BD10: =_xludf.ifna(INDEX($AE:$AE,MATCH(AT10,$C:$C,FALSE)),"") -> #NAME? | BE10: =_xludf.ifna(INDEX($AG:$AG,MATCH(AT10,$C:$C,FALSE)),"") -> #NAME? | BF10: =_xludf.ifna(INDEX($T:$T,MATCH(AT10,$C:$C,FALSE),""),"") -> #NAME? | BG10: =_xludf.ifna(INDEX($AI:$AI,MATCH(AT10,$C:$C,FALSE)),"") -> #NAME?
A11: =IF(C11=0,"",ROW()-ROW($A$2)) -> 9 | B11: 46025 | C11: GMIAMMIPT/2026/01/0001 | D11: 7L64-WP | E11: Relay Holder Tanpa Pin | F11: 2 | G11: EA | H11: =IF(C11=0,"",IF(R11>0,"DONE","WAITING")) -> DONE | I11: D5140 | J11: D155A-6 | K11: Komatsu | L11: 8092 | M11: PS 4000 | N11: PS 4000 | O11: TRACK | P11: HANDRIAN | Q11: COBRA | R11: 200000986794 | S11: 46028 | T11: =IF(C11=0,"",IF(ISBLANK(S11),"WAITING","DONE")) -> DONE | U11: 46031 | V11: 9200066845 | W11: 41875 | X11: 46034 | Y11: =IF(C11=0,"",IF(V11>0,"DONE","WAITING")) -> DONE | Z11: DO 45711 | AA11: 46036 | AB11: =IF(C11=0,"",IF(Z11>0,"DONE","WAITING")) -> DONE | AD11: GMI26-0044682 | AE11: 46037 | AF11: =IF(C11=0,"",IF(ISBLANK(AD11),"WAITING","DONE")) -> DONE | AG11: 46038 | AH11: 46098 | AI11: =IF(AD11=0,"",IF(ISBLANK(AH11),"UNPAID","PAID")) -> PAID | AJ11: {=IFERROR(INDEX('[1]Master Price'!$E:$E,MATCH(D11,'[1]Master Price'!$B:$B,0)),"0")} -> 0 | AK11: =AJ11*F11 -> 0 | AL11: =IFERROR(DATEDIF(S11,T11,"d"),"0")&"-day" -> 0-day | AM11: =IFERROR(DATEDIF(S11,U11,"d"),"0")&"-day" -> 3-day | AN11: =IFERROR(DATEDIF(S11,X11,"d"),"0")&"-day" -> 6-day | AO11: =IFERROR(DATEDIF(X11,AA11,"d"),"0")&"-day" -> 2-day | AP11: =IFERROR(DATEDIF(AA11,AE11,"d"),"0")&"-day" -> 1-day | AQ11: =SUM(AL11:AP11)&"-day" -> 0-day | AS11: =IF(AT11=0,"",ROW()-ROW($AS$2)) -> 9 | AT11: GMIAMMIPT/2026/01/0009 | AU11: =_xludf.ifna(INDEX($B:$B,MATCH(AT11,$C:$C,FALSE)),"") -> #NAME? | AV11: =_xludf.ifna(INDEX($U:$U,MATCH(AT11,$C:$C,FALSE)),"") -> #NAME? | AW11: =_xludf.ifna(INDEX($Z:$Z,MATCH(AT11,$C:$C,FALSE)),"") -> #NAME? | AX11: =_xludf.ifna(INDEX($AA:$AA,MATCH(AT11,$C:$C,FALSE)),"") -> #NAME? | AY11: =IFERROR(INDEX($R:$R,MATCH(AT11,$C:$C,FALSE)),"") -> 200000986767 | AZ11: =_xludf.ifna(INDEX($V:$V,MATCH(AT11,$C:$C,FALSE)),"") -> #NAME? | BA11: =_xludf.ifna(INDEX($W:$W,MATCH(AT11,$C:$C,FALSE)),"") -> #NAME? | BB11: =_xludf.ifna(INDEX($X:$X,MATCH(AT11,$C:$C,FALSE)),"") -> #NAME? | BC11: =_xludf.ifna(INDEX($AD:$AD,MATCH(AT11,$C:$C,FALSE)),"") -> #NAME? | BD11: =_xludf.ifna(INDEX($AE:$AE,MATCH(AT11,$C:$C,FALSE)),"") -> #NAME? | BE11: =_xludf.ifna(INDEX($AG:$AG,MATCH(AT11,$C:$C,FALSE)),"") -> #NAME? | BF11: =_xludf.ifna(INDEX($T:$T,MATCH(AT11,$C:$C,FALSE),""),"") -> #NAME? | BG11: =_xludf.ifna(INDEX($AI:$AI,MATCH(AT11,$C:$C,FALSE)),"") -> #NAME?
A12: =IF(C12=0,"",ROW()-ROW($A$2)) -> 10 | B12: 46025 | C12: GMIAMMIPT/2026/01/0002 | D12: 6L1-48-1 | E12: Vinyl Fully Insulated Female Blade Terminal blue 4mm | F12: 10 | G12: EA | H12: =IF(C12=0,"",IF(R12>0,"DONE","WAITING")) -> DONE | I12: E3902 | J12: CAT 395 | K12: Caterpillar | N12: AC HOT | O12: TRACK | P12: AZIZ | Q12: IMAM | R12: 200000986789 | S12: 46028 | T12: =IF(C12=0,"",IF(ISBLANK(S12),"WAITING","DONE")) -> DONE | U12: 46031 | V12: 9200066826 | W12: 41883 | X12: 46034 | Y12: =IF(C12=0,"",IF(V12>0,"DONE","WAITING")) -> DONE | Z12: DO 45721 | AA12: 46036 | AB12: =IF(C12=0,"",IF(Z12>0,"DONE","WAITING")) -> DONE | AD12: GMI26-0044683 | AE12: 46037 | AF12: =IF(C12=0,"",IF(ISBLANK(AD12),"WAITING","DONE")) -> DONE | AG12: 46038 | AH12: 46098 | AI12: =IF(AD12=0,"",IF(ISBLANK(AH12),"UNPAID","PAID")) -> PAID | AJ12: {=IFERROR(INDEX('[1]Master Price'!$E:$E,MATCH(D12,'[1]Master Price'!$B:$B,0)),"0")} -> 0 | AK12: =AJ12*F12 -> 0 | AL12: =IFERROR(DATEDIF(S12,T12,"d"),"0")&"-day" -> 0-day | AM12: =IFERROR(DATEDIF(S12,U12,"d"),"0")&"-day" -> 3-day | AN12: =IFERROR(DATEDIF(S12,X12,"d"),"0")&"-day" -> 6-day | AO12: =IFERROR(DATEDIF(X12,AA12,"d"),"0")&"-day" -> 2-day | AP12: =IFERROR(DATEDIF(AA12,AE12,"d"),"0")&"-day" -> 1-day | AQ12: =SUM(AL12:AP12)&"-day" -> 0-day | AS12: =IF(AT12=0,"",ROW()-ROW($AS$2)) -> 10 | AT12: GMIAMMIPT/2026/01/0010 | AU12: =_xludf.ifna(INDEX($B:$B,MATCH(AT12,$C:$C,FALSE)),"") -> #NAME? | AV12: =_xludf.ifna(INDEX($U:$U,MATCH(AT12,$C:$C,FALSE)),"") -> #NAME? | AW12: =_xludf.ifna(INDEX($Z:$Z,MATCH(AT12,$C:$C,FALSE)),"") -> #NAME? | AX12: =_xludf.ifna(INDEX($AA:$AA,MATCH(AT12,$C:$C,FALSE)),"") -> #NAME? | AY12: =IFERROR(INDEX($R:$R,MATCH(AT12,$C:$C,FALSE)),"") -> 200000986766 | AZ12: =_xludf.ifna(INDEX($V:$V,MATCH(AT12,$C:$C,FALSE)),"") -> #NAME? | BA12: =_xludf.ifna(INDEX($W:$W,MATCH(AT12,$C:$C,FALSE)),"") -> #NAME? | BB12: =_xludf.ifna(INDEX($X:$X,MATCH(AT12,$C:$C,FALSE)),"") -> #NAME? | BC12: =_xludf.ifna(INDEX($AD:$AD,MATCH(AT12,$C:$C,FALSE)),"") -> #NAME? | BD12: =_xludf.ifna(INDEX($AE:$AE,MATCH(AT12,$C:$C,FALSE)),"") -> #NAME? | BE12: =_xludf.ifna(INDEX($AG:$AG,MATCH(AT12,$C:$C,FALSE)),"") -> #NAME? | BF12: =_xludf.ifna(INDEX($T:$T,MATCH(AT12,$C:$C,FALSE),""),"") -> #NAME? | BG12: =_xludf.ifna(INDEX($AI:$AI,MATCH(AT12,$C:$C,FALSE)),"") -> #NAME?
A13: =IF(C13=0,"",ROW()-ROW($A$2)) -> 11 | B13: 46025 | C13: GMIAMMIPT/2026/01/0002 | D13: 14L-0094-F | E13: THERMOSTAT FUJIN | F13: 1 | G13: EA | H13: =IF(C13=0,"",IF(R13>0,"DONE","WAITING")) -> DONE | I13: E3902 | J13: CAT 395 | K13: Caterpillar | N13: AC HOT | O13: TRACK | P13: AZIZ | Q13: IMAM | R13: 200000986789 | S13: 46028 | T13: =IF(C13=0,"",IF(ISBLANK(S13),"WAITING","DONE")) -> DONE | U13: 46031 | V13: 9200066826 | W13: 41883 | X13: 46034 | Y13: =IF(C13=0,"",IF(V13>0,"DONE","WAITING")) -> DONE | Z13: DO 45721 | AA13: 46036 | AB13: =IF(C13=0,"",IF(Z13>0,"DONE","WAITING")) -> DONE | AD13: GMI26-0044683 | AE13: 46037 | AF13: =IF(C13=0,"",IF(ISBLANK(AD13),"WAITING","DONE")) -> DONE | AG13: 46038 | AH13: 46098 | AI13: =IF(AD13=0,"",IF(ISBLANK(AH13),"UNPAID","PAID")) -> PAID | AJ13: {=IFERROR(INDEX('[1]Master Price'!$E:$E,MATCH(D13,'[1]Master Price'!$B:$B,0)),"0")} -> 0 | AK13: =AJ13*F13 -> 0 | AL13: =IFERROR(DATEDIF(S13,T13,"d"),"0")&"-day" -> 0-day | AM13: =IFERROR(DATEDIF(S13,U13,"d"),"0")&"-day" -> 3-day | AN13: =IFERROR(DATEDIF(S13,X13,"d"),"0")&"-day" -> 6-day | AO13: =IFERROR(DATEDIF(X13,AA13,"d"),"0")&"-day" -> 2-day | AP13: =IFERROR(DATEDIF(AA13,AE13,"d"),"0")&"-day" -> 1-day | AQ13: =SUM(AL13:AP13)&"-day" -> 0-day | AS13: =IF(AT13=0,"",ROW()-ROW($AS$2)) -> 11 | AT13: GMIAMMIPT/2026/01/0011 | AU13: =_xludf.ifna(INDEX($B:$B,MATCH(AT13,$C:$C,FALSE)),"") -> #NAME? | AV13: =_xludf.ifna(INDEX($U:$U,MATCH(AT13,$C:$C,FALSE)),"") -> #NAME? | AW13: =_xludf.ifna(INDEX($Z:$Z,MATCH(AT13,$C:$C,FALSE)),"") -> #NAME? | AX13: =_xludf.ifna(INDEX($AA:$AA,MATCH(AT13,$C:$C,FALSE)),"") -> #NAME? | AY13: =IFERROR(INDEX($R:$R,MATCH(AT13,$C:$C,FALSE)),"") -> 200000986763 | AZ13: =_xludf.ifna(INDEX($V:$V,MATCH(AT13,$C:$C,FALSE)),"") -> #NAME? | BA13: =_xludf.ifna(INDEX($W:$W,MATCH(AT13,$C:$C,FALSE)),"") -> #NAME? | BB13: =_xludf.ifna(INDEX($X:$X,MATCH(AT13,$C:$C,FALSE)),"") -> #NAME? | BC13: =_xludf.ifna(INDEX($AD:$AD,MATCH(AT13,$C:$C,FALSE)),"") -> #NAME? | BD13: =_xludf.ifna(INDEX($AE:$AE,MATCH(AT13,$C:$C,FALSE)),"") -> #NAME? | BE13: =_xludf.ifna(INDEX($AG:$AG,MATCH(AT13,$C:$C,FALSE)),"") -> #NAME? | BF13: =_xludf.ifna(INDEX($T:$T,MATCH(AT13,$C:$C,FALSE),""),"") -> #NAME? | BG13: =_xludf.ifna(INDEX($AI:$AI,MATCH(AT13,$C:$C,FALSE)),"") -> #NAME?
A14: =IF(C14=0,"",ROW()-ROW($A$2)) -> 12 | B14: 46025 | C14: GMIAMMIPT/2026/01/0002 | D14: 5L17-187-BK | E14: Cable Ties width: 4.8mm, length: 380mm Black (pack 0f 100) | F14: 1 | G14: EA | H14: =IF(C14=0,"",IF(R14>0,"DONE","WAITING")) -> DONE | I14: E3902 | J14: CAT 395 | K14: Caterpillar | N14: AC HOT | O14: TRACK | P14: AZIZ | Q14: IMAM | R14: 200000986789 | S14: 46028 | T14: =IF(C14=0,"",IF(ISBLANK(S14),"WAITING","DONE")) -> DONE | U14: 46031 | V14: 9200066826 | W14: 41883 | X14: 46034 | Y14: =IF(C14=0,"",IF(V14>0,"DONE","WAITING")) -> DONE | Z14: DO 45721 | AA14: 46036 | AB14: =IF(C14=0,"",IF(Z14>0,"DONE","WAITING")) -> DONE | AD14: GMI26-0044683 | AE14: 46037 | AF14: =IF(C14=0,"",IF(ISBLANK(AD14),"WAITING","DONE")) -> DONE | AG14: 46038 | AH14: 46098 | AI14: =IF(AD14=0,"",IF(ISBLANK(AH14),"UNPAID","PAID")) -> PAID | AJ14: {=IFERROR(INDEX('[1]Master Price'!$E:$E,MATCH(D14,'[1]Master Price'!$B:$B,0)),"0")} -> 0 | AK14: =AJ14*F14 -> 0 | AL14: =IFERROR(DATEDIF(S14,T14,"d"),"0")&"-day" -> 0-day | AM14: =IFERROR(DATEDIF(S14,U14,"d"),"0")&"-day" -> 3-day | AN14: =IFERROR(DATEDIF(S14,X14,"d"),"0")&"-day" -> 6-day | AO14: =IFERROR(DATEDIF(X14,AA14,"d"),"0")&"-day" -> 2-day | AP14: =IFERROR(DATEDIF(AA14,AE14,"d"),"0")&"-day" -> 1-day | AQ14: =SUM(AL14:AP14)&"-day" -> 0-day | AS14: =IF(AT14=0,"",ROW()-ROW($AS$2)) -> 12 | AT14: GMIAMMIPT/2026/01/0012 | AU14: =_xludf.ifna(INDEX($B:$B,MATCH(AT14,$C:$C,FALSE)),"") -> #NAME? | AV14: =_xludf.ifna(INDEX($U:$U,MATCH(AT14,$C:$C,FALSE)),"") -> #NAME? | AW14: =_xludf.ifna(INDEX($Z:$Z,MATCH(AT14,$C:$C,FALSE)),"") -> #NAME? | AX14: =_xludf.ifna(INDEX($AA:$AA,MATCH(AT14,$C:$C,FALSE)),"") -> #NAME? | AY14: =IFERROR(INDEX($R:$R,MATCH(AT14,$C:$C,FALSE)),"") -> 200000986759 | AZ14: =_xludf.ifna(INDEX($V:$V,MATCH(AT14,$C:$C,FALSE)),"") -> #NAME? | BA14: =_xludf.ifna(INDEX($W:$W,MATCH(AT14,$C:$C,FALSE)),"") -> #NAME? | BB14: =_xludf.ifna(INDEX($X:$X,MATCH(AT14,$C:$C,FALSE)),"") -> #NAME? | BC14: =_xludf.ifna(INDEX($AD:$AD,MATCH(AT14,$C:$C,FALSE)),"") -> #NAME? | BD14: =_xludf.ifna(INDEX($AE:$AE,MATCH(AT14,$C:$C,FALSE)),"") -> #NAME? | BE14: =_xludf.ifna(INDEX($AG:$AG,MATCH(AT14,$C:$C,FALSE)),"") -> #NAME? | BF14: =_xludf.ifna(INDEX($T:$T,MATCH(AT14,$C:$C,FALSE),""),"") -> #NAME? | BG14: =_xludf.ifna(INDEX($AI:$AI,MATCH(AT14,$C:$C,FALSE)),"") -> #NAME?
A15: =IF(C15=0,"",ROW()-ROW($A$2)) -> 13 | B15: 46025 | C15: GMIAMMIPT/2026/01/0003 | D15: 7L23-27 | E15: Weather Proof In-Line Fuse Holder (pack of 1) | F15: 2 | G15: EA | H15: =IF(C15=0,"",IF(R15>0,"DONE","WAITING")) -> DONE | I15: SV521 | J15: SV700TF | K15: Sakai | L15: 6307 | N15: AC HOT | O15: WHEEL | P15: DHIMAS | Q15: WAHYUDIN | R15: 200000986786 | S15: 46028 | T15: =IF(C15=0,"",IF(ISBLANK(S15),"WAITING","DONE")) -> DONE | U15: 46031 | V15: 9200066841 | W15: 41879 | X15: 46034 | Y15: =IF(C15=0,"",IF(V15>0,"DONE","WAITING")) -> DONE | Z15: DO 45715 | AA15: 46036 | AB15: =IF(C15=0,"",IF(Z15>0,"DONE","WAITING")) -> DONE | AD15: GMI26-0044684 | AE15: 46037 | AF15: =IF(C15=0,"",IF(ISBLANK(AD15),"WAITING","DONE")) -> DONE | AG15: 46038 | AH15: 46098 | AI15: =IF(AD15=0,"",IF(ISBLANK(AH15),"UNPAID","PAID")) -> PAID | AJ15: {=IFERROR(INDEX('[1]Master Price'!$E:$E,MATCH(D15,'[1]Master Price'!$B:$B,0)),"0")} -> 0 | AK15: =AJ15*F15 -> 0 | AL15: =IFERROR(DATEDIF(S15,T15,"d"),"0")&"-day" -> 0-day | AM15: =IFERROR(DATEDIF(S15,U15,"d"),"0")&"-day" -> 3-day | AN15: =IFERROR(DATEDIF(S15,X15,"d"),"0")&"-day" -> 6-day | AO15: =IFERROR(DATEDIF(X15,AA15,"d"),"0")&"-day" -> 2-day | AP15: =IFERROR(DATEDIF(AA15,AE15,"d"),"0")&"-day" -> 1-day | AQ15: =SUM(AL15:AP15)&"-day" -> 0-day | AS15: =IF(AT15=0,"",ROW()-ROW($AS$2)) -> 13 | AT15: GMIAMMIPT/2026/01/0013 | AU15: =_xludf.ifna(INDEX($B:$B,MATCH(AT15,$C:$C,FALSE)),"") -> #NAME? | AV15: =_xludf.ifna(INDEX($U:$U,MATCH(AT15,$C:$C,FALSE)),"") -> #NAME? | AW15: =_xludf.ifna(INDEX($Z:$Z,MATCH(AT15,$C:$C,FALSE)),"") -> #NAME? | AX15: =_xludf.ifna(INDEX($AA:$AA,MATCH(AT15,$C:$C,FALSE)),"") -> #NAME? | AY15: =IFERROR(INDEX($R:$R,MATCH(AT15,$C:$C,FALSE)),"") -> 200000986757 | AZ15: =_xludf.ifna(INDEX($V:$V,MATCH(AT15,$C:$C,FALSE)),"") -> #NAME? | BA15: =_xludf.ifna(INDEX($W:$W,MATCH(AT15,$C:$C,FALSE)),"") -> #NAME? | BB15: =_xludf.ifna(INDEX($X:$X,MATCH(AT15,$C:$C,FALSE)),"") -> #NAME? | BC15: =_xludf.ifna(INDEX($AD:$AD,MATCH(AT15,$C:$C,FALSE)),"") -> #NAME? | BD15: =_xludf.ifna(INDEX($AE:$AE,MATCH(AT15,$C:$C,FALSE)),"") -> #NAME? | BE15: =_xludf.ifna(INDEX($AG:$AG,MATCH(AT15,$C:$C,FALSE)),"") -> #NAME? | BF15: =_xludf.ifna(INDEX($T:$T,MATCH(AT15,$C:$C,FALSE),""),"") -> #NAME? | BG15: =_xludf.ifna(INDEX($AI:$AI,MATCH(AT15,$C:$C,FALSE)),"") -> #NAME?
A16: =IF(C16=0,"",ROW()-ROW($A$2)) -> 14 | B16: 46025 | C16: GMIAMMIPT/2026/01/0003 | D16: 7L64-WP | E16: Relay Holder Tanpa Pin | F16: 2 | G16: EA | H16: =IF(C16=0,"",IF(R16>0,"DONE","WAITING")) -> DONE | I16: SV521 | J16: SV700TF | K16: Sakai | L16: 6307 | N16: AC HOT | O16: WHEEL | P16: DHIMAS | Q16: WAHYUDIN | R16: 200000986786 | S16: 46028 | T16: =IF(C16=0,"",IF(ISBLANK(S16),"WAITING","DONE")) -> DONE | U16: 46031 | V16: 9200066841 | W16: 41879 | X16: 46034 | Y16: =IF(C16=0,"",IF(V16>0,"DONE","WAITING")) -> DONE | Z16: DO 45715 | AA16: 46036 | AB16: =IF(C16=0,"",IF(Z16>0,"DONE","WAITING")) -> DONE | AD16: GMI26-0044684 | AE16: 46037 | AF16: =IF(C16=0,"",IF(ISBLANK(AD16),"WAITING","DONE")) -> DONE | AG16: 46038 | AH16: 46098 | AI16: =IF(AD16=0,"",IF(ISBLANK(AH16),"UNPAID","PAID")) -> PAID | AJ16: {=IFERROR(INDEX('[1]Master Price'!$E:$E,MATCH(D16,'[1]Master Price'!$B:$B,0)),"0")} -> 0 | AK16: =AJ16*F16 -> 0 | AL16: =IFERROR(DATEDIF(S16,T16,"d"),"0")&"-day" -> 0-day | AM16: =IFERROR(DATEDIF(S16,U16,"d"),"0")&"-day" -> 3-day | AN16: =IFERROR(DATEDIF(S16,X16,"d"),"0")&"-day" -> 6-day | AO16: =IFERROR(DATEDIF(X16,AA16,"d"),"0")&"-day" -> 2-day | AP16: =IFERROR(DATEDIF(AA16,AE16,"d"),"0")&"-day" -> 1-day | AQ16: =SUM(AL16:AP16)&"-day" -> 0-day | AS16: =IF(AT16=0,"",ROW()-ROW($AS$2)) -> 14 | AT16: GMIAMMIPT/2026/01/0979 | AU16: =_xludf.ifna(INDEX($B:$B,MATCH(AT16,$C:$C,FALSE)),"") -> #NAME? | AV16: =_xludf.ifna(INDEX($U:$U,MATCH(AT16,$C:$C,FALSE)),"") -> #NAME? | AW16: =_xludf.ifna(INDEX($Z:$Z,MATCH(AT16,$C:$C,FALSE)),"") -> #NAME? | AX16: =_xludf.ifna(INDEX($AA:$AA,MATCH(AT16,$C:$C,FALSE)),"") -> #NAME? | AY16: =IFERROR(INDEX($R:$R,MATCH(AT16,$C:$C,FALSE)),"") -> 200000988561 | AZ16: =_xludf.ifna(INDEX($V:$V,MATCH(AT16,$C:$C,FALSE)),"") -> #NAME? | BA16: =_xludf.ifna(INDEX($W:$W,MATCH(AT16,$C:$C,FALSE)),"") -> #NAME? | BB16: =_xludf.ifna(INDEX($X:$X,MATCH(AT16,$C:$C,FALSE)),"") -> #NAME? | BC16: =_xludf.ifna(INDEX($AD:$AD,MATCH(AT16,$C:$C,FALSE)),"") -> #NAME? | BD16: =_xludf.ifna(INDEX($AE:$AE,MATCH(AT16,$C:$C,FALSE)),"") -> #NAME? | BE16: =_xludf.ifna(INDEX($AG:$AG,MATCH(AT16,$C:$C,FALSE)),"") -> #NAME? | BF16: =_xludf.ifna(INDEX($T:$T,MATCH(AT16,$C:$C,FALSE),""),"") -> #NAME? | BG16: =_xludf.ifna(INDEX($AI:$AI,MATCH(AT16,$C:$C,FALSE)),"") -> #NAME?
A17: =IF(C17=0,"",ROW()-ROW($A$2)) -> 15 | B17: 46025 | C17: GMIAMMIPT/2026/01/0003 | D17: 6L1-16-1 | E17: Vinyl Insulated Male Blade Terminal blue 4mm | F17: 10 | G17: EA | H17: =IF(C17=0,"",IF(R17>0,"DONE","WAITING")) -> DONE | I17: SV521 | J17: SV700TF | K17: Sakai | L17: 6307 | N17: AC HOT | O17: WHEEL | P17: DHIMAS | Q17: WAHYUDIN | R17: 200000986786 | S17: 46028 | T17: =IF(C17=0,"",IF(ISBLANK(S17),"WAITING","DONE")) -> DONE | U17: 46031 | V17: 9200066841 | W17: 41879 | X17: 46034 | Y17: =IF(C17=0,"",IF(V17>0,"DONE","WAITING")) -> DONE | Z17: DO 45715 | AA17: 46036 | AB17: =IF(C17=0,"",IF(Z17>0,"DONE","WAITING")) -> DONE | AD17: GMI26-0044684 | AE17: 46037 | AF17: =IF(C17=0,"",IF(ISBLANK(AD17),"WAITING","DONE")) -> DONE | AG17: 46038 | AH17: 46098 | AI17: =IF(AD17=0,"",IF(ISBLANK(AH17),"UNPAID","PAID")) -> PAID | AJ17: {=IFERROR(INDEX('[1]Master Price'!$E:$E,MATCH(D17,'[1]Master Price'!$B:$B,0)),"0")} -> 0 | AK17: =AJ17*F17 -> 0 | AL17: =IFERROR(DATEDIF(S17,T17,"d"),"0")&"-day" -> 0-day | AM17: =IFERROR(DATEDIF(S17,U17,"d"),"0")&"-day" -> 3-day | AN17: =IFERROR(DATEDIF(S17,X17,"d"),"0")&"-day" -> 6-day | AO17: =IFERROR(DATEDIF(X17,AA17,"d"),"0")&"-day" -> 2-day | AP17: =IFERROR(DATEDIF(AA17,AE17,"d"),"0")&"-day" -> 1-day | AQ17: =SUM(AL17:AP17)&"-day" -> 0-day | AS17: =IF(AT17=0,"",ROW()-ROW($AS$2)) -> 15 | AT17: GMIAMMIPT/2026/01/0980 | AU17: =_xludf.ifna(INDEX($B:$B,MATCH(AT17,$C:$C,FALSE)),"") -> #NAME? | AV17: =_xludf.ifna(INDEX($U:$U,MATCH(AT17,$C:$C,FALSE)),"") -> #NAME? | AW17: =_xludf.ifna(INDEX($Z:$Z,MATCH(AT17,$C:$C,FALSE)),"") -> #NAME? | AX17: =_xludf.ifna(INDEX($AA:$AA,MATCH(AT17,$C:$C,FALSE)),"") -> #NAME? | AY17: =IFERROR(INDEX($R:$R,MATCH(AT17,$C:$C,FALSE)),"") -> 200000988562 | AZ17: =_xludf.ifna(INDEX($V:$V,MATCH(AT17,$C:$C,FALSE)),"") -> #NAME? | BA17: =_xludf.ifna(INDEX($W:$W,MATCH(AT17,$C:$C,FALSE)),"") -> #NAME? | BB17: =_xludf.ifna(INDEX($X:$X,MATCH(AT17,$C:$C,FALSE)),"") -> #NAME? | BC17: =_xludf.ifna(INDEX($AD:$AD,MATCH(AT17,$C:$C,FALSE)),"") -> #NAME? | BD17: =_xludf.ifna(INDEX($AE:$AE,MATCH(AT17,$C:$C,FALSE)),"") -> #NAME? | BE17: =_xludf.ifna(INDEX($AG:$AG,MATCH(AT17,$C:$C,FALSE)),"") -> #NAME? | BF17: =_xludf.ifna(INDEX($T:$T,MATCH(AT17,$C:$C,FALSE),""),"") -> #NAME? | BG17: =_xludf.ifna(INDEX($AI:$AI,MATCH(AT17,$C:$C,FALSE)),"") -> #NAME?
A18: =IF(C18=0,"",ROW()-ROW($A$2)) -> 16 | B18: 46025 | C18: GMIAMMIPT/2026/01/0003 | D18: 6L1-112-1 | E18: Vinyl Insulated Ring Terminal blue 4mm | F18: 10 | G18: EA | H18: =IF(C18=0,"",IF(R18>0,"DONE","WAITING")) -> DONE | I18: SV521 | J18: SV700TF | K18: Sakai | L18: 6307 | N18: AC HOT | O18: WHEEL | P18: DHIMAS | Q18: WAHYUDIN | R18: 200000986786 | S18: 46028 | T18: =IF(C18=0,"",IF(ISBLANK(S18),"WAITING","DONE")) -> DONE | U18: 46031 | V18: 9200066841 | W18: 41879 | X18: 46034 | Y18: =IF(C18=0,"",IF(V18>0,"DONE","WAITING")) -> DONE | Z18: DO 45715 | AA18: 46036 | AB18: =IF(C18=0,"",IF(Z18>0,"DONE","WAITING")) -> DONE | AD18: GMI26-0044684 | AE18: 46037 | AF18: =IF(C18=0,"",IF(ISBLANK(AD18),"WAITING","DONE")) -> DONE | AG18: 46038 | AH18: 46098 | AI18: =IF(AD18=0,"",IF(ISBLANK(AH18),"UNPAID","PAID")) -> PAID | AJ18: {=IFERROR(INDEX('[1]Master Price'!$E:$E,MATCH(D18,'[1]Master Price'!$B:$B,0)),"0")} -> 0 | AK18: =AJ18*F18 -> 0 | AL18: =IFERROR(DATEDIF(S18,T18,"d"),"0")&"-day" -> 0-day | AM18: =IFERROR(DATEDIF(S18,U18,"d"),"0")&"-day" -> 3-day | AN18: =IFERROR(DATEDIF(S18,X18,"d"),"0")&"-day" -> 6-day | AO18: =IFERROR(DATEDIF(X18,AA18,"d"),"0")&"-day" -> 2-day | AP18: =IFERROR(DATEDIF(AA18,AE18,"d"),"0")&"-day" -> 1-day | AQ18: =SUM(AL18:AP18)&"-day" -> 0-day | AS18: =IF(AT18=0,"",ROW()-ROW($AS$2)) -> 16 | AT18: GMIAMMIPT/2026/01/0981 | AU18: =_xludf.ifna(INDEX($B:$B,MATCH(AT18,$C:$C,FALSE)),"") -> #NAME? | AV18: =_xludf.ifna(INDEX($U:$U,MATCH(AT18,$C:$C,FALSE)),"") -> #NAME? | AW18: =_xludf.ifna(INDEX($Z:$Z,MATCH(AT18,$C:$C,FALSE)),"") -> #NAME? | AX18: =_xludf.ifna(INDEX($AA:$AA,MATCH(AT18,$C:$C,FALSE)),"") -> #NAME? | AY18: =IFERROR(INDEX($R:$R,MATCH(AT18,$C:$C,FALSE)),"") -> 200000988563 | AZ18: =_xludf.ifna(INDEX($V:$V,MATCH(AT18,$C:$C,FALSE)),"") -> #NAME? | BA18: =_xludf.ifna(INDEX($W:$W,MATCH(AT18,$C:$C,FALSE)),"") -> #NAME? | BB18: =_xludf.ifna(INDEX($X:$X,MATCH(AT18,$C:$C,FALSE)),"") -> #NAME? | BC18: =_xludf.ifna(INDEX($AD:$AD,MATCH(AT18,$C:$C,FALSE)),"") -> #NAME? | BD18: =_xludf.ifna(INDEX($AE:$AE,MATCH(AT18,$C:$C,FALSE)),"") -> #NAME? | BE18: =_xludf.ifna(INDEX($AG:$AG,MATCH(AT18,$C:$C,FALSE)),"") -> #NAME? | BF18: =_xludf.ifna(INDEX($T:$T,MATCH(AT18,$C:$C,FALSE),""),"") -> #NAME? | BG18: =_xludf.ifna(INDEX($AI:$AI,MATCH(AT18,$C:$C,FALSE)),"") -> #NAME?
A19: =IF(C19=0,"",ROW()-ROW($A$2)) -> 17 | B19: 46025 | C19: GMIAMMIPT/2026/01/0003 | D19: 7L10-8-1 | E19: Standard Blade Fuses (ATS) 10 Amp red | F19: 2 | G19: EA | H19: =IF(C19=0,"",IF(R19>0,"DONE","WAITING")) -> DONE | I19: SV521 | J19: SV700TF | K19: Sakai | L19: 6307 | N19: AC HOT | O19: WHEEL | P19: DHIMAS | Q19: WAHYUDIN | R19: 200000986786 | S19: 46028 | T19: =IF(C19=0,"",IF(ISBLANK(S19),"WAITING","DONE")) -> DONE | U19: 46031 | V19: 9200066841 | W19: 41879 | X19: 46034 | Y19: =IF(C19=0,"",IF(V19>0,"DONE","WAITING")) -> DONE | Z19: DO 45715 | AA19: 46036 | AB19: =IF(C19=0,"",IF(Z19>0,"DONE","WAITING")) -> DONE | AD19: GMI26-0044684 | AE19: 46037 | AF19: =IF(C19=0,"",IF(ISBLANK(AD19),"WAITING","DONE")) -> DONE | AG19: 46038 | AH19: 46098 | AI19: =IF(AD19=0,"",IF(ISBLANK(AH19),"UNPAID","PAID")) -> PAID | AJ19: {=IFERROR(INDEX('[1]Master Price'!$E:$E,MATCH(D19,'[1]Master Price'!$B:$B,0)),"0")} -> 0 | AK19: =AJ19*F19 -> 0 | AL19: =IFERROR(DATEDIF(S19,T19,"d"),"0")&"-day" -> 0-day | AM19: =IFERROR(DATEDIF(S19,U19,"d"),"0")&"-day" -> 3-day | AN19: =IFERROR(DATEDIF(S19,X19,"d"),"0")&"-day" -> 6-day | AO19: =IFERROR(DATEDIF(X19,AA19,"d"),"0")&"-day" -> 2-day | AP19: =IFERROR(DATEDIF(AA19,AE19,"d"),"0")&"-day" -> 1-day | AQ19: =SUM(AL19:AP19)&"-day" -> 0-day | AS19: =IF(AT19=0,"",ROW()-ROW($AS$2)) -> 17 | AT19: GMIAMMIPT/2026/01/0982 | AU19: =_xludf.ifna(INDEX($B:$B,MATCH(AT19,$C:$C,FALSE)),"") -> #NAME? | AV19: =_xludf.ifna(INDEX($U:$U,MATCH(AT19,$C:$C,FALSE)),"") -> #NAME? | AW19: =_xludf.ifna(INDEX($Z:$Z,MATCH(AT19,$C:$C,FALSE)),"") -> #NAME? | AX19: =_xludf.ifna(INDEX($AA:$AA,MATCH(AT19,$C:$C,FALSE)),"") -> #NAME? | AY19: =IFERROR(INDEX($R:$R,MATCH(AT19,$C:$C,FALSE)),"") -> 200000988565 | AZ19: =_xludf.ifna(INDEX($V:$V,MATCH(AT19,$C:$C,FALSE)),"") -> #NAME? | BA19: =_xludf.ifna(INDEX($W:$W,MATCH(AT19,$C:$C,FALSE)),"") -> #NAME? | BB19: =_xludf.ifna(INDEX($X:$X,MATCH(AT19,$C:$C,FALSE)),"") -> #NAME? | BC19: =_xludf.ifna(INDEX($AD:$AD,MATCH(AT19,$C:$C,FALSE)),"") -> #NAME? | BD19: =_xludf.ifna(INDEX($AE:$AE,MATCH(AT19,$C:$C,FALSE)),"") -> #NAME? | BE19: =_xludf.ifna(INDEX($AG:$AG,MATCH(AT19,$C:$C,FALSE)),"") -> #NAME? | BF19: =_xludf.ifna(INDEX($T:$T,MATCH(AT19,$C:$C,FALSE),""),"") -> #NAME? | BG19: =_xludf.ifna(INDEX($AI:$AI,MATCH(AT19,$C:$C,FALSE)),"") -> #NAME?
A20: =IF(C20=0,"",ROW()-ROW($A$2)) -> 18 | B20: 46025 | C20: GMIAMMIPT/2026/01/0003 | D20: 5L17-314-BK | E20: NITTO 21E PVC TAPE 19MM X 20M BLACK | F20: 1 | G20: EA | H20: =IF(C20=0,"",IF(R20>0,"DONE","WAITING")) -> DONE | I20: SV521 | J20: SV700TF | K20: Sakai | L20: 6307 | N20: AC HOT | O20: WHEEL | P20: DHIMAS | Q20: WAHYUDIN | R20: 200000986786 | S20: 46028 | T20: =IF(C20=0,"",IF(ISBLANK(S20),"WAITING","DONE")) -> DONE | U20: 46031 | V20: 9200066841 | W20: 41879 | X20: 46034 | Y20: =IF(C20=0,"",IF(V20>0,"DONE","WAITING")) -> DONE | Z20: DO 45715 | AA20: 46036 | AB20: =IF(C20=0,"",IF(Z20>0,"DONE","WAITING")) -> DONE | AD20: GMI26-0044684 | AE20: 46037 | AF20: =IF(C20=0,"",IF(ISBLANK(AD20),"WAITING","DONE")) -> DONE | AG20: 46038 | AH20: 46098 | AI20: =IF(AD20=0,"",IF(ISBLANK(AH20),"UNPAID","PAID")) -> PAID | AJ20: {=IFERROR(INDEX('[1]Master Price'!$E:$E,MATCH(D20,'[1]Master Price'!$B:$B,0)),"0")} -> 0 | AK20: =AJ20*F20 -> 0 | AL20: =IFERROR(DATEDIF(S20,T20,"d"),"0")&"-day" -> 0-day | AM20: =IFERROR(DATEDIF(S20,U20,"d"),"0")&"-day" -> 3-day | AN20: =IFERROR(DATEDIF(S20,X20,"d"),"0")&"-day" -> 6-day | AO20: =IFERROR(DATEDIF(X20,AA20,"d"),"0")&"-day" -> 2-day | AP20: =IFERROR(DATEDIF(AA20,AE20,"d"),"0")&"-day" -> 1-day | AQ20: =SUM(AL20:AP20)&"-day" -> 0-day | AS20: =IF(AT20=0,"",ROW()-ROW($AS$2)) -> 18 | AT20: GMIAMMIPT/2026/01/0983 | AU20: =_xludf.ifna(INDEX($B:$B,MATCH(AT20,$C:$C,FALSE)),"") -> #NAME? | AV20: =_xludf.ifna(INDEX($U:$U,MATCH(AT20,$C:$C,FALSE)),"") -> #NAME? | AW20: =_xludf.ifna(INDEX($Z:$Z,MATCH(AT20,$C:$C,FALSE)),"") -> #NAME? | AX20: =_xludf.ifna(INDEX($AA:$AA,MATCH(AT20,$C:$C,FALSE)),"") -> #NAME? | AY20: =IFERROR(INDEX($R:$R,MATCH(AT20,$C:$C,FALSE)),"") -> 200000988566 | AZ20: =_xludf.ifna(INDEX($V:$V,MATCH(AT20,$C:$C,FALSE)),"") -> #NAME? | BA20: =_xludf.ifna(INDEX($W:$W,MATCH(AT20,$C:$C,FALSE)),"") -> #NAME? | BB20: =_xludf.ifna(INDEX($X:$X,MATCH(AT20,$C:$C,FALSE)),"") -> #NAME? | BC20: =_xludf.ifna(INDEX($AD:$AD,MATCH(AT20,$C:$C,FALSE)),"") -> #NAME? | BD20: =_xludf.ifna(INDEX($AE:$AE,MATCH(AT20,$C:$C,FALSE)),"") -> #NAME? | BE20: =_xludf.ifna(INDEX($AG:$AG,MATCH(AT20,$C:$C,FALSE)),"") -> #NAME? | BF20: =_xludf.ifna(INDEX($T:$T,MATCH(AT20,$C:$C,FALSE),""),"") -> #NAME? | BG20: =_xludf.ifna(INDEX($AI:$AI,MATCH(AT20,$C:$C,FALSE)),"") -> #NAME?
A21: =IF(C21=0,"",ROW()-ROW($A$2)) -> 19 | B21: 46025 | C21: GMIAMMIPT/2026/01/0003 | D21: 5L17-182-BK | E21: Cable Ties width: 2.4mm, length: 100mm Black (pack 0f 100) | F21: 1 | G21: EA | H21: =IF(C21=0,"",IF(R21>0,"DONE","WAITING")) -> DONE | I21: SV521 | J21: SV700TF | K21: Sakai | L21: 6307 | N21: AC HOT | O21: WHEEL | P21: DHIMAS | Q21: WAHYUDIN | R21: 200000986786 | S21: 46028 | T21: =IF(C21=0,"",IF(ISBLANK(S21),"WAITING","DONE")) -> DONE | U21: 46031 | V21: 9200066841 | W21: 41879 | X21: 46034 | Y21: =IF(C21=0,"",IF(V21>0,"DONE","WAITING")) -> DONE | Z21: DO 45715 | AA21: 46036 | AB21: =IF(C21=0,"",IF(Z21>0,"DONE","WAITING")) -> DONE | AD21: GMI26-0044684 | AE21: 46037 | AF21: =IF(C21=0,"",IF(ISBLANK(AD21),"WAITING","DONE")) -> DONE | AG21: 46038 | AH21: 46098 | AI21: =IF(AD21=0,"",IF(ISBLANK(AH21),"UNPAID","PAID")) -> PAID | AJ21: {=IFERROR(INDEX('[1]Master Price'!$E:$E,MATCH(D21,'[1]Master Price'!$B:$B,0)),"0")} -> 0 | AK21: =AJ21*F21 -> 0 | AL21: =IFERROR(DATEDIF(S21,T21,"d"),"0")&"-day" -> 0-day | AM21: =IFERROR(DATEDIF(S21,U21,"d"),"0")&"-day" -> 3-day | AN21: =IFERROR(DATEDIF(S21,X21,"d"),"0")&"-day" -> 6-day | AO21: =IFERROR(DATEDIF(X21,AA21,"d"),"0")&"-day" -> 2-day | AP21: =IFERROR(DATEDIF(AA21,AE21,"d"),"0")&"-day" -> 1-day | AQ21: =SUM(AL21:AP21)&"-day" -> 0-day | AS21: =IF(AT21=0,"",ROW()-ROW($AS$2)) -> 19 | AT21: GMIAMMIPT/2026/01/0984 | AU21: =_xludf.ifna(INDEX($B:$B,MATCH(AT21,$C:$C,FALSE)),"") -> #NAME? | AV21: =_xludf.ifna(INDEX($U:$U,MATCH(AT21,$C:$C,FALSE)),"") -> #NAME? | AW21: =_xludf.ifna(INDEX($Z:$Z,MATCH(AT21,$C:$C,FALSE)),"") -> #NAME? | AX21: =_xludf.ifna(INDEX($AA:$AA,MATCH(AT21,$C:$C,FALSE)),"") -> #NAME? | AY21: =IFERROR(INDEX($R:$R,MATCH(AT21,$C:$C,FALSE)),"") -> 200000988570 | AZ21: =_xludf.ifna(INDEX($V:$V,MATCH(AT21,$C:$C,FALSE)),"") -> #NAME? | BA21: =_xludf.ifna(INDEX($W:$W,MATCH(AT21,$C:$C,FALSE)),"") -> #NAME? | BB21: =_xludf.ifna(INDEX($X:$X,MATCH(AT21,$C:$C,FALSE)),"") -> #NAME? | BC21: =_xludf.ifna(INDEX($AD:$AD,MATCH(AT21,$C:$C,FALSE)),"") -> #NAME? | BD21: =_xludf.ifna(INDEX($AE:$AE,MATCH(AT21,$C:$C,FALSE)),"") -> #NAME? | BE21: =_xludf.ifna(INDEX($AG:$AG,MATCH(AT21,$C:$C,FALSE)),"") -> #NAME? | BF21: =_xludf.ifna(INDEX($T:$T,MATCH(AT21,$C:$C,FALSE),""),"") -> #NAME? | BG21: =_xludf.ifna(INDEX($AI:$AI,MATCH(AT21,$C:$C,FALSE)),"") -> #NAME?
A22: =IF(C22=0,"",ROW()-ROW($A$2)) -> 20 | B22: 46025 | C22: GMIAMMIPT/2026/01/0004 | D22: 14L-0760-2 | E22: Fitting 1/2 R12 180 + Core R134 | F22: 1 | G22: EA | H22: =IF(C22=0,"",IF(R22>0,"DONE","WAITING")) -> DONE | I22: D8508 | J22: NOT REGISTERED | K22: NOT REGISTERED | N22: SUPPLY ONLY (BOSTON) | O22: SUPPORT | P22: LEO | Q22: DIDI | R22: PO BOSTON | S22: 46025 | T22: =IF(C22=0,"",IF(ISBLANK(S22),"WAITING","DONE")) -> DONE | U22: PO BOSTON | V22: PO/AMM-IPT/26/I/00085 | W22: 42173 | X22: 46044 | Y22: =IF(C22=0,"",IF(V22>0,"DONE","WAITING")) -> DONE | Z22: DO 46065 | AA22: 46049 | AB22: =IF(C22=0,"",IF(Z22>0,"DONE","WAITING")) -> DONE | AD22: GMI26-0045001 | AE22: 46049 | AF22: =IF(C22=0,"",IF(ISBLANK(AD22),"WAITING","DONE")) -> DONE | AG22: 46062 | AH22: 46064 | AI22: =IF(AD22=0,"",IF(ISBLANK(AH22),"UNPAID","PAID")) -> PAID | AJ22: {=IFERROR(INDEX('[1]Master Price'!$E:$E,MATCH(D22,'[1]Master Price'!$B:$B,0)),"0")} -> 0 | AK22: =AJ22*F22 -> 0 | AL22: =IFERROR(DATEDIF(S22,T22,"d"),"0")&"-day" -> 0-day | AM22: =IFERROR(DATEDIF(S22,U22,"d"),"0")&"-day" -> 0-day | AN22: =IFERROR(DATEDIF(S22,X22,"d"),"0")&"-day" -> 19-day | AO22: =IFERROR(DATEDIF(X22,AA22,"d"),"0")&"-day" -> 5-day | AP22: =IFERROR(DATEDIF(AA22,AE22,"d"),"0")&"-day" -> 0-day | AQ22: =SUM(AL22:AP22)&"-day" -> 0-day | AS22: =IF(AT22=0,"",ROW()-ROW($AS$2)) -> 20 | AT22: GMIAMMIPT/2026/01/0985 | AU22: =_xludf.ifna(INDEX($B:$B,MATCH(AT22,$C:$C,FALSE)),"") -> #NAME? | AV22: =_xludf.ifna(INDEX($U:$U,MATCH(AT22,$C:$C,FALSE)),"") -> #NAME? | AW22: =_xludf.ifna(INDEX($Z:$Z,MATCH(AT22,$C:$C,FALSE)),"") -> #NAME? | AX22: =_xludf.ifna(INDEX($AA:$AA,MATCH(AT22,$C:$C,FALSE)),"") -> #NAME? | AY22: =IFERROR(INDEX($R:$R,MATCH(AT22,$C:$C,FALSE)),"") -> 210000270073 | AZ22: =_xludf.ifna(INDEX($V:$V,MATCH(AT22,$C:$C,FALSE)),"") -> #NAME? | BA22: =_xludf.ifna(INDEX($W:$W,MATCH(AT22,$C:$C,FALSE)),"") -> #NAME? | BB22: =_xludf.ifna(INDEX($X:$X,MATCH(AT22,$C:$C,FALSE)),"") -> #NAME? | BC22: =_xludf.ifna(INDEX($AD:$AD,MATCH(AT22,$C:$C,FALSE)),"") -> #NAME? | BD22: =_xludf.ifna(INDEX($AE:$AE,MATCH(AT22,$C:$C,FALSE)),"") -> #NAME? | BE22: =_xludf.ifna(INDEX($AG:$AG,MATCH(AT22,$C:$C,FALSE)),"") -> #NAME? | BF22: =_xludf.ifna(INDEX($T:$T,MATCH(AT22,$C:$C,FALSE),""),"") -> #NAME? | BG22: =_xludf.ifna(INDEX($AI:$AI,MATCH(AT22,$C:$C,FALSE)),"") -> #NAME?
A23: =IF(C23=0,"",ROW()-ROW($A$2)) -> 21 | B23: 46025 | C23: GMIAMMIPT/2026/01/0004 | D23: 14L-0143-1 | E23: Core Valve R134 | F23: 4 | G23: EA | H23: =IF(C23=0,"",IF(R23>0,"DONE","WAITING")) -> DONE | I23: D8508 | J23: NOT REGISTERED | K23: NOT REGISTERED | N23: SUPPLY ONLY (BOSTON) | O23: SUPPORT | P23: LEO | Q23: DIDI | R23: PO BOSTON | S23: 46025 | T23: =IF(C23=0,"",IF(ISBLANK(S23),"WAITING","DONE")) -> DONE | U23: PO BOSTON | V23: PO/AMM-IPT/26/I/00085 | W23: 42173 | X23: 46044 | Y23: =IF(C23=0,"",IF(V23>0,"DONE","WAITING")) -> DONE | Z23: DO 46065 | AA23: 46049 | AB23: =IF(C23=0,"",IF(Z23>0,"DONE","WAITING")) -> DONE | AD23: GMI26-0045001 | AE23: 46049 | AF23: =IF(C23=0,"",IF(ISBLANK(AD23),"WAITING","DONE")) -> DONE | AG23: 46062 | AH23: 46064 | AI23: =IF(AD23=0,"",IF(ISBLANK(AH23),"UNPAID","PAID")) -> PAID | AJ23: {=IFERROR(INDEX('[1]Master Price'!$E:$E,MATCH(D23,'[1]Master Price'!$B:$B,0)),"0")} -> 0 | AK23: =AJ23*F23 -> 0 | AL23: =IFERROR(DATEDIF(S23,T23,"d"),"0")&"-day" -> 0-day | AM23: =IFERROR(DATEDIF(S23,U23,"d"),"0")&"-day" -> 0-day | AN23: =IFERROR(DATEDIF(S23,X23,"d"),"0")&"-day" -> 19-day | AO23: =IFERROR(DATEDIF(X23,AA23,"d"),"0")&"-day" -> 5-day | AP23: =IFERROR(DATEDIF(AA23,AE23,"d"),"0")&"-day" -> 0-day | AQ23: =SUM(AL23:AP23)&"-day" -> 0-day | AS23: =IF(AT23=0,"",ROW()-ROW($AS$2)) -> 21 | AT23: GMIAMMIPT/2026/01/0986 | AU23: =_xludf.ifna(INDEX($B:$B,MATCH(AT23,$C:$C,FALSE)),"") -> #NAME? | AV23: =_xludf.ifna(INDEX($U:$U,MATCH(AT23,$C:$C,FALSE)),"") -> #NAME? | AW23: =_xludf.ifna(INDEX($Z:$Z,MATCH(AT23,$C:$C,FALSE)),"") -> #NAME? | AX23: =_xludf.ifna(INDEX($AA:$AA,MATCH(AT23,$C:$C,FALSE)),"") -> #NAME? | AY23: =IFERROR(INDEX($R:$R,MATCH(AT23,$C:$C,FALSE)),"") -> 200000988582 | AZ23: =_xludf.ifna(INDEX($V:$V,MATCH(AT23,$C:$C,FALSE)),"") -> #NAME? | BA23: =_xludf.ifna(INDEX($W:$W,MATCH(AT23,$C:$C,FALSE)),"") -> #NAME? | BB23: =_xludf.ifna(INDEX($X:$X,MATCH(AT23,$C:$C,FALSE)),"") -> #NAME? | BC23: =_xludf.ifna(INDEX($AD:$AD,MATCH(AT23,$C:$C,FALSE)),"") -> #NAME? | BD23: =_xludf.ifna(INDEX($AE:$AE,MATCH(AT23,$C:$C,FALSE)),"") -> #NAME? | BE23: =_xludf.ifna(INDEX($AG:$AG,MATCH(AT23,$C:$C,FALSE)),"") -> #NAME? | BF23: =_xludf.ifna(INDEX($T:$T,MATCH(AT23,$C:$C,FALSE),""),"") -> #NAME? | BG23: =_xludf.ifna(INDEX($AI:$AI,MATCH(AT23,$C:$C,FALSE)),"") -> #NAME?
A24: =IF(C24=0,"",ROW()-ROW($A$2)) -> 22 | B24: 46025 | C24: GMIAMMIPT/2026/01/0004 | D24: 14L-0677-3/8 | E24: Fitting R12 3/4 90 + Core valve | F24: 1 | G24: EA | H24: =IF(C24=0,"",IF(R24>0,"DONE","WAITING")) -> DONE | I24: D8508 | J24: NOT REGISTERED | K24: NOT REGISTERED | N24: SUPPLY ONLY (BOSTON) | O24: SUPPORT | P24: LEO | Q24: DIDI | R24: PO BOSTON | S24: 46025 | T24: =IF(C24=0,"",IF(ISBLANK(S24),"WAITING","DONE")) -> DONE | U24: PO BOSTON | V24: PO/AMM-IPT/26/I/00085 | W24: 42173 | X24: 46044 | Y24: =IF(C24=0,"",IF(V24>0,"DONE","WAITING")) -> DONE | Z24: DO 46065 | AA24: 46049 | AB24: =IF(C24=0,"",IF(Z24>0,"DONE","WAITING")) -> DONE | AD24: GMI26-0045001 | AE24: 46049 | AF24: =IF(C24=0,"",IF(ISBLANK(AD24),"WAITING","DONE")) -> DONE | AG24: 46062 | AH24: 46064 | AI24: =IF(AD24=0,"",IF(ISBLANK(AH24),"UNPAID","PAID")) -> PAID | AJ24: {=IFERROR(INDEX('[1]Master Price'!$E:$E,MATCH(D24,'[1]Master Price'!$B:$B,0)),"0")} -> 0 | AK24: =AJ24*F24 -> 0 | AL24: =IFERROR(DATEDIF(S24,T24,"d"),"0")&"-day" -> 0-day | AM24: =IFERROR(DATEDIF(S24,U24,"d"),"0")&"-day" -> 0-day | AN24: =IFERROR(DATEDIF(S24,X24,"d"),"0")&"-day" -> 19-day | AO24: =IFERROR(DATEDIF(X24,AA24,"d"),"0")&"-day" -> 5-day | AP24: =IFERROR(DATEDIF(AA24,AE24,"d"),"0")&"-day" -> 0-day | AQ24: =SUM(AL24:AP24)&"-day" -> 0-day | AS24: =IF(AT24=0,"",ROW()-ROW($AS$2)) -> 22 | AT24: GMIAMMIPT/2026/01/0987 | AU24: =_xludf.ifna(INDEX($B:$B,MATCH(AT24,$C:$C,FALSE)),"") -> #NAME? | AV24: =_xludf.ifna(INDEX($U:$U,MATCH(AT24,$C:$C,FALSE)),"") -> #NAME? | AW24: =_xludf.ifna(INDEX($Z:$Z,MATCH(AT24,$C:$C,FALSE)),"") -> #NAME? | AX24: =_xludf.ifna(INDEX($AA:$AA,MATCH(AT24,$C:$C,FALSE)),"") -> #NAME? | AY24: =IFERROR(INDEX($R:$R,MATCH(AT24,$C:$C,FALSE)),"") -> 200000988585 | AZ24: =_xludf.ifna(INDEX($V:$V,MATCH(AT24,$C:$C,FALSE)),"") -> #NAME? | BA24: =_xludf.ifna(INDEX($W:$W,MATCH(AT24,$C:$C,FALSE)),"") -> #NAME? | BB24: =_xludf.ifna(INDEX($X:$X,MATCH(AT24,$C:$C,FALSE)),"") -> #NAME? | BC24: =_xludf.ifna(INDEX($AD:$AD,MATCH(AT24,$C:$C,FALSE)),"") -> #NAME? | BD24: =_xludf.ifna(INDEX($AE:$AE,MATCH(AT24,$C:$C,FALSE)),"") -> #NAME? | BE24: =_xludf.ifna(INDEX($AG:$AG,MATCH(AT24,$C:$C,FALSE)),"") -> #NAME? | BF24: =_xludf.ifna(INDEX($T:$T,MATCH(AT24,$C:$C,FALSE),""),"") -> #NAME? | BG24: =_xludf.ifna(INDEX($AI:$AI,MATCH(AT24,$C:$C,FALSE)),"") -> #NAME?
A25: =IF(C25=0,"",ROW()-ROW($A$2)) -> 23 | B25: 46025 | C25: GMIAMMIPT/2026/01/0005 | D25: 14L-0299 | E25: Pressure Switch Lps | F25: 1 | G25: EA | H25: =IF(C25=0,"",IF(R25>0,"DONE","WAITING")) -> DONE | I25: WA52518 | J25: AXOR 2528RMC | K25: Mercedes Benz | N25: SUPPLY ONLY | O25: SUPPORT | P25: LEO | Q25: AFTAL | R25: 200000986781 | S25: 46028 | T25: =IF(C25=0,"",IF(ISBLANK(S25),"WAITING","DONE")) -> DONE | U25: 46031 | V25: 9200066844 | W25: 41877 | X25: 46034 | Y25: =IF(C25=0,"",IF(V25>0,"DONE","WAITING")) -> DONE | Z25: DO 45713 | AA25: 46036 | AB25: =IF(C25=0,"",IF(Z25>0,"DONE","WAITING")) -> DONE | AD25: GMI26-0044685 | AE25: 46037 | AF25: =IF(C25=0,"",IF(ISBLANK(AD25),"WAITING","DONE")) -> DONE | AG25: 46038 | AH25: 46098 | AI25: =IF(AD25=0,"",IF(ISBLANK(AH25),"UNPAID","PAID")) -> PAID | AJ25: {=IFERROR(INDEX('[1]Master Price'!$E:$E,MATCH(D25,'[1]Master Price'!$B:$B,0)),"0")} -> 0 | AK25: =AJ25*F25 -> 0 | AL25: =IFERROR(DATEDIF(S25,T25,"d"),"0")&"-day" -> 0-day | AM25: =IFERROR(DATEDIF(S25,U25,"d"),"0")&"-day" -> 3-day | AN25: =IFERROR(DATEDIF(S25,X25,"d"),"0")&"-day" -> 6-day | AO25: =IFERROR(DATEDIF(X25,AA25,"d"),"0")&"-day" -> 2-day | AP25: =IFERROR(DATEDIF(AA25,AE25,"d"),"0")&"-day" -> 1-day | AQ25: =SUM(AL25:AP25)&"-day" -> 0-day | AS25: =IF(AT25=0,"",ROW()-ROW($AS$2)) -> 23 | AT25: GMIAMMIPT/2026/01/0988 | AU25: =_xludf.ifna(INDEX($B:$B,MATCH(AT25,$C:$C,FALSE)),"") -> #NAME? | AV25: =_xludf.ifna(INDEX($U:$U,MATCH(AT25,$C:$C,FALSE)),"") -> #NAME? | AW25: =_xludf.ifna(INDEX($Z:$Z,MATCH(AT25,$C:$C,FALSE)),"") -> #NAME? | AX25: =_xludf.ifna(INDEX($AA:$AA,MATCH(AT25,$C:$C,FALSE)),"") -> #NAME? | AY25: =IFERROR(INDEX($R:$R,MATCH(AT25,$C:$C,FALSE)),"") -> 200000988589 | AZ25: =_xludf.ifna(INDEX($V:$V,MATCH(AT25,$C:$C,FALSE)),"") -> #NAME? | BA25: =_xludf.ifna(INDEX($W:$W,MATCH(AT25,$C:$C,FALSE)),"") -> #NAME? | BB25: =_xludf.ifna(INDEX($X:$X,MATCH(AT25,$C:$C,FALSE)),"") -> #NAME? | BC25: =_xludf.ifna(INDEX($AD:$AD,MATCH(AT25,$C:$C,FALSE)),"") -> #NAME? | BD25: =_xludf.ifna(INDEX($AE:$AE,MATCH(AT25,$C:$C,FALSE)),"") -> #NAME? | BE25: =_xludf.ifna(INDEX($AG:$AG,MATCH(AT25,$C:$C,FALSE)),"") -> #NAME? | BF25: =_xludf.ifna(INDEX($T:$T,MATCH(AT25,$C:$C,FALSE),""),"") -> #NAME? | BG25: =_xludf.ifna(INDEX($AI:$AI,MATCH(AT25,$C:$C,FALSE)),"") -> #NAME?
A26: =IF(C26=0,"",ROW()-ROW($A$2)) -> 24 | B26: 46025 | C26: GMIAMMIPT/2026/01/0006 | D26: 2L3-8F | E26: LED Work Lamp 9-32VDC 2100 lumens 27W Flood Lens Round Type | F26: 1 | G26: EA | H26: =IF(C26=0,"",IF(R26>0,"DONE","WAITING")) -> DONE | I26: WA52507 | J26: AXOR 2528RMC | K26: Mercedes Benz | N26: SUPPLY ONLY | O26: SUPPORT | P26: LEO | Q26: HERIYANTO | R26: 200000986778 | S26: 46028 | T26: =IF(C26=0,"",IF(ISBLANK(S26),"WAITING","DONE")) -> DONE | U26: 46031 | V26: 9200066843 | W26: 41876 | X26: 46034 | Y26: =IF(C26=0,"",IF(V26>0,"DONE","WAITING")) -> DONE | Z26: DO 45712 | AA26: 46036 | AB26: =IF(C26=0,"",IF(Z26>0,"DONE","WAITING")) -> DONE | AD26: GMI26-0044686 | AE26: 46037 | AF26: =IF(C26=0,"",IF(ISBLANK(AD26),"WAITING","DONE")) -> DONE | AG26: 46038 | AH26: 46098 | AI26: =IF(AD26=0,"",IF(ISBLANK(AH26),"UNPAID","PAID")) -> PAID | AJ26: {=IFERROR(INDEX('[1]Master Price'!$E:$E,MATCH(D26,'[1]Master Price'!$B:$B,0)),"0")} -> 0 | AK26: =AJ26*F26 -> 0 | AL26: =IFERROR(DATEDIF(S26,T26,"d"),"0")&"-day" -> 0-day | AM26: =IFERROR(DATEDIF(S26,U26,"d"),"0")&"-day" -> 3-day | AN26: =IFERROR(DATEDIF(S26,X26,"d"),"0")&"-day" -> 6-day | AO26: =IFERROR(DATEDIF(X26,AA26,"d"),"0")&"-day" -> 2-day | AP26: =IFERROR(DATEDIF(AA26,AE26,"d"),"0")&"-day" -> 1-day | AQ26: =SUM(AL26:AP26)&"-day" -> 0-day | AS26: =IF(AT26=0,"",ROW()-ROW($AS$2)) -> 24 | AT26: GMIAMMIPT/2026/01/0989 | AU26: =_xludf.ifna(INDEX($B:$B,MATCH(AT26,$C:$C,FALSE)),"") -> #NAME? | AV26: =_xludf.ifna(INDEX($U:$U,MATCH(AT26,$C:$C,FALSE)),"") -> #NAME? | AW26: =_xludf.ifna(INDEX($Z:$Z,MATCH(AT26,$C:$C,FALSE)),"") -> #NAME? | AX26: =_xludf.ifna(INDEX($AA:$AA,MATCH(AT26,$C:$C,FALSE)),"") -> #NAME? | AY26: =IFERROR(INDEX($R:$R,MATCH(AT26,$C:$C,FALSE)),"") -> 200000988592 | AZ26: =_xludf.ifna(INDEX($V:$V,MATCH(AT26,$C:$C,FALSE)),"") -> #NAME? | BA26: =_xludf.ifna(INDEX($W:$W,MATCH(AT26,$C:$C,FALSE)),"") -> #NAME? | BB26: =_xludf.ifna(INDEX($X:$X,MATCH(AT26,$C:$C,FALSE)),"") -> #NAME? | BC26: =_xludf.ifna(INDEX($AD:$AD,MATCH(AT26,$C:$C,FALSE)),"") -> #NAME? | BD26: =_xludf.ifna(INDEX($AE:$AE,MATCH(AT26,$C:$C,FALSE)),"") -> #NAME? | BE26: =_xludf.ifna(INDEX($AG:$AG,MATCH(AT26,$C:$C,FALSE)),"") -> #NAME? | BF26: =_xludf.ifna(INDEX($T:$T,MATCH(AT26,$C:$C,FALSE),""),"") -> #NAME? | BG26: =_xludf.ifna(INDEX($AI:$AI,MATCH(AT26,$C:$C,FALSE)),"") -> #NAME?
A27: =IF(C27=0,"",ROW()-ROW($A$2)) -> 25 | B27: 46025 | C27: GMIAMMIPT/2026/01/0007 | D27: 11L-3024 | E27: LED FLood Light 6 Eyes 18 Watt 10-30 VDC | F27: 2 | G27: EA | H27: =IF(C27=0,"",IF(R27>0,"DONE","WAITING")) -> DONE | I27: FT54801 | J27: AROCS 4845K | K27: Mercedes Benz | N27: SUPPLY ONLY | O27: SUPPORT | P27: LEO | Q27: FAUZI | R27: 200000986774 | S27: 46028 | T27: =IF(C27=0,"",IF(ISBLANK(S27),"WAITING","DONE")) -> DONE | U27: 46031 | V27: 9200066922 | W27: 41885 | X27: 46034 | Y27: =IF(C27=0,"",IF(V27>0,"DONE","WAITING")) -> DONE | Z27: DO 45723 | AA27: 46036 | AB27: =IF(C27=0,"",IF(Z27>0,"DONE","WAITING")) -> DONE | AD27: GMI26-0044687 | AE27: 46037 | AF27: =IF(C27=0,"",IF(ISBLANK(AD27),"WAITING","DONE")) -> DONE | AG27: 46038 | AH27: 46098 | AI27: =IF(AD27=0,"",IF(ISBLANK(AH27),"UNPAID","PAID")) -> PAID | AJ27: {=IFERROR(INDEX('[1]Master Price'!$E:$E,MATCH(D27,'[1]Master Price'!$B:$B,0)),"0")} -> 0 | AK27: =AJ27*F27 -> 0 | AL27: =IFERROR(DATEDIF(S27,T27,"d"),"0")&"-day" -> 0-day | AM27: =IFERROR(DATEDIF(S27,U27,"d"),"0")&"-day" -> 3-day | AN27: =IFERROR(DATEDIF(S27,X27,"d"),"0")&"-day" -> 6-day | AO27: =IFERROR(DATEDIF(X27,AA27,"d"),"0")&"-day" -> 2-day | AP27: =IFERROR(DATEDIF(AA27,AE27,"d"),"0")&"-day" -> 1-day | AQ27: =SUM(AL27:AP27)&"-day" -> 0-day | AS27: =IF(AT27=0,"",ROW()-ROW($AS$2)) -> 25 | AT27: GMIAMMIPT/2026/01/0990 | AU27: =_xludf.ifna(INDEX($B:$B,MATCH(AT27,$C:$C,FALSE)),"") -> #NAME? | AV27: =_xludf.ifna(INDEX($U:$U,MATCH(AT27,$C:$C,FALSE)),"") -> #NAME? | AW27: =_xludf.ifna(INDEX($Z:$Z,MATCH(AT27,$C:$C,FALSE)),"") -> #NAME? | AX27: =_xludf.ifna(INDEX($AA:$AA,MATCH(AT27,$C:$C,FALSE)),"") -> #NAME? | AY27: =IFERROR(INDEX($R:$R,MATCH(AT27,$C:$C,FALSE)),"") -> CANCEL | AZ27: =_xludf.ifna(INDEX($V:$V,MATCH(AT27,$C:$C,FALSE)),"") -> #NAME? | BA27: =_xludf.ifna(INDEX($W:$W,MATCH(AT27,$C:$C,FALSE)),"") -> #NAME? | BB27: =_xludf.ifna(INDEX($X:$X,MATCH(AT27,$C:$C,FALSE)),"") -> #NAME? | BC27: =_xludf.ifna(INDEX($AD:$AD,MATCH(AT27,$C:$C,FALSE)),"") -> #NAME? | BD27: =_xludf.ifna(INDEX($AE:$AE,MATCH(AT27,$C:$C,FALSE)),"") -> #NAME? | BE27: =_xludf.ifna(INDEX($AG:$AG,MATCH(AT27,$C:$C,FALSE)),"") -> #NAME? | BF27: =_xludf.ifna(INDEX($T:$T,MATCH(AT27,$C:$C,FALSE),""),"") -> #NAME? | BG27: =_xludf.ifna(INDEX($AI:$AI,MATCH(AT27,$C:$C,FALSE)),"") -> #NAME?
